Workbook

Sheet DETALLE 26
A1: FECHA | B1: ABONOS | J1: FECHA | K1: EGRESOS | S1: FECHA | T1: ABONOS CTA. CTES.
B2: FOLIO | C2: CONCEPTO | D2: DETALLE | E2: MONTO PARA CALCULO | F2: NETO | G2: IVA | H2: MONTO TOTAL | K2: FOLIO | L2: CONCEPTO | M2: DETALLE | N2: MEDIO DE PAGO | O2: NETO | P2: IVA | Q2: MONTO TOTAL | T2: CONCEPTO | U2: DETALLE | V2: MONTO TOTAL
A3: 46097 | B3: 2 | C3: UP FRONT | D3: 2026/03 | F3: =H3/1.19 -> 26028588 | G3: =H3-F3 -> 4945431.8 | H3: 30974020 | J3: ='ENERO 26'!F2 -> 46034 | K3: ='ENERO 26'!E2 -> 4048987 | L3: ='ENERO 26'!D2 -> SERVICIOS EQUIFAX CHILE LIMITADA | M3: INFORMES SOLICITADOS POR PRINCIPAL | N3: CTA. CTE. BANCO CHILE: FCO | O3: =Q3/1.19 -> 23521.008 | P3: =Q3-O3 -> 4468.9916 | Q3: ='ENERO 26'!N2 -> 27990 | S3: 46106 | T3: DEVOLUCIÓN | U3: CTA. CTE. BANCO CHILE: FCO | V3: 34324
A4: 46097 | B4: 1 | C4: TRAILER FEE | D4: 2026/03 | F4: =H4/1.19 -> 322687.39 | G4: =H4-F4 -> 61310.605 | H4: 383998 | J4: ='ENERO 26'!F3 -> 46029 | K4: ='ENERO 26'!E3 -> 5543387 | L4: ='ENERO 26'!D3 -> FALABELLA RETAIL S.A. | M4: NOTEBOOK | N4: CTA. CTE. BANCO CHILE: FCO | O4: =Q4/1.19 -> 462176.47 | P4: =Q4-O4 -> 87813.529 | Q4: ='ENERO 26'!N3 -> 549990 | S4: 46106 | T4: DEVOLUCIÓN | U4: CTA. CTE. BANCO CHILE: FCO | V4: 34324
A5: 46129 | B5: 8 | C5: UPFRONTMUD | D5: 2026/04 | E5: 2693457121 | F5: =H5/1.19 -> 20200931 | G5: =H5-F5 -> 3838176.9 | H5: 24039108 | J5: ='ENERO 26'!F4 -> 46034 | K5: ='ENERO 26'!E4 -> 4048985 | L5: ='ENERO 26'!D4 -> SERVICIOS EQUIFAX CHILE LIMITADA | M5: INFORMES SOLICITADOS POR PRINCIPAL | N5: CTA. CTE. BANCO CHILE: FCO | O5: =Q5/1.19 -> 15117.647 | P5: =Q5-O5 -> 2872.3529 | Q5: ='ENERO 26'!N4 -> 17990 | S5: 46107 | T5: DEVOLUCIÓN | U5: CTA. CTE. BANCO CHILE: FCO | V5: 2820162
A6: 46129 | B6: 7 | C6: ACUM_E (Trailer Fee: Previsional) | D6: 2026/04 | F6: =H6/1.19 -> 87780.672 | G6: =H6-F6 -> 16678.328 | H6: 104459 | J6: 46049 | K6: - | L6: ARRIENDO PROPORCIONAL | M6: ENERO 2026 | N6: CTA. CTE. BCI: FV ASESORIAS | O6: 0 | P6: 0 | Q6: =(200000/30)*3 -> 20000 | S6: 46108 | T6: PAGO SUELDOS | U6: CTA. CTE. BANCO CHILE: NATALIA | V6: 3000000
A7: 46129 | B7: 6 | C7: ACUM_A (Trailer Fee: RG) | D7: 2026/04 | F7: =H7/1.19 -> 1276009.2 | G7: =H7-F7 -> 242441.76 | H7: 1518451 | J7: 46054 | K7: - | L7: ARRIENDO COMPLETO | M7: FEBRERO 2026 | N7: CTA. CTE. BCI: FV ASESORIAS | O7: 0 | P7: 0 | Q7: 200000 | S7: 46111 | T7: DEVOLUCIÓN | U7: CTA. CTE. BANCO CHILE: FCO | V7: 518750 | W7: *
A8: 46129 | B8: 5 | C8: SEGUROS_E (Pago por póliza) | D8: 2026/04 | F8: =H8/1.19 -> 79683.193 | G8: =H8-F8 -> 15139.807 | H8: 94823 | J8: ='FEBRERO 26'!F4 -> 46070 | K8: ='FEBRERO 26'!E4 -> 1167147 | L8: ='FEBRERO 26'!D4 -> Artel S.A | M8: ARTICULOS DE OFICINA… | N8: CTA. CTE. BANCO CHILE: FCO | O8: =Q8/1.19 -> 58516.807 | P8: =Q8-O8 -> 11118.193 | Q8: ='FEBRERO 26'!N4 -> 69635 | S8: 46111 | T8: PRESTAMO PREPAGO C.C. CHILE | U8: CTA. CTE. BANCO CHILE: FCO | V8: 7000000 | X8: PRESTAMO ACUMULADO | Y8: =($V$8+$V$9+$V$10+$V$14)-$V$11 -> 22000000
A9: 46158 | B9: 9 | C9: UPFRONTMUD | D9: 2026/05 | E9: 868665848 | F9: =H9/1.19 -> 6514993.3 | G9: =H9-F9 -> 1237848.7 | H9: 7752842 | J9: 46080 | K9: 32714 | L9: IX Comercio Chile SPA | M9: DOCKERS | N9: CTA. CTE. BANCO CHILE: FCO | O9: =Q9/1.19 -> 100815.13 | P9: =Q9-O9 -> 19154.874 | Q9: 119970 | S9: 46112 | T9: PRESTAMO PREPAGO C.C. CHILE | U9: CTA. CTE. BANCO CHILE: FCO | V9: 7000000
A10: 46158 | B10: 10 | C10: ACUM_E (Trailer Fee: Previsional) | D10: 2026/05 | E10: 1163055255 | F10: =H10/1.19 -> 466275.63 | G10: =H10-F10 -> 88592.37 | H10: 554868 | J10: 46081 | K10: 139727 | L10: BADAMAX RETAIL S A | M10: FERUCH | N10: CTA. CTE. BANCO CHILE: FCO | O10: =Q10/1.19 -> 173436.97 | P10: =Q10-O10 -> 32953.025 | Q10: 206390 | S10: 46113 | T10: PRESTAMO PREPAGO C.C. CHILE | U10: CTA. CTE. BANCO CHILE: FCO | V10: 4500000
A11: 46158 | B11: 11 | C11: ACUM_A (Trailer Fee: RG) | D11: 2026/05 | E11: 5378778285 | F11: =H11/1.19 -> 2533498.3 | G11: =H11-F11 -> 481364.68 | H11: 3014863 | J11: ='FEBRERO 26'!F2 -> 46081 | K11: ='FEBRERO 26'!E2 -> 116797 | L11: ='FEBRERO 26'!D2 -> Guante Y G | M11: ZAPATOS | N11: CTA. CTE. BANCO CHILE: FCO | O11: =Q11/1.19 -> 116781.51 | P11: =Q11-O11 -> 22188.487 | Q11: ='FEBRERO 26'!N2 -> 138970 | R11: * | S11: 46122 | T11: DEVOLUCIÓN PRESTAMO FV | U11: CTA. CTE. BCI FV ASESORIAS | V11: 500000
A12: 46184 | B12: 12 | C12: UPFRONTMUD | D12: 2026/06 | E12: 938046787 | F12: =H12/1.19 -> 7035351.3 | G12: =H12-F12 -> 1336716.7 | H12: 8372068 | J12: ='FEBRERO 26'!F3 -> 46081 | K12: ='FEBRERO 26'!E3 -> 25502774 | L12: ='FEBRERO 26'!D3 -> CENCOSUD RETAIL S.A. | M12: ROPA FORMAL | N12: CTA. CTE. BANCO CHILE: FCO | O12: =Q12/1.19 -> 157109.24 | P12: =Q12-O12 -> 29850.756 | Q12: ='FEBRERO 26'!N3 -> 186960 | R12: * | S12: 46139 | T12: DEVOLUCIÓN COMPRA MICROSOFT | U12: CTA. CTE. BANCO CHILE: FCO | V12: 84990
A13: 46184 | B13: 13 | C13: ACUM_E (Trailer Fee: Previsional) | D13: 2026/06 | E13: 1.8676101e+09 | F13: =H13/1.19 -> 822343.7 | G13: =H13-F13 -> 156245.3 | H13: 978589 | J13: 46082 | K13: - | L13: ARRIENDO COMPLETO | M13: MARZO 2026 | N13: CTA. CTE. BCI: FV ASESORIAS | O13: 0 | P13: 0 | Q13: 200000 | S13: 46141 | T13: PAGO SUELDOS | U13: CTA. CTE. BANCO SANTANDER: NATALIA | V13: 3000000
A14: 46184 | B14: 14 | C14: ACUM_A (Trailer Fee: RG) | D14: 2026/06 | E14: 6.1837235e+09 | F14: =H14/1.19 -> 3150059.7 | G14: =H14-F14 -> 598511.34 | H14: 3748571 | J14: 46095 | K14: 5854862 | L14: ROSEN | M14: SOFA + VELADORES | N14: TC BANCO CHILE: FCO | O14: =Q14/1.19 -> 1212563.9 | P14: =Q14-O14 -> 230387.13 | Q14: 1442951 | S14: 46155 | T14: PRESTAMO PREPAGO C.C. CHILE | U14: CTA. CTE. BANCO CHILE: FCO | V14: 4000000
A15: 46223 | B15: 16 | C15: UPFRONTMUD | D15: 2026/07 | E15: 459087265 | F15: =H15/1.19 -> 3443153.8 | G15: =H15-F15 -> 654199.22 | H15: 4097353 | J15: 46099 | K15: 5603375 | L15: FALABELLA RETAIL S.A. | M15: IMPRESORA | N15: CTA. CTE. BANCO CHILE: FCO | O15: =Q15/1.19 -> 134445.38 | P15: =Q15-O15 -> 25544.622 | Q15: 159990 | R15: * | S15: 46155 | T15: DEVOLUCIÓN COMPRA EASY | U15: CTA. CTE. BANCO SANTANDER: NATALIA | V15: 125010
A16: 46223 | B16: 17 | C16: ACUM_E (Trailer Fee: Previsional) | D16: 2026/07 | E16: 2056452511 | F16: =H16/1.19 -> 866701.68 | G16: =H16-F16 -> 164673.32 | H16: 1031375 | J16: 46099 | L16: FALABELLA RETAIL S.A. | M16: GARANTÍA 3 AÑOS (MARZO 2029) - IMPRESORA | N16: CTA. CTE. BANCO CHILE: FCO | O16: 0 | P16: 0 | Q16: 32400 | R16: * | S16: 46139 | T16: DEVOLUCIÓN COMPRA PASAJES AEREOS | U16: CTA. CTE. BANCO CHILE: FCO | V16: 624682
A17: 46223 | B17: 18 | C17: ACUM_A (Trailer Fee: RG) | D17: 2026/07 | E17: 6774003916 | F17: =H17/1.19 -> 3330578.2 | G17: =H17-F17 -> 632809.85 | H17: 3963388 | J17: 46105 | L17: SUELDO | M17: NATALIA | N17: CTA. CTE. BCI: FV ASESORIAS | O17: 0 | P17: 0 | Q17: 3000000 | S17: 46169 | T17: DEVOLUCIÓN COMPRA EASY | U17: CTA. CTE. BANCO SANTANDER: NATALIA | V17: 155950
J18: 46106 | K18: 5623730 | L18: FALABELLA RETAIL S.A. | M18: NUEVO NOTEBOOK | N18: CTA. CTE. BCI: FV ASESORIAS | O18: =Q18/1.19 -> 747882.35 | P18: =Q18-O18 -> 142097.65 | Q18: 889980 | S18: 46175 | T18: DEVOLUCIÓN COMPRA OSOJI | U18: CTA. CTE. BANCO CHILE: FCO | V18: 359712
J19: 46106 | L19: FALABELLA RETAIL S.A. | M19: GARANTÍA 3 AÑOS (MARZO 2029) - NUEVO NOTEBOOK | N19: CTA. CTE. BCI: FV ASESORIAS | O19: 0 | P19: 0 | Q19: 195990 | S19: 46182 | T19: DEVOLUCIÓN MATERIALES DE OFICINA | U19: CTA. CTE. BANCO SANTANDER: NATALIA | V19: 44590
J20: 46137 | L20: SUSCRIPCIÓN MICROSOFT 365 | N20: CTA. CTE. BANCO CHILE: FCO | Q20: 84990 | R20: - | S20: 46182 | T20: DEVOLUCIÓN ÚTILES DE ASEO | U20: CTA. CTE. BANCO SANTANDER: NATALIA | V20: 50630
J21: 46122 | L21: PREVIRED | M21: LEYES SOCIALES: NATALIA TAPIA | N21: CTA. CTE. BCI: FV ASESORIAS | Q21: 805429
J22: 46122 | L22: SII IMPUESTOS | M22: F29 (IVA, IMPUESTO A LA RENTA ($87.811), PPM, ETC. | N22: CTA. CTE. BCI: FV ASESORIAS | Q22: 4819453
J23: 46141 | L23: ARRIENDO COMPLETO | M23: ABRIL 2026 | N23: CTA. CTE. BCI: FV ASESORIAS | Q23: 200000
J24: 46141 | L24: ARRIENDO COMPLETO | M24: MAYO 2026 | N24: CTA. CTE. BCI: FV ASESORIAS | Q24: 200000
J25: 46141 | L25: SUELDO | M25: NATALIA | N25: CTA. CTE. BCI: FV ASESORIAS | O25: 0 | P25: 0 | Q25: 3000000
J26: 46138 | K26: 140313 | L26: BADAMAX RETAIL S A | M26: FERUCH | N26: CTA. CTE. BCI: FV ASESORIAS | O26: =Q26/1.19 -> 80470.588 | P26: =Q26-O26 -> 15289.412 | Q26: 95760
J27: 46138 | K27: 5646665 | L27: FALABELLA RETAIL S.A. | M27: ROPA FORMAL | N27: CTA. CTE. BCI: FV ASESORIAS | O27: =Q27/1.19 -> 47210.084 | P27: =Q27-O27 -> 8969.916 | Q27: 56180
J28: 46131 | L28: SKY | M28: VIAJE VALDIVIA | N28: CTA. CTE. BANCO CHILE: FCO | O28: =Q28/1.19 -> 155701.68 | P28: =Q28-O28 -> 29583.319 | Q28: 185285
J29: 46131 | L29: LATAM AIRLINES GROUP SA | M29: VIAJE VALDIVIA | N29: CTA. CTE. BANCO CHILE: FCO | Q29: 313038
J30: 46131 | L30: LATAM AIRLINES GROUP SA | M30: VIAJE VALDIVIA | N30: CTA. CTE. BANCO CHILE: FCO | Q30: 126359
J31: 46149 | L31: BANCO DE CREDITO E INVERSIONES | M31: COMISIONES E INTERES ABRIL 2026 | N31: CTA. CTE. BCI: FV ASESORIAS | Q31: 5982
J32: 46154 | L32: PREVIRED | M32: LEYES SOCIALES: NATALIA TAPIA | N32: CTA. CTE. BCI: FV ASESORIAS | Q32: 808015
J33: 46154 | K33: 37928726 | L33: EASY RETAIL S.A. | M33: MATERIALES PINTURA CASA ROJA | N33: CTA. CTE. BANCO SANTANDER: NATALIA | Q33: 125010
J34: 46157 | K34: 10048 | L34: PRINCIPAL ASSET MANAGEMENT CHILE S.A. | M34: ????? | O34: =Q34/1.19 -> 120400.84 | P34: =Q34-O34 -> 22876.16 | Q34: 143277
L35: COPAGO AVERTA | M35: PAGO ABRIL 2026 | N35: CTA. CTE. BCI: FV ASESORIAS | Q35: 142235
J36: 46162 | K36: 38250266 | L36: EASY RETAIL S.A. | M36: COMPRA MUEBLE FCO. ALONSO | N36: CTA. CTE. BANCO SANTANDER: NATALIA | O36: =Q36/1.19 -> 131050.42 | P36: =Q36-O36 -> 24899.58 | Q36: 155950
J37: 46168 | L37: SUELDO | M37: NATALIA | N37: CTA. CTE. BCI: FV ASESORIAS | O37: 0 | P37: 0 | Q37: 3000000
J38: 46175 | L38: OSOJI | M38: COMPRA ASPIRADORA ROBOT + CEPILLO LIMPIEZA + CABEZALES REPUESTO | N38: CTA. CTE. BANCO CHILE: FCO | O38: =Q38/1.19 -> 302278.99 | P38: =Q38-O38 -> 57433.008 | Q38: 359712
J39: 46175 | L39: ARRIENDO COMPLETO | M39: JUNIO 2026 | N39: CTA. CTE. BCI: FV ASESORIAS | Q39: 200000
L40: LAPIZ LOPEZ | M40: MATERIALES OFICINA | N40: CTA. CTE. BANCO SANTANDER: NATALIA | O40: =Q40/1.19 -> 37470.588 | P40: =Q40-O40 -> 7119.4118 | Q40: 44590
...

Sheet ENERO 26
A1: Nro | B1: Tipo Compra | C1: RUT Proveedor | D1: Razon Social | E1: Folio | F1: Fecha Docto | G1: Fecha Recepcion | H1: Fecha Acuse | I1: Monto Exento | J1: Monto Neto | K1: Monto IVA Recuperable | L1: Monto Iva No Recuperable | M1: Codigo IVA No Rec. | N1: Monto Total | O1: Monto Neto Activo Fijo | P1: IVA Activo Fijo | Q1: IVA uso Comun | R1: Impto. Sin Derecho a Credito | S1: IVA No Retenido | T1: Tabacos Puros | U1: Tabacos Cigarrillos | V1: Tabacos Elaborados | W1: NCE o NDE sobre Fact. de Compra | X1: Codigo Otro Impuesto | Y1: Valor Otro Impuesto | Z1: Tasa Otro Impuesto
A2: 1 | B2: IVA no Recuperable | C2: 85896100-9 | D2: SERVICIOS EQUIFAX CHILE LIMITADA | E2: 4048987 | F2: 46034 | G2: 46034.649 | I2: 0 | J2: 23521 | L2: 4469 | M2: 9 | N2: 27990 | S2: 0 | W2: 0
A3: 2 | B3: IVA no Recuperable | C3: 77261280-K | D3: FALABELLA RETAIL S.A. | E3: 5543387 | F3: 46029 | G3: 46029.816 | I3: 0 | J3: 462176 | L3: 87814 | M3: 9 | N3: 549990 | S3: 0 | W3: 0
A4: 3 | B4: IVA no Recuperable | C4: 85896100-9 | D4: SERVICIOS EQUIFAX CHILE LIMITADA | E4: 4048985 | F4: 46034 | G4: 46034.649 | I4: 0 | J4: 15118 | L4: 2872 | M4: 9 | N4: 17990 | S4: 0 | W4: 0
A20: TOTAL | J20: =SUM(J2:J19) -> 500815 | K20: =SUM(K2:K19) -> 0 | L20: =SUM(L2:L19) -> 95155 | N20: =SUM(N2:N19) -> 595970

Sheet FEBRERO 26
A1: Nro | B1: Tipo Compra | C1: RUT Proveedor | D1: Razon Social | E1: Folio | F1: Fecha Docto | G1: Fecha Recepcion | H1: Fecha Acuse | I1: Monto Exento | J1: Monto Neto | K1: Monto IVA Recuperable | L1: Monto Iva No Recuperable | M1: Codigo IVA No Rec. | N1: Monto Total | O1: Monto Neto Activo Fijo | P1: IVA Activo Fijo | Q1: IVA uso Comun | R1: Impto. Sin Derecho a Credito | S1: IVA No Retenido | T1: Tabacos Puros | U1: Tabacos Cigarrillos | V1: Tabacos Elaborados | W1: NCE o NDE sobre Fact. de Compra | X1: Codigo Otro Impuesto | Y1: Valor Otro Impuesto | Z1: Tasa Otro Impuesto
A2: 1 | B2: IVA no Recuperable | C2: 78558400-7 | D2: Guante Y G | E2: 116797 | F2: 46081 | G2: 46081.552 | I2: 0 | J2: 116782 | L2: 22188 | M2: 9 | N2: 138970 | S2: 0 | W2: 0
A3: 2 | B3: IVA no Recuperable | C3: 81201000-K | D3: CENCOSUD RETAIL S.A. | E3: 25502774 | F3: 46081 | G3: 46081.524 | I3: 0 | J3: 157109 | L3: 29851 | M3: 9 | N3: 186960 | S3: 0 | W3: 0
A4: 3 | B4: IVA no Recuperable | C4: 92642000-3 | D4: Artel S.A | E4: 1167147 | F4: 46070 | G4: 46070.833 | I4: 0 | J4: 58517 | L4: 11118 | M4: 9 | N4: 69635 | S4: 0 | W4: 0
A20: TOTAL | J20: =SUM(J2:J19) -> 332408 | K20: =SUM(K2:K19) -> 0 | L20: =SUM(L2:L19) -> 63157 | N20: =SUM(N2:N19) -> 395565

Sheet MARZO 26
A1: Nro | B1: Tipo Compra | C1: RUT Proveedor | D1: Razon Social | E1: Folio | F1: Fecha Docto | G1: Fecha Recepcion | H1: Fecha Acuse | I1: Monto Exento | J1: Monto Neto | K1: Monto IVA Recuperable | L1: Monto Iva No Recuperable | M1: Codigo IVA No Rec. | N1: Monto Total | O1: Monto Neto Activo Fijo | P1: IVA Activo Fijo | Q1: IVA uso Comun | R1: Impto. Sin Derecho a Credito | S1: IVA No Retenido | T1: Tabacos Puros | U1: Tabacos Cigarrillos | V1: Tabacos Elaborados | W1: NCE o NDE sobre Fact. de Compra | X1: Codigo Otro Impuesto | Y1: Valor Otro Impuesto | Z1: Tasa Otro Impuesto
A2: 1 | B2: Del Giro | C2: 77261280-K | D2: FALABELLA RETAIL S.A. | E2: 5603375 | F2: 46099 | G2: 46099.613 | I2: 0 | J2: 134445 | K2: 25545 | N2: 159990 | S2: 0 | W2: 0
A3: 2 | B3: Activo Fijo | C3: 93129000-2 | D3: ROSEN S.A. | E3: 5854862 | F3: 46095 | G3: 46095.827 | I3: 0 | J3: 1212564 | K3: 230387 | N3: 1442951 | O3: 1212564 | P3: 230387 | S3: 0 | W3: 0
A4: 3 | B4: Del Giro | C4: 86708800-8 | D4: BADAMAX RETAIL S A | E4: 139727 | F4: 46081 | G4: 46081.57 | I4: 0 | J4: 173437 | K4: 32953 | N4: 206390 | S4: 0 | W4: 0
A5: 4 | B5: Del Giro | C5: 76449468-7 | D5: IX Comercio Chile SPA | E5: 32714 | F5: 46080 | G5: 46080.827 | I5: 0 | J5: 100815 | K5: 19155 | N5: 119970 | S5: 0 | W5: 0
A20: TOTAL | J20: =SUM(J2:J19) -> 1621261 | K20: =SUM(K2:K19) -> 308040 | L20: =SUM(L2:L19) -> 0 | N20: =SUM(N2:N19) -> 1929301

Sheet ABRIL 26
A1: Nro | B1: Tipo Compra | C1: RUT Proveedor | D1: Razon Social | E1: Folio | F1: Fecha Docto | G1: Fecha Recepcion | H1: Fecha Acuse | I1: Monto Exento | J1: Monto Neto | K1: Monto IVA Recuperable | L1: Monto Iva No Recuperable | M1: Codigo IVA No Rec. | N1: Monto Total | O1: Monto Neto Activo Fijo | P1: IVA Activo Fijo | Q1: IVA uso Comun | R1: Impto. Sin Derecho a Credito | S1: IVA No Retenido | T1: Tabacos Puros | U1: Tabacos Cigarrillos | V1: Tabacos Elaborados | W1: NCE o NDE sobre Fact. de Compra | X1: Codigo Otro Impuesto | Y1: Valor Otro Impuesto | Z1: Tasa Otro Impuesto
A2: 1 | B2: Del Giro | C2: 89862200-2 | D2: LATAM AIRLINES GROUP SA | E2: 7260665 | F2: 46131 | G2: 46131.913 | I2: 313038 | J2: 0 | K2: 0 | N2: 313038 | S2: 0 | W2: 0
A3: 2 | B3: Del Giro | C3: 89862200-2 | D3: LATAM AIRLINES GROUP SA | E3: 7260715 | F3: 46131 | G3: 46131.939 | I3: 126359 | J3: 0 | K3: 0 | N3: 126359 | S3: 0 | W3: 0
A20: TOTAL | J20: =SUM(J2:J19) -> 0 | K20: =SUM(K2:K19) -> 0 | L20: =SUM(L2:L19) -> 0 | N20: =SUM(N2:N19) -> 439397

Sheet MAYO 26
A1: Nro | B1: Tipo Compra | C1: RUT Proveedor | D1: Razon Social | E1: Folio | F1: Fecha Docto | G1: Fecha Recepcion | H1: Fecha Acuse | I1: Monto Exento | J1: Monto Neto | K1: Monto IVA Recuperable | L1: Monto Iva No Recuperable | M1: Codigo IVA No Rec. | N1: Monto Total | O1: Monto Neto Activo Fijo | P1: IVA Activo Fijo | Q1: IVA uso Comun | R1: Impto. Sin Derecho a Credito | S1: IVA No Retenido | T1: Tabacos Puros | U1: Tabacos Cigarrillos | V1: Tabacos Elaborados | W1: NCE o NDE sobre Fact. de Compra | X1: Codigo Otro Impuesto | Y1: Valor Otro Impuesto | Z1: Tasa Otro Impuesto
A2: 1 | B2: Del Giro | C2: 77261280-K | D2: FALABELLA RETAIL S.A. | E2: 5646665 | F2: 46138 | G2: 46138.769 | I2: 0 | J2: 47210 | K2: 8970 | N2: 56180 | S2: 0 | W2: 0
A3: 2 | B3: Del Giro | C3: 86708800-8 | D3: BADAMAX RETAIL S A | E3: 140313 | F3: 46138 | G3: 46138.789 | I3: 0 | J3: 80471 | K3: 15289 | N3: 95760 | S3: 0 | W3: 0
A4: 3 | B4: Del Giro | C4: 97006000-6 | D4: BANCO DE CREDITO E INVERSIONES | E4: 30023425 | F4: 46149 | G4: 46150.772 | I4: 0 | J4: 5027 | K4: 955 | N4: 5982 | S4: 0 | W4: 0
A5: 4 | B5: Del Giro | C5: 76568660-1 | D5: EASY RETAIL S.A. | E5: 37928726 | F5: 46154 | G5: 46154.771 | I5: 0 | J5: 105051 | K5: 19959 | N5: 125010 | S5: 0 | W5: 0
A6: 5 | B6: Del Giro | C6: 76613770-9 | D6: PRINCIPAL ASSET MANAGEMENT CHILE S.A. | E6: 10048 | F6: 45792 | G6: 46157.463 | I6: 0 | J6: 120401 | K6: 22876 | N6: 143277 | S6: 0 | W6: 0
A7: 6 | B7: Del Giro | C7: 76568660-1 | D7: EASY RETAIL S.A. | E7: 38250266 | F7: 46161 | G7: 46161.584 | I7: 0 | J7: 131050 | K7: 24900 | N7: 155950 | S7: 0 | W7: 0
A20: TOTAL | J20: =SUM(J2:J19) -> 489210 | K20: =SUM(K2:K19) -> 92949 | L20: =SUM(L2:L19) -> 0 | N20: =SUM(N2:N19) -> 582159
