Workbook
Name año_pension: '[1]CNU Series'!$X$1:$X$15
Name año_pension: '[1]CNU Series'!$X$1:$X$15
Name año_pension: '[1]CNU Series'!$X$1:$X$15
Name año_pension: '[1]CNU Series'!$X$1:$X$15
Name año_pension: '[2]CNU Series'!$X$1:$X$15
Name Estado: '[1]CNU Series'!$V$1:$V$2
Name Estado: '[1]CNU Series'!$V$1:$V$2
Name Estado: '[1]CNU Series'!$V$1:$V$2
Name Estado: '[1]CNU Series'!$V$1:$V$2
Name Estado: '[2]CNU Series'!$V$1:$V$2

Sheet Portada
DS13: 0 | EK13: =+'Motor I'!$C$19 -> 0 | EU13: Porción de mejora de pensión por aportes voluntarios futuros. | EV13: =+EK22-DS22 -> #N/A
EU14: Porción de pensión CON saldos actuales y aportes obligatorios futuros. | EV14: =+DS22 -> #N/A
DS15: 0 | EK15: 40000
FU16: Pensión
DS17: 0 | EK17: 0 | FU17: =+EK22 -> #N/A | FV17: =+EK22 -> #N/A
AX18: Mujer | BO18: 0 | CH18: Moderado | CZ18: =+'Motor I'!K13 -> #N/A | FT18: =+EK22 -> #N/A
DS19: =+DS13+DS15+DS17 -> 0 | EK19: =+EK13+EK15+EK17 -> 40000
BO20: 0
BX21: =+'Motor I'!I33 -> Desde | CA21: =+'Motor I'!J33 -> Hasta | CE21: =+'Motor I'!K33 -> Activo | CF21: 1 | CG21: 1 | CH21: 1 | CI21: 1 | CJ21: 1 | CK21: 1 | CL21: =+'Motor I'!L33 -> Moderado | CM21: 1 | CN21: 1 | CO21: 1 | CP21: 1 | CQ21: 1 | CR21: 1 | CS21: =+'Motor I'!M33 -> Conservador | CT21: 1 | CU21: 1 | CV21: 1 | CW21: 1 | CX21: 1 | CY21: 1 | CZ21: =+'Motor I'!N33 -> Sin Perfil | DA21: 1 | DB21: 1 | DC21: 1 | DD21: 1 | DE21: 1 | DF21: 1
BO22: 0 | DS22: =+'Motor I'!C50/'Motor I'!C51 -> #N/A | EK22: =+'Motor II'!C50/'Motor II'!C51 -> #N/A
BX23: =+'Motor I'!I34 -> 25 | CA23: =+'Motor I'!J34 -> 40 | CE23: =+'Motor I'!K34 -> A | CL23: =+'Motor I'!L34 -> B | CS23: =+'Motor I'!M34 -> B | CZ23: =+'Motor I'!N34 -> A-B
BO24: 0
A25: Analisís de Pensión | BX25: =+'Motor I'!I35 -> 41 | CA25: =+'Motor I'!J35 -> 50 | CE25: =+'Motor I'!K35 -> C | CL25: =+'Motor I'!L35 -> C | CS25: =+'Motor I'!M35 -> C | CZ25: =+'Motor I'!N35 -> C | DS25: =+'Motor I'!C50 -> 0 | EK25: =+'Motor II'!C50 -> 0
BX26: 1
A27: 45931 | BX27: =+'Motor I'!I36 -> 51 | CA27: =+'Motor I'!J36 -> 60 | CE27: =+'Motor I'!K36 -> D | CL27: =+'Motor I'!L36 -> E | CS27: =+'Motor I'!M36 -> E | CZ27: =+'Motor I'!N36 -> D-E
BX28: 1 | BY28: 1 | BZ28: 1 | CA28: 1 | CB28: 1 | CC28: 1 | CE28: 1 | CF28: 1 | CG28: 1 | CH28: 1 | CI28: 1 | CJ28: 1 | CK28: 1 | CL28: 1 | CM28: 1 | CN28: 1 | CO28: 1 | CP28: 1 | CQ28: 1 | CR28: 1 | CS28: 1 | CT28: 1 | CU28: 1 | CV28: 1 | CW28: 1 | CX28: 1 | CY28: 1 | CZ28: 1 | DA28: 1 | DB28: 1 | DC28: 1 | DD28: 1 | DE28: 1 | DF28: 1
DI29: =+'Topes imponibles'!J2 -> #N/A

Sheet Paso 2B solicitado por cliente
B15: A. | C15: Fondo para cuenta obligatoria | Q15: C | S15: =+VLOOKUP(Q15,'Motor III'!$L$41:$M$45,2,FALSE) -> 0.0338 | V15: B.
B16: A. | C16: Fondo para ahorro previsional voluntario | Q16: C | S16: =+VLOOKUP(Q16,'Motor III'!$L$41:$M$45,2,FALSE) -> 0.0338 | V16: B.
B17: A. | C17: Fondo para depositos convenidos | Q17: C | S17: =+VLOOKUP(Q17,'Motor III'!$L$41:$M$45,2,FALSE) -> 0.0338 | V17: B.
C21: =+'Motor III'!$C$25 -> #N/A

Sheet 1.CNU
A1: CNU | H1: Tasa | I1: 0.0414 | K1: Tasa | L1: 0.0441
A2: Edad | B2: Hombre | C2: Mujer | H2: Hombre | I2: Mujer | K2: Hombre | L2: Mujer | N2: Trimestre | O2: Meses | P2: Tasa | Q2: Mujer 60 años | R2: Hombre 65 años | S2: Saldo | T2: Pensón Mujer | U2: Pensión Hombre | W2: Mujer | X2: Pensión
A3: 20 | B3: =+'3,41'!K19 -> 324.252 | C3: =+'3,41'!M19 -> 327.168 | H3: 278.292 | I3: 280.44 | K3: 258.156 | L3: 263.82 | N3: T1 | O3: ene-mar | P3: 0.0441 | Q3: 205.488 | R3: 182.856 | S3: 100000000 | T3: =+S3/Q3 -> 486646.42 | U3: =+S3/R3 -> 546878.42 | W3: T1 | X3: =+T3 -> 486646.42
A4: 21 | B4: =+'3,41'!K20 -> 323.076 | C4: =+'3,41'!M20 -> 326.064 | H4: 277.56 | I4: 279.768 | K4: 257.352 | L4: 263.184 | N4: T2 | O4: abr-jun | P4: 0.0441 | Q4: 205.488 | R4: 182.856 | S4: 100000000 | T4: =+S4/Q4 -> 486646.42 | U4: =+S4/R4 -> 546878.42 | W4: T2 | X4: =+T4 -> 486646.42
A5: 22 | B5: =+'3,41'!K21 -> 321.864 | C5: =+'3,41'!M21 -> 324.924 | H5: 276.792 | I5: 279.06 | K5: 256.512 | L5: 262.524 | N5: T3 | O5: jul-sept | P5: 0.0441 | Q5: 205.488 | R5: 182.856 | S5: 100000000 | T5: =+S5/Q5 -> 486646.42 | U5: =+S5/R5 -> 546878.42 | W5: T3 | X5: =+T5 -> 486646.42
A6: 23 | B6: =+'3,41'!K22 -> 320.604 | C6: =+'3,41'!M22 -> 323.736 | H6: 276 | I6: 278.328 | K6: 255.636 | L6: 261.828 | N6: T4 | O6: oct-dic | P6: 0.0414 | Q6: 212.448 | R6: 188.28 | S6: 100000000 | T6: =+S6/Q6 -> 470703.42 | U6: =+S6/R6 -> 531123.86 | W6: T4 | X6: =+T6 -> 470703.42
A7: 24 | B7: =+'3,41'!K23 -> 319.308 | C7: =+'3,41'!M23 -> 322.512 | H7: 275.172 | I7: 277.56 | K7: 254.724 | L7: 261.108
A8: 25 | B8: =+'3,41'!K24 -> 317.964 | C8: =+'3,41'!M24 -> 321.24 | H8: 274.308 | I8: 276.756 | K8: 253.776 | L8: 260.352 | N8: 4,41% v/s 4,14% | O8: Var Pensión | W8: Hombre | X8: Pensión
A9: 26 | B9: =+'3,41'!K25 -> 316.572 | C9: =+'3,41'!M25 -> 319.92 | H9: 273.408 | I9: 275.928 | K9: 252.792 | L9: 259.56 | N9: Mujer | O9: =+T6-T5 -> -15943.003 | W9: T1 | X9: =+U3 -> 546878.42
A10: 27 | B10: =+'3,41'!K26 -> 315.12 | C10: =+'3,41'!M26 -> 318.552 | H10: 272.46 | I10: 275.052 | K10: 251.76 | L10: 258.732 | N10: Hombre | O10: =+U6-U5 -> -15754.56 | W10: T2 | X10: =+U4 -> 546878.42
A11: 28 | B11: =+'3,41'!K27 -> 313.632 | C11: =+'3,41'!M27 -> 317.136 | H11: 271.488 | I11: 274.14 | K11: 250.692 | L11: 257.868 | W11: T3 | X11: =+U5 -> 546878.42
A12: 29 | B12: =+'3,41'!K28 -> 312.096 | C12: =+'3,41'!M28 -> 315.672 | H12: 270.468 | I12: 273.192 | K12: 249.576 | L12: 256.956 | W12: T4 | X12: =+U6 -> 531123.86
A13: 30 | B13: =+'3,41'!K29 -> 310.5 | C13: =+'3,41'!M29 -> 314.148 | H13: 269.412 | I13: 272.196 | K13: 248.412 | L13: 256.008
A14: 31 | B14: =+'3,41'!K30 -> 308.844 | C14: =+'3,41'!M30 -> 312.576 | H14: 268.308 | I14: 271.164 | K14: 247.2 | L14: 255.024
A15: 32 | B15: =+'3,41'!K31 -> 307.128 | C15: =+'3,41'!M31 -> 310.956 | H15: 267.156 | I15: 270.096 | K15: 245.94 | L15: 254.004
A16: 33 | B16: =+'3,41'!K32 -> 305.364 | C16: =+'3,41'!M32 -> 309.276 | H16: 265.956 | I16: 268.968 | K16: 244.62 | L16: 252.924
A17: 34 | B17: =+'3,41'!K33 -> 303.54 | C17: =+'3,41'!M33 -> 307.536 | H17: 264.708 | I17: 267.804 | K17: 243.252 | L17: 251.808
A18: 35 | B18: =+'3,41'!K34 -> 301.644 | C18: =+'3,41'!M34 -> 305.724 | H18: 263.4 | I18: 266.58 | K18: 241.824 | L18: 250.644
A19: 36 | B19: =+'3,41'!K35 -> 299.688 | C19: =+'3,41'!M35 -> 303.864 | H19: 262.044 | I19: 265.308 | K19: 240.336 | L19: 249.42
A20: 37 | B20: =+'3,41'!K36 -> 297.66 | C20: =+'3,41'!M36 -> 301.932 | H20: 260.628 | I20: 263.988 | K20: 238.788 | L20: 248.16
A21: 38 | B21: =+'3,41'!K37 -> 295.56 | C21: =+'3,41'!M37 -> 299.94 | H21: 259.164 | I21: 262.608 | K21: 237.168 | L21: 246.84
A22: 39 | B22: =+'3,41'!K38 -> 293.388 | C22: =+'3,41'!M38 -> 297.864 | H22: 257.628 | I22: 261.168 | K22: 235.476 | L22: 245.46
A23: 40 | B23: =+'3,41'!K39 -> 291.144 | C23: =+'3,41'!M39 -> 295.728 | H23: 256.032 | I23: 259.68 | K23: 233.712 | L23: 244.02
A24: 41 | B24: =+'3,41'!K40 -> 288.828 | C24: =+'3,41'!M40 -> 293.52 | H24: 254.364 | I24: 258.12 | K24: 231.888 | L24: 242.52
... A73: 90 | B73: =+'3,41'!K89 -> 73.704 | C73: =+'3,41'!M89 -> 73.86 | H73: 71.16 | I73: 71.388 | K73: 51.984 | L73: 63.492

Sheet 3,41
A1: Depto. Trámite de Pensiones
A2: Proceso de Negocio: Trámitación Análisis.
A4: Id. Usuario: LZUNIGA
A7: CÁLCULO DE SERIES CNU
A9: Fecha: 07-10-2025 - 14:50:45
B12: (1) Causante Hombre con Beneficiarios
B13: (2) Causante Mujer con Beneficiarios
B14: CAPITALES NECESARIOS UNITARIOS | J14: TABLA RESULTADO TU NÚMERO
B16: Utilizando Tabla RV-2020 | J16: CNU x 12
B18: Edad | C18: Masculino (1) | E18: Femenino (2) | K18: Masculino (1) | M18: Femenino (2)
B19: 20 | C19: 27.021 | E19: 27.264 | K19: 324.252 | M19: 327.168
B20: 21 | C20: 26.923 | E20: 27.172 | K20: 323.076 | M20: 326.064
B21: 22 | C21: 26.822 | E21: 27.077 | K21: 321.864 | M21: 324.924
B22: 23 | C22: 26.717 | E22: 26.978 | K22: 320.604 | M22: 323.736
B23: 24 | C23: 26.609 | E23: 26.876 | K23: 319.308 | M23: 322.512
B24: 25 | C24: 26.497 | E24: 26.77 | K24: 317.964 | M24: 321.24
B25: 26 | C25: 26.381 | E25: 26.66 | K25: 316.572 | M25: 319.92
B26: 27 | C26: 26.26 | E26: 26.546 | K26: 315.12 | M26: 318.552
B27: 28 | C27: 26.136 | E27: 26.428 | K27: 313.632 | M27: 317.136
B28: 29 | C28: 26.008 | E28: 26.306 | K28: 312.096 | M28: 315.672
B29: 30 | C29: 25.875 | E29: 26.179 | K29: 310.5 | M29: 314.148
B30: 31 | C30: 25.737 | E30: 26.048 | K30: 308.844 | M30: 312.576
... B89: 90 | C89: 6.142 | E89: 6.155 | K89: 73.704 | M89: 73.86

Sheet 3,54 v2
A1: CNU | H1: Tasa | I1: 0.0414 | K1: Tasa | L1: 0.0441
A2: Edad | B2: Hombre | C2: Mujer | H2: Hombre | I2: Mujer | K2: Hombre | L2: Mujer | N2: Trimestre | O2: Meses | P2: Tasa | Q2: Mujer 60 años | R2: Hombre 65 años | S2: Saldo | T2: Pensón Mujer | U2: Pensión Hombre | W2: Mujer | X2: Pensión
A3: 20 | B3: =+'3,54'!P19 -> 315.156 | C3: =+'3,54'!Q19 -> 317.904 | H3: 278.292 | I3: 280.44 | K3: 258.156 | L3: 263.82 | N3: T1 | O3: ene-mar | P3: 0.0441 | Q3: 205.488 | R3: 182.856 | S3: 100000000 | T3: =+S3/Q3 -> 486646.42 | U3: =+S3/R3 -> 546878.42 | W3: T1 | X3: =+T3 -> 486646.42
A4: 21 | B4: =+'3,54'!P20 -> 314.076 | C4: =+'3,54'!Q20 -> 316.896 | H4: 277.56 | I4: 279.768 | K4: 257.352 | L4: 263.184 | N4: T2 | O4: abr-jun | P4: 0.0441 | Q4: 205.488 | R4: 182.856 | S4: 100000000 | T4: =+S4/Q4 -> 486646.42 | U4: =+S4/R4 -> 546878.42 | W4: T2 | X4: =+T4 -> 486646.42
A5: 22 | B5: =+'3,54'!P21 -> 312.96 | C5: =+'3,54'!Q21 -> 315.852 | H5: 276.792 | I5: 279.06 | K5: 256.512 | L5: 262.524 | N5: T3 | O5: jul-sept | P5: 0.0441 | Q5: 205.488 | R5: 182.856 | S5: 100000000 | T5: =+S5/Q5 -> 486646.42 | U5: =+S5/R5 -> 546878.42 | W5: T3 | X5: =+T5 -> 486646.42
A6: 23 | B6: =+'3,54'!P22 -> 311.796 | C6: =+'3,54'!Q22 -> 314.76 | H6: 276 | I6: 278.328 | K6: 255.636 | L6: 261.828 | N6: T4 | O6: oct-dic | P6: 0.0414 | Q6: 212.448 | R6: 188.28 | S6: 100000000 | T6: =+S6/Q6 -> 470703.42 | U6: =+S6/R6 -> 531123.86 | W6: T4 | X6: =+T6 -> 470703.42
A7: 24 | B7: =+'3,54'!P23 -> 310.608 | C7: =+'3,54'!Q23 -> 313.632 | H7: 275.172 | I7: 277.56 | K7: 254.724 | L7: 261.108
A8: 25 | B8: =+'3,54'!P24 -> 309.36 | C8: =+'3,54'!Q24 -> 312.468 | H8: 274.308 | I8: 276.756 | K8: 253.776 | L8: 260.352 | N8: 4,41% v/s 4,14% | O8: Var Pensión | W8: Hombre | X8: Pensión
A9: 26 | B9: =+'3,54'!P25 -> 308.076 | C9: =+'3,54'!Q25 -> 311.256 | H9: 273.408 | I9: 275.928 | K9: 252.792 | L9: 259.56 | N9: Mujer | O9: =+T6-T5 -> -15943.003 | W9: T1 | X9: =+U3 -> 546878.42
A10: 27 | B10: =+'3,54'!P26 -> 306.744 | C10: =+'3,54'!Q26 -> 309.996 | H10: 272.46 | I10: 275.052 | K10: 251.76 | L10: 258.732 | N10: Hombre | O10: =+U6-U5 -> -15754.56 | W10: T2 | X10: =+U4 -> 546878.42
A11: 28 | B11: =+'3,54'!P27 -> 305.364 | C11: =+'3,54'!Q27 -> 308.688 | H11: 271.488 | I11: 274.14 | K11: 250.692 | L11: 257.868 | W11: T3 | X11: =+U5 -> 546878.42
A12: 29 | B12: =+'3,54'!P28 -> 303.924 | C12: =+'3,54'!Q28 -> 307.332 | H12: 270.468 | I12: 273.192 | K12: 249.576 | L12: 256.956 | W12: T4 | X12: =+U6 -> 531123.86
A13: 30 | B13: =+'3,54'!P29 -> 302.448 | C13: =+'3,54'!Q29 -> 305.928 | H13: 269.412 | I13: 272.196 | K13: 248.412 | L13: 256.008
A14: 31 | B14: =+'3,54'!P30 -> 300.912 | C14: =+'3,54'!Q30 -> 304.464 | H14: 268.308 | I14: 271.164 | K14: 247.2 | L14: 255.024
A15: 32 | B15: =+'3,54'!P31 -> 299.316 | C15: =+'3,54'!Q31 -> 302.952 | H15: 267.156 | I15: 270.096 | K15: 245.94 | L15: 254.004
A16: 33 | B16: =+'3,54'!P32 -> 297.672 | C16: =+'3,54'!Q32 -> 301.392 | H16: 265.956 | I16: 268.968 | K16: 244.62 | L16: 252.924
A17: 34 | B17: =+'3,54'!P33 -> 295.968 | C17: =+'3,54'!Q33 -> 299.772 | H17: 264.708 | I17: 267.804 | K17: 243.252 | L17: 251.808
A18: 35 | B18: =+'3,54'!P34 -> 294.204 | C18: =+'3,54'!Q34 -> 298.092 | H18: 263.4 | I18: 266.58 | K18: 241.824 | L18: 250.644
A19: 36 | B19: =+'3,54'!P35 -> 292.368 | C19: =+'3,54'!Q35 -> 296.352 | H19: 262.044 | I19: 265.308 | K19: 240.336 | L19: 249.42
A20: 37 | B20: =+'3,54'!P36 -> 290.472 | C20: =+'3,54'!Q36 -> 294.552 | H20: 260.628 | I20: 263.988 | K20: 238.788 | L20: 248.16
A21: 38 | B21: =+'3,54'!P37 -> 288.504 | C21: =+'3,54'!Q37 -> 292.68 | H21: 259.164 | I21: 262.608 | K21: 237.168 | L21: 246.84
A22: 39 | B22: =+'3,54'!P38 -> 286.464 | C22: =+'3,54'!Q38 -> 290.748 | H22: 257.628 | I22: 261.168 | K22: 235.476 | L22: 245.46
A23: 40 | B23: =+'3,54'!P39 -> 284.352 | C23: =+'3,54'!Q39 -> 288.744 | H23: 256.032 | I23: 259.68 | K23: 233.712 | L23: 244.02
A24: 41 | B24: =+'3,54'!P40 -> 282.168 | C24: =+'3,54'!Q40 -> 286.668 | H24: 254.364 | I24: 258.12 | K24: 231.888 | L24: 242.52
... A73: 90 | B73: =+'3,54'!P89 -> 73.308 | C73: =+'3,54'!Q89 -> 73.464 | H73: 71.16 | I73: 71.388 | K73: 51.984 | L73: 63.492

Sheet 3,54
A1: Depto. Trámite de Pensiones
A2: Proceso de Negocio: Trámitación Análisis.
A4: Id. Usuario: LZUNIGA
A7: CÁLCULO DE SERIES CNU
A9: Fecha: 09-04-2025 - 17:07:49
B12: (1) Causante Hombre con Beneficiarios
B13: (2) Causante Mujer con Beneficiarios
B14: CAPITALES NECESARIOS UNITARIOS | J14: TABLA RESULTADO TU NÚMERO
B16: Utilizando Tabla RV-2020 | J16: CNU x 12
B18: Edad | C18: Masculino (1) | E18: Femenino (2) | K18: Masculino (1) | M18: Femenino (2) | P18: =+K18 -> Masculino (1) | Q18: =+M18 -> Femenino (2)
B19: 20 | C19: 26.263 | E19: 26.492 | K19: 315.156 | M19: 317.904 | P19: =+K19 -> 315.156 | Q19: =+M19 -> 317.904
B20: 21 | C20: 26.173 | E20: 26.408 | K20: 314.076 | M20: 316.896 | P20: =+K20 -> 314.076 | Q20: =+M20 -> 316.896
B21: 22 | C21: 26.08 | E21: 26.321 | K21: 312.96 | M21: 315.852 | P21: =+K21 -> 312.96 | Q21: =+M21 -> 315.852
B22: 23 | C22: 25.983 | E22: 26.23 | K22: 311.796 | M22: 314.76 | P22: =+K22 -> 311.796 | Q22: =+M22 -> 314.76
B23: 24 | C23: 25.884 | E23: 26.136 | K23: 310.608 | M23: 313.632 | P23: =+K23 -> 310.608 | Q23: =+M23 -> 313.632
B24: 25 | C24: 25.78 | E24: 26.039 | K24: 309.36 | M24: 312.468 | P24: =+K24 -> 309.36 | Q24: =+M24 -> 312.468
B25: 26 | C25: 25.673 | E25: 25.938 | K25: 308.076 | M25: 311.256 | P25: =+K25 -> 308.076 | Q25: =+M25 -> 311.256
B26: 27 | C26: 25.562 | E26: 25.833 | K26: 306.744 | M26: 309.996 | P26: =+K26 -> 306.744 | Q26: =+M26 -> 309.996
B27: 28 | C27: 25.447 | E27: 25.724 | K27: 305.364 | M27: 308.688 | P27: =+K27 -> 305.364 | Q27: =+M27 -> 308.688
B28: 29 | C28: 25.327 | E28: 25.611 | K28: 303.924 | M28: 307.332 | P28: =+K28 -> 303.924 | Q28: =+M28 -> 307.332
B29: 30 | C29: 25.204 | E29: 25.494 | K29: 302.448 | M29: 305.928 | P29: =+K29 -> 302.448 | Q29: =+M29 -> 305.928
B30: 31 | C30: 25.076 | E30: 25.372 | K30: 300.912 | M30: 304.464 | P30: =+K30 -> 300.912 | Q30: =+M30 -> 304.464
... B89: 90 | C89: 6.109 | E89: 6.122 | K89: 73.308 | M89: 73.464 | P89: =+K89 -> 73.308 | Q89: =+M89 -> 73.464

Sheet 3,43 t1
A1: CNU | H1: Tasa | I1: 0.0414 | K1: Tasa | L1: 0.0441
A2: Edad | B2: Hombre | C2: Mujer | H2: Hombre | I2: Mujer | K2: Hombre | L2: Mujer | N2: Trimestre | O2: Meses | P2: Tasa | Q2: Mujer 60 años | R2: Hombre 65 años | S2: Saldo | T2: Pensón Mujer | U2: Pensión Hombre | W2: Mujer | X2: Pensión
A3: 20 | B3: =+'3,43'!K19 -> 322.824 | C3: =+'3,43'!M19 -> 325.716 | H3: 278.292 | I3: 280.44 | K3: 258.156 | L3: 263.82 | N3: T1 | O3: ene-mar | P3: 0.0441 | Q3: 205.488 | R3: 182.856 | S3: 100000000 | T3: =+S3/Q3 -> 486646.42 | U3: =+S3/R3 -> 546878.42 | W3: T1 | X3: =+T3 -> 486646.42
A4: 21 | B4: =+'3,43'!K20 -> 321.66 | C4: =+'3,43'!M20 -> 324.624 | H4: 277.56 | I4: 279.768 | K4: 257.352 | L4: 263.184 | N4: T2 | O4: abr-jun | P4: 0.0441 | Q4: 205.488 | R4: 182.856 | S4: 100000000 | T4: =+S4/Q4 -> 486646.42 | U4: =+S4/R4 -> 546878.42 | W4: T2 | X4: =+T4 -> 486646.42
A5: 22 | B5: =+'3,43'!K21 -> 320.46 | C5: =+'3,43'!M21 -> 323.496 | H5: 276.792 | I5: 279.06 | K5: 256.512 | L5: 262.524 | N5: T3 | O5: jul-sept | P5: 0.0441 | Q5: 205.488 | R5: 182.856 | S5: 100000000 | T5: =+S5/Q5 -> 486646.42 | U5: =+S5/R5 -> 546878.42 | W5: T3 | X5: =+T5 -> 486646.42
A6: 23 | B6: =+'3,43'!K22 -> 319.224 | C6: =+'3,43'!M22 -> 322.332 | H6: 276 | I6: 278.328 | K6: 255.636 | L6: 261.828 | N6: T4 | O6: oct-dic | P6: 0.0414 | Q6: 212.448 | R6: 188.28 | S6: 100000000 | T6: =+S6/Q6 -> 470703.42 | U6: =+S6/R6 -> 531123.86 | W6: T4 | X6: =+T6 -> 470703.42
A7: 24 | B7: =+'3,43'!K23 -> 317.94 | C7: =+'3,43'!M23 -> 321.12 | H7: 275.172 | I7: 277.56 | K7: 254.724 | L7: 261.108
A8: 25 | B8: =+'3,43'!K24 -> 316.608 | C8: =+'3,43'!M24 -> 319.86 | H8: 274.308 | I8: 276.756 | K8: 253.776 | L8: 260.352 | N8: 4,41% v/s 4,14% | O8: Var Pensión | W8: Hombre | X8: Pensión
A9: 26 | B9: =+'3,43'!K25 -> 315.228 | C9: =+'3,43'!M25 -> 318.564 | H9: 273.408 | I9: 275.928 | K9: 252.792 | L9: 259.56 | N9: Mujer | O9: =+T6-T5 -> -15943.003 | W9: T1 | X9: =+U3 -> 546878.42
A10: 27 | B10: =+'3,43'!K26 -> 313.812 | C10: =+'3,43'!M26 -> 317.208 | H10: 272.46 | I10: 275.052 | K10: 251.76 | L10: 258.732 | N10: Hombre | O10: =+U6-U5 -> -15754.56 | W10: T2 | X10: =+U4 -> 546878.42
A11: 28 | B11: =+'3,43'!K27 -> 312.336 | C11: =+'3,43'!M27 -> 315.804 | H11: 271.488 | I11: 274.14 | K11: 250.692 | L11: 257.868 | W11: T3 | X11: =+U5 -> 546878.42
A12: 29 | B12: =+'3,43'!K28 -> 310.812 | C12: =+'3,43'!M28 -> 314.364 | H12: 270.468 | I12: 273.192 | K12: 249.576 | L12: 256.956 | W12: T4 | X12: =+U6 -> 531123.86
A13: 30 | B13: =+'3,43'!K29 -> 309.24 | C13: =+'3,43'!M29 -> 312.864 | H13: 269.412 | I13: 272.196 | K13: 248.412 | L13: 256.008
A14: 31 | B14: =+'3,43'!K30 -> 307.596 | C14: =+'3,43'!M30 -> 311.304 | H14: 268.308 | I14: 271.164 | K14: 247.2 | L14: 255.024
A15: 32 | B15: =+'3,43'!K31 -> 305.904 | C15: =+'3,43'!M31 -> 309.696 | H15: 267.156 | I15: 270.096 | K15: 245.94 | L15: 254.004
A16: 33 | B16: =+'3,43'!K32 -> 304.164 | C16: =+'3,43'!M32 -> 308.04 | H16: 265.956 | I16: 268.968 | K16: 244.62 | L16: 252.924
A17: 34 | B17: =+'3,43'!K33 -> 302.352 | C17: =+'3,43'!M33 -> 306.312 | H17: 264.708 | I17: 267.804 | K17: 243.252 | L17: 251.808
A18: 35 | B18: =+'3,43'!K34 -> 300.48 | C18: =+'3,43'!M34 -> 304.536 | H18: 263.4 | I18: 266.58 | K18: 241.824 | L18: 250.644
A19: 36 | B19: =+'3,43'!K35 -> 298.536 | C19: =+'3,43'!M35 -> 302.688 | H19: 262.044 | I19: 265.308 | K19: 240.336 | L19: 249.42
A20: 37 | B20: =+'3,43'!K36 -> 296.532 | C20: =+'3,43'!M36 -> 300.78 | H20: 260.628 | I20: 263.988 | K20: 238.788 | L20: 248.16
A21: 38 | B21: =+'3,43'!K37 -> 294.456 | C21: =+'3,43'!M37 -> 298.8 | H21: 259.164 | I21: 262.608 | K21: 237.168 | L21: 246.84
A22: 39 | B22: =+'3,43'!K38 -> 292.308 | C22: =+'3,43'!M38 -> 296.76 | H22: 257.628 | I22: 261.168 | K22: 235.476 | L22: 245.46
A23: 40 | B23: =+'3,43'!K39 -> 290.076 | C23: =+'3,43'!M39 -> 294.636 | H23: 256.032 | I23: 259.68 | K23: 233.712 | L23: 244.02
A24: 41 | B24: =+'3,43'!K40 -> 287.784 | C24: =+'3,43'!M40 -> 292.452 | H24: 254.364 | I24: 258.12 | K24: 231.888 | L24: 242.52
... A73: 90 | B73: =+'3,43'!K89 -> 73.644 | C73: =+'3,43'!M89 -> 73.8 | H73: 71.16 | I73: 71.388 | K73: 51.984 | L73: 63.492

Sheet 3,43
A1: Depto. Trámite de Pensiones
A2: Proceso de Negocio: Trámitación Análisis.
A4: Id. Usuario: LZUNIGA
A7: CÁLCULO DE SERIES CNU
A9: Fecha: 09-01-2025 - 16:53:37
B12: (1) Causante Hombre con Beneficiarios
B13: (2) Causante Mujer con Beneficiarios
B14: CAPITALES NECESARIOS UNITARIOS | J14: TABLA RESULTADO TU NÚMERO
B16: Utilizando Tabla RV-2020 | J16: CNU x 12
B18: Edad | C18: Masculino (1) | E18: Femenino (2) | K18: Masculino (1) | M18: Femenino (2)
B19: 20 | C19: 26.902 | E19: 27.143 | K19: 322.824 | M19: 325.716
B20: 21 | C20: 26.805 | E20: 27.052 | K20: 321.66 | M20: 324.624
B21: 22 | C21: 26.705 | E21: 26.958 | K21: 320.46 | M21: 323.496
B22: 23 | C22: 26.602 | E22: 26.861 | K22: 319.224 | M22: 322.332
B23: 24 | C23: 26.495 | E23: 26.76 | K23: 317.94 | M23: 321.12
B24: 25 | C24: 26.384 | E24: 26.655 | K24: 316.608 | M24: 319.86
B25: 26 | C25: 26.269 | E25: 26.547 | K25: 315.228 | M25: 318.564
B26: 27 | C26: 26.151 | E26: 26.434 | K26: 313.812 | M26: 317.208
B27: 28 | C27: 26.028 | E27: 26.317 | K27: 312.336 | M27: 315.804
B28: 29 | C28: 25.901 | E28: 26.197 | K28: 310.812 | M28: 314.364
B29: 30 | C29: 25.77 | E29: 26.072 | K29: 309.24 | M29: 312.864
B30: 31 | C30: 25.633 | E30: 25.942 | K30: 307.596 | M30: 311.304
... B89: 90 | C89: 6.137 | E89: 6.15 | K89: 73.644 | M89: 73.8

Sheet 4,14
A1: Depto. Trámite de Pensiones
A2: Proceso de Negocio: Trámitación Análisis.
A4: Id. Usuario: CLUENGO
A7: CÁLCULO DE SERIES CNU
A9: Fecha: 07-10-2024 - 11:07:18
B12: (1) Causante Hombre con Beneficiarios
B13: (2) Causante Mujer con Beneficiarios
B14: CAPITALES NECESARIOS UNITARIOS | J14: TABLA RESULTADO TU NÚMERO
B16: Utilizando Tabla RV-2020 | J16: CNU x 12
B18: Edad | C18: Masculino (1) | E18: Femenino (2) | K18: Masculino (1) | M18: Femenino (2)
B19: 20 | C19: 23.191 | E19: 23.37 | K19: 278.292 | M19: 280.44
B20: 21 | C20: 23.13 | E20: 23.314 | K20: 277.56 | M20: 279.768
B21: 22 | C21: 23.066 | E21: 23.255 | K21: 276.792 | M21: 279.06
B22: 23 | C22: 23 | E22: 23.194 | K22: 276 | M22: 278.328
B23: 24 | C23: 22.931 | E23: 23.13 | K23: 275.172 | M23: 277.56
B24: 25 | C24: 22.859 | E24: 23.063 | K24: 274.308 | M24: 276.756
B25: 26 | C25: 22.784 | E25: 22.994 | K25: 273.408 | M25: 275.928
B26: 27 | C26: 22.705 | E26: 22.921 | K26: 272.46 | M26: 275.052
B27: 28 | C27: 22.624 | E27: 22.845 | K27: 271.488 | M27: 274.14
B28: 29 | C28: 22.539 | E28: 22.766 | K28: 270.468 | M28: 273.192
B29: 30 | C29: 22.451 | E29: 22.683 | K29: 269.412 | M29: 272.196
B30: 31 | C30: 22.359 | E30: 22.597 | K30: 268.308 | M30: 271.164
... B89: 90 | C89: 5.93 | E89: 5.949 | K89: 71.16 | M89: 71.388

Sheet 4,41
A1: Depto. Trámite de Pensiones
A2: Proceso de Negocio: Trámitación Análisis.
A4: Id. Usuario: CLUENGO
A7: CÁLCULO DE SERIES CNU
A9: Fecha: 15-04-2024 - 11:55:02
B12: (1) Causante Hombre con Beneficiarios
B13: (2) Causante Mujer con Beneficiarios
B14: CAPITALES NECESARIOS UNITARIOS | J14: TABLA RESULTADO TU NÚMERO
B16: Utilizando Tabla RV-2020 | J16: CNU x 12
B18: Edad | C18: Masculino (1) | E18: Femenino (2) | K18: Masculino (1) | M18: Femenino (2)
B19: 20 | C19: 22.012 | E19: 22.172 | K19: 264.144 | M19: 266.064
B20: 21 | C20: 21.96 | E20: 22.125 | K20: 263.52 | M20: 265.5
B21: 22 | C21: 21.906 | E21: 22.076 | K21: 262.872 | M21: 264.912
B22: 23 | C22: 21.85 | E22: 22.024 | K22: 262.2 | M22: 264.288
B23: 24 | C23: 21.791 | E23: 21.971 | K23: 261.492 | M23: 263.652
B24: 25 | C24: 21.73 | E24: 21.914 | K24: 260.76 | M24: 262.968
B25: 26 | C25: 21.666 | E25: 21.855 | K25: 259.992 | M25: 262.26
B26: 27 | C26: 21.599 | E26: 21.794 | K26: 259.188 | M26: 261.528
B27: 28 | C27: 21.529 | E27: 21.729 | K27: 258.348 | M27: 260.748
B28: 29 | C28: 21.457 | E28: 21.661 | K28: 257.484 | M28: 259.932
B29: 30 | C29: 21.381 | E29: 21.591 | K29: 256.572 | M29: 259.092
B30: 31 | C30: 21.301 | E30: 21.517 | K30: 255.612 | M30: 258.204
... B89: 90 | C89: 5.865 | E89: 5.885 | K89: 70.38 | M89: 70.62

Sheet 2.VF
B1: SALDO | H1: FLUJO
A2: Fondo | B2: A | C2: B | D2: C | E2: D | F2: E | G2: A-B | H2: A | I2: B | J2: C | K2: D | L2: E | M2: A-B | N2: D-E
A3: Plazos | B3: 0.0449 | C3: 0.0402 | D3: 0.0338 | E3: 0.0281 | F3: 0.0217 | G3: 0.0449 | H3: 0.0449 | I3: 0.0402 | J3: 0.0338 | K3: 0.0281 | L3: 0.0217 | M3: 0.0449 | N3: 0.0281
A4: 0 | B4: 0 | C4: 0 | D4: 0 | E4: 0 | F4: 0 | G4: 0 | H4: 0 | I4: 0 | J4: 0 | K4: 0 | L4: 0 | M4: 0 | N4: 0
A5: 1 | B5: 1.045 | C5: 1.04 | D5: 1.034 | E5: 1.028 | F5: 1.022 | G5: 1.045 | H5: 12.245 | I5: 12.22 | J5: 12.185 | K5: 12.154 | L5: 12.119 | M5: 1.045 | N5: 1.028
A6: 2 | B6: 1.092 | C6: 1.082 | D6: 1.069 | E6: 1.057 | F6: 1.044 | G6: 1.092 | H6: 25.04 | I6: 24.93 | J6: 24.781 | K6: 24.649 | L6: 24.501 | M6: 1.092 | N6: 1.057
A7: 3 | B7: 1.141 | C7: 1.126 | D7: 1.105 | E7: 1.087 | F7: 1.067 | G7: 1.141 | H7: 38.409 | I7: 38.152 | J7: 37.804 | K7: 37.495 | L7: 37.151 | M7: 1.141 | N7: 1.087
A8: 4 | B8: 1.192 | C8: 1.171 | D8: 1.142 | E8: 1.117 | F8: 1.09 | G8: 1.192 | H8: 52.379 | I8: 51.905 | J8: 51.266 | K8: 50.703 | L8: 50.076 | M8: 1.192 | N8: 1.117
A9: 5 | B9: 1.246 | C9: 1.218 | D9: 1.181 | E9: 1.149 | F9: 1.113 | G9: 1.246 | H9: 66.975 | I9: 66.211 | J9: 65.184 | K9: 64.281 | L9: 63.282 | M9: 1.246 | N9: 1.149
A10: 6 | B10: 1.302 | C10: 1.267 | D10: 1.221 | E10: 1.181 | F10: 1.137 | G10: 1.302 | H10: 82.228 | I10: 81.093 | J10: 79.572 | K10: 78.242 | L10: 76.774 | M10: 1.302 | N10: 1.181
A11: 7 | B11: 1.36 | C11: 1.318 | D11: 1.262 | E11: 1.214 | F11: 1.162 | G11: 1.36 | H11: 98.165 | I11: 96.572 | J11: 94.446 | K11: 92.594 | L11: 90.559 | M11: 1.36 | N11: 1.214
A12: 8 | B12: 1.421 | C12: 1.371 | D12: 1.305 | E12: 1.248 | F12: 1.187 | G12: 1.421 | H12: 114.817 | I12: 112.674 | J12: 109.823 | K12: 107.35 | L12: 104.643 | M12: 1.421 | N12: 1.248
A13: 9 | B13: 1.485 | C13: 1.426 | D13: 1.349 | E13: 1.283 | F13: 1.213 | G13: 1.485 | H13: 132.217 | I13: 129.423 | J13: 125.72 | K13: 122.52 | L13: 119.033 | M13: 1.485 | N13: 1.283
A14: 10 | B14: 1.551 | C14: 1.483 | D14: 1.394 | E14: 1.319 | F14: 1.239 | G14: 1.551 | H14: 150.399 | I14: 146.845 | J14: 142.154 | K14: 138.116 | L14: 133.734 | M14: 1.551 | N14: 1.319
A15: 11 | B15: 1.621 | C15: 1.543 | D15: 1.441 | E15: 1.356 | F15: 1.266 | G15: 1.621 | H15: 169.397 | I15: 164.968 | J15: 159.144 | K15: 154.151 | L15: 148.755 | M15: 1.621 | N15: 1.356
... A44: 40 | B44: 5.794 | C44: 4.838 | D44: 3.78 | E44: 3.03 | F44: 2.36 | G44: 5.794 | H44: 1307.444 | I44: 1166.658 | J44: 1002.084 | K44: 877.928 | L44: 759.597 | M44: 5.794 | N44: 3.03

Sheet 3.Ahorro
B1: Rentabilidad | C1: 0.0449
B2: Tasa | C2: =(1+C1)^(1/12)-1 -> 0.0036668053
B3: Saldo | C3: 0
B6: Años/meses | C6: =+C7*12 -> 60 | D6: =+D7*12 -> 120 | E6: =+E7*12 -> 180 | F6: =+F7*12 -> 240 | G6: =+G7*12 -> 300 | H6: =+H7*12 -> 360 | I6: =+I7*12 -> 420 | J6: =+J7*12 -> 480
B7: Ahorro | C7: 5 | D7: 10 | E7: 15 | F7: 20 | G7: 25 | H7: 30 | I7: 35 | J7: 40
B8: 1000000 | C8: =+PMT($C$2,$C$6,$C$3,B8*-1) -> 14930.853 | D8: =+PMT($C$2,$D$6,$C$3,B8*-1) -> 6648.9789 | E8: =+PMT($C$2,$E$6,$C$3,B8*-1) -> 3932.2039 | F8: =+PMT($C$2,$F$6,$C$3,B8*-1) -> 2605.9262 | G8: =+PMT($C$2,$G$6,$C$3,B8*-1) -> 1835.0058 | H8: =+PMT($C$2,$H$6,$C$3,B8*-1) -> 1340.9021 | I8: =+PMT($C$2,$I$6,$C$3,B8*-1) -> 1004.1252 | J8: =+PMT($C$2,$J$6,$C$3,B8*-1) -> 764.85113
B9: 2000000 | C9: =+PMT($C$2,$C$6,$C$3,B9*-1) -> 29861.705 | D9: =+PMT($C$2,$D$6,$C$3,B9*-1) -> 13297.958 | E9: =+PMT($C$2,$E$6,$C$3,B9*-1) -> 7864.4078 | F9: =+PMT($C$2,$F$6,$C$3,B9*-1) -> 5211.8524 | G9: =+PMT($C$2,$G$6,$C$3,B9*-1) -> 3670.0116 | H9: =+PMT($C$2,$H$6,$C$3,B9*-1) -> 2681.8042 | I9: =+PMT($C$2,$I$6,$C$3,B9*-1) -> 2008.2505 | J9: =+PMT($C$2,$J$6,$C$3,B9*-1) -> 1529.7023
B10: 3000000 | C10: =+PMT($C$2,$C$6,$C$3,B10*-1) -> 44792.558 | D10: =+PMT($C$2,$D$6,$C$3,B10*-1) -> 19946.937 | E10: =+PMT($C$2,$E$6,$C$3,B10*-1) -> 11796.612 | F10: =+PMT($C$2,$F$6,$C$3,B10*-1) -> 7817.7786 | G10: =+PMT($C$2,$G$6,$C$3,B10*-1) -> 5505.0174 | H10: =+PMT($C$2,$H$6,$C$3,B10*-1) -> 4022.7062 | I10: =+PMT($C$2,$I$6,$C$3,B10*-1) -> 3012.3757 | J10: =+PMT($C$2,$J$6,$C$3,B10*-1) -> 2294.5534
B11: 4000000 | C11: =+PMT($C$2,$C$6,$C$3,B11*-1) -> 59723.41 | D11: =+PMT($C$2,$D$6,$C$3,B11*-1) -> 26595.916 | E11: =+PMT($C$2,$E$6,$C$3,B11*-1) -> 15728.816 | F11: =+PMT($C$2,$F$6,$C$3,B11*-1) -> 10423.705 | G11: =+PMT($C$2,$G$6,$C$3,B11*-1) -> 7340.0232 | H11: =+PMT($C$2,$H$6,$C$3,B11*-1) -> 5363.6083 | I11: =+PMT($C$2,$I$6,$C$3,B11*-1) -> 4016.501 | J11: =+PMT($C$2,$J$6,$C$3,B11*-1) -> 3059.4045
B12: 5000000 | C12: =+PMT($C$2,$C$6,$C$3,B12*-1) -> 74654.263 | D12: =+PMT($C$2,$D$6,$C$3,B12*-1) -> 33244.895 | E12: =+PMT($C$2,$E$6,$C$3,B12*-1) -> 19661.02 | F12: =+PMT($C$2,$F$6,$C$3,B12*-1) -> 13029.631 | G12: =+PMT($C$2,$G$6,$C$3,B12*-1) -> 9175.029 | H12: =+PMT($C$2,$H$6,$C$3,B12*-1) -> 6704.5104 | I12: =+PMT($C$2,$I$6,$C$3,B12*-1) -> 5020.6262 | J12: =+PMT($C$2,$J$6,$C$3,B12*-1) -> 3824.2557
B13: 6000000 | C13: =+PMT($C$2,$C$6,$C$3,B13*-1) -> 89585.115 | D13: =+PMT($C$2,$D$6,$C$3,B13*-1) -> 39893.873 | E13: =+PMT($C$2,$E$6,$C$3,B13*-1) -> 23593.224 | F13: =+PMT($C$2,$F$6,$C$3,B13*-1) -> 15635.557 | G13: =+PMT($C$2,$G$6,$C$3,B13*-1) -> 11010.035 | H13: =+PMT($C$2,$H$6,$C$3,B13*-1) -> 8045.4125 | I13: =+PMT($C$2,$I$6,$C$3,B13*-1) -> 6024.7515 | J13: =+PMT($C$2,$J$6,$C$3,B13*-1) -> 4589.1068
B14: 7000000 | C14: =+PMT($C$2,$C$6,$C$3,B14*-1) -> 104515.97 | D14: =+PMT($C$2,$D$6,$C$3,B14*-1) -> 46542.852 | E14: =+PMT($C$2,$E$6,$C$3,B14*-1) -> 27525.427 | F14: =+PMT($C$2,$F$6,$C$3,B14*-1) -> 18241.483 | G14: =+PMT($C$2,$G$6,$C$3,B14*-1) -> 12845.041 | H14: =+PMT($C$2,$H$6,$C$3,B14*-1) -> 9386.3146 | I14: =+PMT($C$2,$I$6,$C$3,B14*-1) -> 7028.8767 | J14: =+PMT($C$2,$J$6,$C$3,B14*-1) -> 5353.9579
B15: 8000000 | C15: =+PMT($C$2,$C$6,$C$3,B15*-1) -> 119446.82 | D15: =+PMT($C$2,$D$6,$C$3,B15*-1) -> 53191.831 | E15: =+PMT($C$2,$E$6,$C$3,B15*-1) -> 31457.631 | F15: =+PMT($C$2,$F$6,$C$3,B15*-1) -> 20847.41 | G15: =+PMT($C$2,$G$6,$C$3,B15*-1) -> 14680.046 | H15: =+PMT($C$2,$H$6,$C$3,B15*-1) -> 10727.217 | I15: =+PMT($C$2,$I$6,$C$3,B15*-1) -> 8033.0019 | J15: =+PMT($C$2,$J$6,$C$3,B15*-1) -> 6118.809
B16: 9000000 | C16: =+PMT($C$2,$C$6,$C$3,B16*-1) -> 134377.67 | D16: =+PMT($C$2,$D$6,$C$3,B16*-1) -> 59840.81 | E16: =+PMT($C$2,$E$6,$C$3,B16*-1) -> 35389.835 | F16: =+PMT($C$2,$F$6,$C$3,B16*-1) -> 23453.336 | G16: =+PMT($C$2,$G$6,$C$3,B16*-1) -> 16515.052 | H16: =+PMT($C$2,$H$6,$C$3,B16*-1) -> 12068.119 | I16: =+PMT($C$2,$I$6,$C$3,B16*-1) -> 9037.1272 | J16: =+PMT($C$2,$J$6,$C$3,B16*-1) -> 6883.6602
B17: 10000000 | C17: =+PMT($C$2,$C$6,$C$3,B17*-1) -> 149308.53 | D17: =+PMT($C$2,$D$6,$C$3,B17*-1) -> 66489.789 | E17: =+PMT($C$2,$E$6,$C$3,B17*-1) -> 39322.039 | F17: =+PMT($C$2,$F$6,$C$3,B17*-1) -> 26059.262 | G17: =+PMT($C$2,$G$6,$C$3,B17*-1) -> 18350.058 | H17: =+PMT($C$2,$H$6,$C$3,B17*-1) -> 13409.021 | I17: =+PMT($C$2,$I$6,$C$3,B17*-1) -> 10041.252 | J17: =+PMT($C$2,$J$6,$C$3,B17*-1) -> 7648.5113
B18: 15000000 | C18: =+PMT($C$2,$C$6,$C$3,B18*-1) -> 223962.79 | D18: =+PMT($C$2,$D$6,$C$3,B18*-1) -> 99734.684 | E18: =+PMT($C$2,$E$6,$C$3,B18*-1) -> 58983.059 | F18: =+PMT($C$2,$F$6,$C$3,B18*-1) -> 39088.893 | G18: =+PMT($C$2,$G$6,$C$3,B18*-1) -> 27525.087 | H18: =+PMT($C$2,$H$6,$C$3,B18*-1) -> 20113.531 | I18: =+PMT($C$2,$I$6,$C$3,B18*-1) -> 15061.879 | J18: =+PMT($C$2,$J$6,$C$3,B18*-1) -> 11472.767
B19: 20000000 | C19: =+PMT($C$2,$C$6,$C$3,B19*-1) -> 298617.05 | D19: =+PMT($C$2,$D$6,$C$3,B19*-1) -> 132979.58 | E19: =+PMT($C$2,$E$6,$C$3,B19*-1) -> 78644.078 | F19: =+PMT($C$2,$F$6,$C$3,B19*-1) -> 52118.524 | G19: =+PMT($C$2,$G$6,$C$3,B19*-1) -> 36700.116 | H19: =+PMT($C$2,$H$6,$C$3,B19*-1) -> 26818.042 | I19: =+PMT($C$2,$I$6,$C$3,B19*-1) -> 20082.505 | J19: =+PMT($C$2,$J$6,$C$3,B19*-1) -> 15297.023
... B47: 260000000 | C47: =+PMT($C$2,$C$6,$C$3,B47*-1) -> 3882021.7 | D47: =+PMT($C$2,$D$6,$C$3,B47*-1) -> 1728734.5 | E47: =+PMT($C$2,$E$6,$C$3,B47*-1) -> 1022373 | F47: =+PMT($C$2,$F$6,$C$3,B47*-1) -> 677540.81 | G47: =+PMT($C$2,$G$6,$C$3,B47*-1) -> 477101.51 | H47: =+PMT($C$2,$H$6,$C$3,B47*-1) -> 348634.54 | I47: =+PMT($C$2,$I$6,$C$3,B47*-1) -> 261072.56 | J47: =+PMT($C$2,$J$6,$C$3,B47*-1) -> 198861.29

Sheet Motor I
B3: =+C8 -> Mujer | C3: =+VLOOKUP(B3,$B$4:$C$5,2,FALSE) -> 3 | I3: 2 | J3: 3 | K3: 4 | L3: 5 | M3: 6 | N3: 7
B4: Mujer | C4: 3 | H4: Género | I4: Desde | J4: Hasta | K4: Activo | L4: Moderado | M4: Conservador | N4: Sin Perfil | R4: Mujer | S4: Hombre
B5: Hombre | C5: 2 | G5: 2 | H5: Mujer | I5: 25 | J5: 40 | K5: A | L5: B | M5: B | N5: A-B | R5: =+COUNTIF(C8,$R$4) -> 1 | S5: =+COUNTIF(C8,$S$4) -> 0
G6: 3 | H6: Mujer | I6: 41 | J6: 50 | K6: C | L6: C | M6: C | N6: C | R6: 1 | S6: 1
G7: 4 | H7: Mujer | I7: 51 | J7: 60 | K7: D | L7: E | M7: E | N7: D-E
B8: Género | C8: =+Portada!AX18 -> Mujer | G8: 5 | H8: Hombre | I8: 25 | J8: 40 | K8: A | L8: B | M8: B | N8: A-B
B9: Edad actual | C9: =+Portada!BO18 -> 0 | G9: 6 | H9: Hombre | I9: 41 | J9: 55 | K9: C | L9: C | M9: C | N9: C
B10: Edad de pensión | C10: =+Portada!BO22 -> 0 | G10: 7 | H10: Hombre | I10: 56 | J10: 65 | K10: D | L10: E | M10: E | N10: D-E
B11: Años que faltan | C11: =+C10-C9 -> 0
B12: Monto de pensión objetivo | C12: =+Portada!BO24 -> 0 | H12: Género | I12: Edad | J12: Perfil | K12: Fondo | N12: =+J13 -> Moderado | O12: =+VLOOKUP(N12,N13:O16,2,FALSE) -> 4
B13: CNU | C13: =+VLOOKUP(C10,'1.CNU'!$A$3:$C$73,'Motor I'!$C$3) -> #N/A | H13: =+C8 -> Mujer | I13: =+HLOOKUP(I12,$I$15:$I$17,$L$15,FALSE) -> 0 | J13: =+HLOOKUP(J12,$J$15:$J$17,$L$15,FALSE) -> Moderado | K13: =+HLOOKUP(K12,$K$15:$K$17,$L$15,FALSE) -> #N/A | N13: Activo | O13: 3
B14: Saldo de pensión necesario | C14: =+C12*C13 -> #N/A | N14: Moderado | O14: 4
B15: Promedio de cotizaciones | C15: =+Portada!BO20 -> 0 | I15: Edad | J15: Perfil | K15: Fondo | L15: =+VLOOKUP($H$13,$H$16:$L$17,5,FALSE) -> 2 | N15: Conservador | O15: 5
B16: Tope | C16: 87.8 | H16: Mujer | I16: =+C9 -> 0 | J16: =+Portada!CH18 -> Moderado | K16: =+VLOOKUP(I16,I5:N7,$O$12,TRUE) -> #N/A | L16: 2 | N16: Sin Perfil | O16: 6
B17: UF | C17: 39179.01 | H17: Hombre | I17: =+C9 -> 0 | J17: =+Portada!CH18 -> Moderado | K17: =+VLOOKUP(I17,I8:N10,$O$12,TRUE) -> #N/A | L17: 3
B18: Cotización Maxima | C18: =+C16*C17 -> 3439917.1
B19: Cotización mensual | C19: =+MIN((C18*10%),(C15*10%)) -> 0
B21: Fondo | C21: =+C33 -> #N/A | E21: =+C21 -> #N/A | F21: =+VLOOKUP(E21,$H$38:$I$44,2,FALSE) -> #N/A | G21: =+VLOOKUP(E21,$E$22:$F$26,2,FALSE) -> #N/A | H21: Mujer | I21: 2 | J21: 2 | K21: 2 | L21: 2 | M21: 2 | N21: 2
B22: Rentabilidad | C22: =+HLOOKUP(C21,'2.VF'!$B$2:$F$3,2,FALSE) -> #N/A | E22: A | F22: 2 | H22: Mujer | I22: 3 | J22: 3 | K22: 3 | L22: 3 | M22: 3 | N22: 3
B23: Saldos actuales | E23: B | F23: 3 | H23: Mujer | I23: 4 | J23: 4 | K23: 4 | L23: 4 | M23: 4 | N23: 4
B24: Factor | C24: =+VLOOKUP($C$11,'2.VF'!$A$4:$G$44,'Motor I'!$G$21,FALSE) -> #REF! | E24: C | F24: 4 | H24: Hombre | I24: 5 | J24: 5 | K24: 5 | L24: 5 | M24: 5 | N24: 5
B25: CCIO | C25: 0 | E25: D | F25: 5 | H25: Hombre | I25: 6 | J25: 6 | K25: 6 | L25: 6 | M25: 6 | N25: 6
B26: APV A | C26: 0 | E26: E | F26: 6 | H26: Hombre | I26: 7 | J26: 7 | K26: 7 | L26: 7 | M26: 7 | N26: 7
B27: APV B | C27: 0
B28: Depositos convenidos | C28: 0 | H28: Género | I28: Desde | J28: Hasta | K28: Activo | L28: Moderado | M28: Conservador | N28: Sin Perfil
B29: Cuenta dos | C29: 0 | H29: Hombre | I29: =+IF($H$29=$H$13,I24,I21) -> 2 | J29: =+IF($H$29=$H$13,J24,J21) -> 2 | K29: =+IF($H$31=$H$13,K24,K21) -> 2 | L29: =+IF($H$31=$H$13,L24,L21) -> 2 | M29: =+IF($H$29=$H$13,M24,M21) -> 2 | N29: =+IF($H$29=$H$13,N24,N21) -> 2
B30: Total saldos | C30: =SUM(C25:C29) -> 0 | H30: Hombre | I30: =+IF($H$30=$H$13,I25,I22) -> 3 | J30: =+IF($H$30=$H$13,J25,J22) -> 3 | K30: =+IF($H$30=$H$13,K25,K22) -> 3 | L30: =+IF($H$30=$H$13,L25,L22) -> 3 | M30: =+IF($H$30=$H$13,M25,M22) -> 3 | N30: =+IF($H$30=$H$13,N25,N22) -> 3
H31: Hombre | I31: =+IF($H$31=$H$13,I26,I23) -> 4 | J31: =+IF($H$31=$H$13,J26,J23) -> 4 | K31: =+IF($H$31=$H$13,K26,K23) -> 4 | L31: =+IF($H$31=$H$13,L26,L23) -> 4 | M31: =+IF($H$31=$H$13,M26,M23) -> 4 | N31: =+IF($H$31=$H$13,N26,N23) -> 4
B33: Fondo | C33: =+J38 -> #N/A | E33: =+C33 -> #N/A | F33: =+VLOOKUP(E33,$E$34:$F$38,2,FALSE) -> #N/A | H33: Género | I33: Desde | J33: Hasta | K33: Activo | L33: Moderado | M33: Conservador | N33: Sin Perfil
B34: Rentabilidad | C34: =+HLOOKUP(C33,'2.VF'!$H$2:$L$3,2,FALSE) -> #N/A | E34: A | F34: 7 | H34: =+HLOOKUP(H33,H4:H10,5,FALSE) -> Hombre | I34: =+HLOOKUP(I33,I4:I10,I29,FALSE) -> 25 | J34: =+HLOOKUP(J33,J4:J10,J29,FALSE) -> 40 | K34: =+HLOOKUP(K33,K4:K10,K29,FALSE) -> A | L34: =+HLOOKUP(L33,L4:L10,L29,FALSE) -> B | M34: =+HLOOKUP(M33,M4:M10,M29,FALSE) -> B | N34: =+HLOOKUP(N33,N4:N10,N29,FALSE) -> A-B
B35: Flujo mensual | E35: B | F35: 8 | H35: =+HLOOKUP(H33,H4:H10,6,FALSE) -> Hombre | I35: =+HLOOKUP(I33,I4:I10,I30,FALSE) -> 41 | J35: =+HLOOKUP(J33,J4:J10,J30,FALSE) -> 50 | K35: =+HLOOKUP(K33,K4:K10,K30,FALSE) -> C | L35: =+HLOOKUP(L33,L4:L10,L30,FALSE) -> C | M35: =+HLOOKUP(M33,M4:M10,M30,FALSE) -> C | N35: =+HLOOKUP(N33,N4:N10,N30,FALSE) -> C
B36: Factor | C36: =+VLOOKUP(C11,'2.VF'!$A$5:$L$44,'Motor I'!$F$33) -> #N/A | E36: C | F36: 9 | H36: =+HLOOKUP(H33,H4:H10,7,FALSE) -> Hombre | I36: =+HLOOKUP(I33,I4:I10,I31,FALSE) -> 51 | J36: =+HLOOKUP(J33,J4:J10,J31,FALSE) -> 60 | K36: =+HLOOKUP(K33,K4:K10,K31,FALSE) -> D | L36: =+HLOOKUP(L33,L4:L10,L31,FALSE) -> E | M36: =+HLOOKUP(M33,M4:M10,M31,FALSE) -> E | N36: =+HLOOKUP(N33,N4:N10,N31,FALSE) -> D-E
B37: CCIO | C37: =+C19 -> 0 | E37: D | F37: 10
B38: APV A | C38: 0 | E38: E | F38: 11 | H38: A | I38: 0.0449 | J38: =+K13 -> #N/A | K38: =+VLOOKUP(J38,$H$38:$I$44,2,FALSE) -> #N/A
B39: APV B | C39: 0 | E39: A-B | F39: 7 | H39: B | I39: 0.0402
B40: Depositos convenidos | C40: 0 | E40: D-E | F40: 10 | H40: C | I40: 0.0338
B41: Cuenta dos | C41: 0 | H41: D | I41: 0.0281
B42: Total flujos | C42: =SUM(C37:C41) -> 0 | H42: E | I42: 0.0217
H43: A-B | I43: 0.0449
H44: D-E | I44: 0.0217
...

Sheet Pension proyectada I
A1: Plazo | B1: Meses | C1: Saldo actual | D1: Mensual | E1: Rentabilidad | F1: Cotizacion Obligatoria | G1: APV | H1: Deposito convenido | I1: Total Aporte mensual | J1: Saldo al Final del Periodo | K1: Rentabilidad Mensual | L1: Rentabilidad del año | M1: Aportes del año | N1: variación del saldo
A2: 0 | B2: 0 | C2: =+Portada!DS19 -> 0 | D2: 0 | E2: 0 | F2: 0 | G2: 0 | H2: 0 | I2: 0 | J2: =+C2 -> 0 | K2: 0 | L2: 0 | M2: 0 | N2: 0
A3: 1 | B3: 12 | C3: =+Portada!$DS$19 -> 0 | D3: =(1+E3)^(1/12)-1 -> #N/A | E3: =+'Motor I'!$C$59 -> #N/A | F3: =+'Motor I'!$C$19*-1 -> 0 | G3: 0 | H3: 0 | I3: =+F3+G3+H3 -> 0 | J3: =FV(D3,B3,I3,-C3) -> #N/A | K3: =(C3*D3) -> #N/A | L3: =(K3*12) -> #N/A | M3: =(F3*12) -> 0 | N3: =(L3-M3) -> #N/A
A4: 2 | B4: 12 | C4: =+J3 -> #N/A | D4: =(1+E4)^(1/12)-1 -> #N/A | E4: =+'Motor I'!$C$59 -> #N/A | F4: =+'Motor I'!$C$19*-1 -> 0 | G4: 0 | H4: 0 | I4: =+F4+G4+H4 -> 0 | J4: =FV(D4,B4,I4,-C4) -> #N/A | K4: =(C4*D4) -> #N/A | L4: =(K4*12) -> #N/A | M4: =(F4*12) -> 0 | N4: =(L4-M4) -> #N/A
A5: 3 | B5: 12 | C5: =+J4 -> #N/A | D5: =(1+E5)^(1/12)-1 -> #N/A | E5: =+'Motor I'!$C$59 -> #N/A | F5: =+'Motor I'!$C$19*-1 -> 0 | G5: 0 | H5: 0 | I5: =+F5+G5+H5 -> 0 | J5: =FV(D5,B5,I5,-C5) -> #N/A | K5: =(C5*D5) -> #N/A | L5: =(K5*12) -> #N/A | M5: =(F5*12) -> 0 | N5: =(L5-M5) -> #N/A
A6: 4 | B6: 12 | C6: =+J5 -> #N/A | D6: =(1+E6)^(1/12)-1 -> #N/A | E6: =+'Motor I'!$C$59 -> #N/A | F6: =+'Motor I'!$C$19*-1 -> 0 | G6: 0 | H6: 0 | I6: =+F6+G6+H6 -> 0 | J6: =FV(D6,B6,I6,-C6) -> #N/A | K6: =(C6*D6) -> #N/A | L6: =(K6*12) -> #N/A | M6: =(F6*12) -> 0 | N6: =(L6-M6) -> #N/A
A7: 5 | B7: 12 | C7: =+J6 -> #N/A | D7: =(1+E7)^(1/12)-1 -> #N/A | E7: =+'Motor I'!$C$59 -> #N/A | F7: =+'Motor I'!$C$19*-1 -> 0 | G7: 0 | H7: 0 | I7: =+F7+G7+H7 -> 0 | J7: =FV(D7,B7,I7,-C7) -> #N/A | K7: =(C7*D7) -> #N/A | L7: =(K7*12) -> #N/A | M7: =(F7*12) -> 0 | N7: =(L7-M7) -> #N/A
A8: 6 | B8: 12 | C8: =+J7 -> #N/A | D8: =(1+E8)^(1/12)-1 -> #N/A | E8: =+'Motor I'!$C$59 -> #N/A | F8: =+'Motor I'!$C$19*-1 -> 0 | G8: 0 | H8: 0 | I8: =+F8+G8+H8 -> 0 | J8: =FV(D8,B8,I8,-C8) -> #N/A | K8: =(C8*D8) -> #N/A | L8: =(K8*12) -> #N/A | M8: =(F8*12) -> 0 | N8: =(L8-M8) -> #N/A
A9: 7 | B9: 12 | C9: =+J8 -> #N/A | D9: =(1+E9)^(1/12)-1 -> #N/A | E9: =+'Motor I'!$C$59 -> #N/A | F9: =+'Motor I'!$C$19*-1 -> 0 | G9: 0 | H9: 0 | I9: =+F9+G9+H9 -> 0 | J9: =FV(D9,B9,I9,-C9) -> #N/A | K9: =(C9*D9) -> #N/A | L9: =(K9*12) -> #N/A | M9: =(F9*12) -> 0 | N9: =(L9-M9) -> #N/A
A10: 8 | B10: 12 | C10: =+J9 -> #N/A | D10: =(1+E10)^(1/12)-1 -> #N/A | E10: =+'Motor I'!$C$59 -> #N/A | F10: =+'Motor I'!$C$19*-1 -> 0 | G10: 0 | H10: 0 | I10: =+F10+G10+H10 -> 0 | J10: =FV(D10,B10,I10,-C10) -> #N/A | K10: =(C10*D10) -> #N/A | L10: =(K10*12) -> #N/A | M10: =(F10*12) -> 0 | N10: =(L10-M10) -> #N/A
A11: 9 | B11: 12 | C11: =+J10 -> #N/A | D11: =(1+E11)^(1/12)-1 -> #N/A | E11: =+'Motor I'!$C$59 -> #N/A | F11: =+'Motor I'!$C$19*-1 -> 0 | G11: 0 | H11: 0 | I11: =+F11+G11+H11 -> 0 | J11: =FV(D11,B11,I11,-C11) -> #N/A | K11: =(C11*D11) -> #N/A | L11: =(K11*12) -> #N/A | M11: =(F11*12) -> 0 | N11: =(L11-M11) -> #N/A
A12: 10 | B12: 12 | C12: =+J11 -> #N/A | D12: =(1+E12)^(1/12)-1 -> #N/A | E12: =+'Motor I'!$C$59 -> #N/A | F12: =+'Motor I'!$C$19*-1 -> 0 | G12: 0 | H12: 0 | I12: =+F12+G12+H12 -> 0 | J12: =FV(D12,B12,I12,-C12) -> #N/A | K12: =(C12*D12) -> #N/A | L12: =(K12*12) -> #N/A | M12: =(F12*12) -> 0 | N12: =(L12-M12) -> #N/A
A13: 11 | B13: 12 | C13: =+J12 -> #N/A | D13: =(1+E13)^(1/12)-1 -> #N/A | E13: =+'Motor I'!$C$59 -> #N/A | F13: =+'Motor I'!$C$19*-1 -> 0 | G13: 0 | H13: 0 | I13: =+F13+G13+H13 -> 0 | J13: =FV(D13,B13,I13,-C13) -> #N/A | K13: =(C13*D13) -> #N/A | L13: =(K13*12) -> #N/A | M13: =(F13*12) -> 0 | N13: =(L13-M13) -> #N/A
A14: 12 | B14: 12 | C14: =+J13 -> #N/A | D14: =(1+E14)^(1/12)-1 -> #N/A | E14: =+'Motor I'!$C$59 -> #N/A | F14: =+'Motor I'!$C$19*-1 -> 0 | G14: 0 | H14: 0 | I14: =+F14+G14+H14 -> 0 | J14: =FV(D14,B14,I14,-C14) -> #N/A | K14: =(C14*D14) -> #N/A | L14: =(K14*12) -> #N/A | M14: =(F14*12) -> 0 | N14: =(L14-M14) -> #N/A
A15: 13 | B15: 12 | C15: =+J14 -> #N/A | D15: =(1+E15)^(1/12)-1 -> #N/A | E15: =+'Motor I'!$C$59 -> #N/A | F15: =+'Motor I'!$C$19*-1 -> 0 | G15: 0 | H15: 0 | I15: =+F15+G15+H15 -> 0 | J15: =FV(D15,B15,I15,-C15) -> #N/A | K15: =(C15*D15) -> #N/A | L15: =(K15*12) -> #N/A | M15: =(F15*12) -> 0 | N15: =(L15-M15) -> #N/A
... A42: 40 | B42: 12 | C42: =+J41 -> #N/A | D42: =(1+E42)^(1/12)-1 -> #N/A | E42: =+'Motor I'!$C$59 -> #N/A | F42: =+'Motor I'!$C$19*-1 -> 0 | G42: 0 | H42: 0 | I42: =+F42+G42+H42 -> 0 | J42: =FV(D42,B42,I42,-C42) -> #N/A | K42: =(C42*D42) -> #N/A | L42: =(K42*12) -> #N/A | M42: =(F42*12) -> 0 | N42: =(L42-M42) -> #N/A

Sheet Motor II
B3: =+C8 -> Mujer | C3: =+VLOOKUP(B3,$B$4:$C$5,2,FALSE) -> 3 | I3: 2 | J3: 3 | K3: 4 | L3: 5 | M3: 6 | N3: 7
B4: Mujer | C4: 3 | H4: Género | I4: Desde | J4: Hasta | K4: Activo | L4: Moderado | M4: Conservador | N4: Sin Perfil | R4: Mujer | S4: Hombre
B5: Hombre | C5: 2 | G5: 2 | H5: Mujer | I5: 25 | J5: 40 | K5: A | L5: B | M5: B | N5: A-B | R5: =+COUNTIF(C8,$R$4) -> 1 | S5: =+COUNTIF(C8,$S$4) -> 0
G6: 3 | H6: Mujer | I6: 41 | J6: 50 | K6: C | L6: C | M6: C | N6: C | R6: 1 | S6: 1
G7: 4 | H7: Mujer | I7: 51 | J7: 60 | K7: D | L7: E | M7: E | N7: D-E
B8: Género | C8: =+Portada!AX18 -> Mujer | G8: 5 | H8: Hombre | I8: 25 | J8: 40 | K8: A | L8: B | M8: B | N8: A-B
B9: Edad actual | C9: =+Portada!BO18 -> 0 | G9: 6 | H9: Hombre | I9: 41 | J9: 55 | K9: C | L9: C | M9: C | N9: C
B10: Edad de pensión | C10: =+Portada!BO22 -> 0 | G10: 7 | H10: Hombre | I10: 56 | J10: 65 | K10: D | L10: E | M10: E | N10: D-E
B11: Años que faltan | C11: =+C10-C9 -> 0
B12: Monto de pensión objetivo | C12: =+Portada!BO24 -> 0 | H12: Género | I12: Edad | J12: Perfil | K12: Fondo | N12: =+J13 -> Moderado | O12: =+VLOOKUP(N12,N13:O16,2,FALSE) -> 4
B13: CNU | C13: =+VLOOKUP(C10,'1.CNU'!$A$3:$C$73,'Motor II'!$C$3) -> #N/A | H13: =+C8 -> Mujer | I13: =+HLOOKUP(I12,$I$15:$I$17,$L$15,FALSE) -> 0 | J13: =+HLOOKUP(J12,$J$15:$J$17,$L$15,FALSE) -> Moderado | K13: =+HLOOKUP(K12,$K$15:$K$17,$L$15,FALSE) -> #N/A | N13: Activo | O13: 3
B14: Saldo de pensión necesario | C14: =+C12*C13 -> #N/A | N14: Moderado | O14: 4
B15: Promedio de cotizaciones | C15: =+Portada!BO20 -> 0 | I15: Edad | J15: Perfil | K15: Fondo | L15: =+VLOOKUP($H$13,$H$16:$L$17,5,FALSE) -> 2 | N15: Conservador | O15: 5
B16: Tope | C16: 87.8 | H16: Mujer | I16: =+C9 -> 0 | J16: =+Portada!CH18 -> Moderado | K16: =+VLOOKUP(I16,I5:N7,$O$12,TRUE) -> #N/A | L16: 2 | N16: Sin Perfil | O16: 6
B17: UF | C17: 37754.47 | H17: Hombre | I17: =+C9 -> 0 | J17: =+Portada!CH18 -> Moderado | K17: =+VLOOKUP(I17,I8:N10,$O$12,TRUE) -> #N/A | L17: 3
B18: Cotización Maxima | C18: =+C16*C17 -> 3314842.5
B19: Cotización mensual | C19: =+MIN((C18*10%),(C15*10%)) -> 0
B21: Fondo | C21: =+C33 -> #N/A | E21: =+C21 -> #N/A | F21: =+VLOOKUP(E21,$H$38:$I$44,2,FALSE) -> #N/A | G21: =+VLOOKUP(E21,$E$22:$F$26,2,FALSE) -> #N/A | H21: Mujer | I21: 2 | J21: 2 | K21: 2 | L21: 2 | M21: 2 | N21: 2
B22: Rentabilidad | C22: =+HLOOKUP(C21,'2.VF'!$B$2:$F$3,2,FALSE) -> #N/A | E22: A | F22: 2 | H22: Mujer | I22: 3 | J22: 3 | K22: 3 | L22: 3 | M22: 3 | N22: 3
B23: Saldos actuales | E23: B | F23: 3 | H23: Mujer | I23: 4 | J23: 4 | K23: 4 | L23: 4 | M23: 4 | N23: 4
B24: Factor | C24: =+VLOOKUP($C$11,'2.VF'!$A$4:$G$44,'Motor II'!$G$21,FALSE) -> #REF! | E24: C | F24: 4 | H24: Hombre | I24: 5 | J24: 5 | K24: 5 | L24: 5 | M24: 5 | N24: 5
B25: CCIO | C25: 0 | E25: D | F25: 5 | H25: Hombre | I25: 6 | J25: 6 | K25: 6 | L25: 6 | M25: 6 | N25: 6
B26: APV A | C26: 0 | E26: E | F26: 6 | H26: Hombre | I26: 7 | J26: 7 | K26: 7 | L26: 7 | M26: 7 | N26: 7
B27: APV B | C27: 0
B28: Depositos convenidos | C28: 0 | H28: Género | I28: Desde | J28: Hasta | K28: Activo | L28: Moderado | M28: Conservador | N28: Sin Perfil
B29: Cuenta dos | C29: 0 | H29: Hombre | I29: =+IF($H$29=$H$13,I24,I21) -> 2 | J29: =+IF($H$29=$H$13,J24,J21) -> 2 | K29: =+IF($H$31=$H$13,K24,K21) -> 2 | L29: =+IF($H$31=$H$13,L24,L21) -> 2 | M29: =+IF($H$29=$H$13,M24,M21) -> 2 | N29: =+IF($H$29=$H$13,N24,N21) -> 2
B30: Total saldos | C30: =SUM(C25:C29) -> 0 | H30: Hombre | I30: =+IF($H$30=$H$13,I25,I22) -> 3 | J30: =+IF($H$30=$H$13,J25,J22) -> 3 | K30: =+IF($H$30=$H$13,K25,K22) -> 3 | L30: =+IF($H$30=$H$13,L25,L22) -> 3 | M30: =+IF($H$30=$H$13,M25,M22) -> 3 | N30: =+IF($H$30=$H$13,N25,N22) -> 3
H31: Hombre | I31: =+IF($H$31=$H$13,I26,I23) -> 4 | J31: =+IF($H$31=$H$13,J26,J23) -> 4 | K31: =+IF($H$31=$H$13,K26,K23) -> 4 | L31: =+IF($H$31=$H$13,L26,L23) -> 4 | M31: =+IF($H$31=$H$13,M26,M23) -> 4 | N31: =+IF($H$31=$H$13,N26,N23) -> 4
B33: Fondo | C33: =+J38 -> #N/A | E33: =+C33 -> #N/A | F33: =+VLOOKUP(E33,$E$34:$F$38,2,FALSE) -> #N/A | H33: Género | I33: Desde | J33: Hasta | K33: Activo | L33: Moderado | M33: Conservador | N33: Sin Perfil
B34: Rentabilidad | C34: =+HLOOKUP(C33,'2.VF'!$H$2:$L$3,2,FALSE) -> #N/A | E34: A | F34: 7 | H34: =+HLOOKUP(H33,H4:H10,5,FALSE) -> Hombre | I34: =+HLOOKUP(I33,I4:I10,I29,FALSE) -> 25 | J34: =+HLOOKUP(J33,J4:J10,J29,FALSE) -> 40 | K34: =+HLOOKUP(K33,K4:K10,K29,FALSE) -> A | L34: =+HLOOKUP(L33,L4:L10,L29,FALSE) -> B | M34: =+HLOOKUP(M33,M4:M10,M29,FALSE) -> B | N34: =+HLOOKUP(N33,N4:N10,N29,FALSE) -> A-B
B35: Flujo mensual | E35: B | F35: 8 | H35: =+HLOOKUP(H33,H4:H10,6,FALSE) -> Hombre | I35: =+HLOOKUP(I33,I4:I10,I30,FALSE) -> 41 | J35: =+HLOOKUP(J33,J4:J10,J30,FALSE) -> 50 | K35: =+HLOOKUP(K33,K4:K10,K30,FALSE) -> C | L35: =+HLOOKUP(L33,L4:L10,L30,FALSE) -> C | M35: =+HLOOKUP(M33,M4:M10,M30,FALSE) -> C | N35: =+HLOOKUP(N33,N4:N10,N30,FALSE) -> C
B36: Factor | C36: =+VLOOKUP(C11,'2.VF'!$A$5:$L$44,'Motor II'!$F$33) -> #N/A | E36: C | F36: 9 | H36: =+HLOOKUP(H33,H4:H10,7,FALSE) -> Hombre | I36: =+HLOOKUP(I33,I4:I10,I31,FALSE) -> 51 | J36: =+HLOOKUP(J33,J4:J10,J31,FALSE) -> 60 | K36: =+HLOOKUP(K33,K4:K10,K31,FALSE) -> D | L36: =+HLOOKUP(L33,L4:L10,L31,FALSE) -> E | M36: =+HLOOKUP(M33,M4:M10,M31,FALSE) -> E | N36: =+HLOOKUP(N33,N4:N10,N31,FALSE) -> D-E
B37: CCIO | C37: =+C19 -> 0 | E37: D | F37: 10
B38: APV A | C38: 0 | E38: E | F38: 11 | H38: A | I38: 0.0449 | J38: =+K13 -> #N/A | K38: =+VLOOKUP(J38,$H$38:$I$44,2,FALSE) -> #N/A
B39: APV B | C39: 0 | E39: A-B | F39: 7 | H39: B | I39: 0.0402
B40: Depositos convenidos | C40: 0 | E40: D-E | F40: 10 | H40: C | I40: 0.0338
B41: Cuenta dos | C41: 0 | H41: D | I41: 0.0281
B42: Total flujos | C42: =SUM(C37:C41) -> 0 | H42: E | I42: 0.0217
H43: A-B | I43: 0.0449
H44: D-E | I44: 0.0217
...

Sheet Pension proyectada II
A1: Plazo | B1: Meses | C1: Saldo actual | D1: Mensual | E1: Rentabilidad | F1: Cotizacion Obligatoria | G1: APV | H1: Deposito convenido | I1: Total Aporte mensual | J1: Saldo al Final del Periodo | K1: Rentabilidad Mensual | L1: Rentabilidad del año | M1: Aportes del año | N1: variación del saldo
A2: 0 | B2: 0 | C2: =+Portada!DS19 -> 0 | D2: 0 | E2: 0 | F2: 0 | G2: 0 | H2: 0 | I2: 0 | J2: =+C2 -> 0 | K2: 0 | L2: 0 | M2: 0 | N2: 0
A3: 1 | B3: 12 | C3: =+Portada!$DS$19 -> 0 | D3: =(1+E3)^(1/12)-1 -> #N/A | E3: =+'Motor I'!$C$59 -> #N/A | F3: =+'Motor I'!$C$19*-1 -> 0 | G3: =+Portada!$EK$15*-1 -> -40000 | H3: =+Portada!$EK$17*-1 -> 0 | I3: =+F3+G3+H3 -> -40000 | J3: =FV(D3,B3,I3,-C3) -> #N/A | K3: =(C3*D3) -> #N/A | L3: =(K3*12) -> #N/A | M3: =(F3*12) -> 0 | N3: =(L3-M3) -> #N/A
A4: 2 | B4: 12 | C4: =+J3 -> #N/A | D4: =(1+E4)^(1/12)-1 -> #N/A | E4: =+'Motor I'!$C$59 -> #N/A | F4: =+'Motor I'!$C$19*-1 -> 0 | G4: =+Portada!$EK$15*-1 -> -40000 | H4: =+Portada!$EK$17*-1 -> 0 | I4: =+F4+G4+H4 -> -40000 | J4: =FV(D4,B4,I4,-C4) -> #N/A | K4: =(C4*D4) -> #N/A | L4: =(K4*12) -> #N/A | M4: =(F4*12) -> 0 | N4: =(L4-M4) -> #N/A
A5: 3 | B5: 12 | C5: =+J4 -> #N/A | D5: =(1+E5)^(1/12)-1 -> #N/A | E5: =+'Motor I'!$C$59 -> #N/A | F5: =+'Motor I'!$C$19*-1 -> 0 | G5: =+Portada!$EK$15*-1 -> -40000 | H5: =+Portada!$EK$17*-1 -> 0 | I5: =+F5+G5+H5 -> -40000 | J5: =FV(D5,B5,I5,-C5) -> #N/A | K5: =(C5*D5) -> #N/A | L5: =(K5*12) -> #N/A | M5: =(F5*12) -> 0 | N5: =(L5-M5) -> #N/A
A6: 4 | B6: 12 | C6: =+J5 -> #N/A | D6: =(1+E6)^(1/12)-1 -> #N/A | E6: =+'Motor I'!$C$59 -> #N/A | F6: =+'Motor I'!$C$19*-1 -> 0 | G6: =+Portada!$EK$15*-1 -> -40000 | H6: =+Portada!$EK$17*-1 -> 0 | I6: =+F6+G6+H6 -> -40000 | J6: =FV(D6,B6,I6,-C6) -> #N/A | K6: =(C6*D6) -> #N/A | L6: =(K6*12) -> #N/A | M6: =(F6*12) -> 0 | N6: =(L6-M6) -> #N/A
A7: 5 | B7: 12 | C7: =+J6 -> #N/A | D7: =(1+E7)^(1/12)-1 -> #N/A | E7: =+'Motor I'!$C$59 -> #N/A | F7: =+'Motor I'!$C$19*-1 -> 0 | G7: =+Portada!$EK$15*-1 -> -40000 | H7: =+Portada!$EK$17*-1 -> 0 | I7: =+F7+G7+H7 -> -40000 | J7: =FV(D7,B7,I7,-C7) -> #N/A | K7: =(C7*D7) -> #N/A | L7: =(K7*12) -> #N/A | M7: =(F7*12) -> 0 | N7: =(L7-M7) -> #N/A
A8: 6 | B8: 12 | C8: =+J7 -> #N/A | D8: =(1+E8)^(1/12)-1 -> #N/A | E8: =+'Motor I'!$C$59 -> #N/A | F8: =+'Motor I'!$C$19*-1 -> 0 | G8: =+Portada!$EK$15*-1 -> -40000 | H8: =+Portada!$EK$17*-1 -> 0 | I8: =+F8+G8+H8 -> -40000 | J8: =FV(D8,B8,I8,-C8) -> #N/A | K8: =(C8*D8) -> #N/A | L8: =(K8*12) -> #N/A | M8: =(F8*12) -> 0 | N8: =(L8-M8) -> #N/A
A9: 7 | B9: 12 | C9: =+J8 -> #N/A | D9: =(1+E9)^(1/12)-1 -> #N/A | E9: =+'Motor I'!$C$59 -> #N/A | F9: =+'Motor I'!$C$19*-1 -> 0 | G9: =+Portada!$EK$15*-1 -> -40000 | H9: =+Portada!$EK$17*-1 -> 0 | I9: =+F9+G9+H9 -> -40000 | J9: =FV(D9,B9,I9,-C9) -> #N/A | K9: =(C9*D9) -> #N/A | L9: =(K9*12) -> #N/A | M9: =(F9*12) -> 0 | N9: =(L9-M9) -> #N/A
A10: 8 | B10: 12 | C10: =+J9 -> #N/A | D10: =(1+E10)^(1/12)-1 -> #N/A | E10: =+'Motor I'!$C$59 -> #N/A | F10: =+'Motor I'!$C$19*-1 -> 0 | G10: =+Portada!$EK$15*-1 -> -40000 | H10: =+Portada!$EK$17*-1 -> 0 | I10: =+F10+G10+H10 -> -40000 | J10: =FV(D10,B10,I10,-C10) -> #N/A | K10: =(C10*D10) -> #N/A | L10: =(K10*12) -> #N/A | M10: =(F10*12) -> 0 | N10: =(L10-M10) -> #N/A
A11: 9 | B11: 12 | C11: =+J10 -> #N/A | D11: =(1+E11)^(1/12)-1 -> #N/A | E11: =+'Motor I'!$C$59 -> #N/A | F11: =+'Motor I'!$C$19*-1 -> 0 | G11: =+Portada!$EK$15*-1 -> -40000 | H11: =+Portada!$EK$17*-1 -> 0 | I11: =+F11+G11+H11 -> -40000 | J11: =FV(D11,B11,I11,-C11) -> #N/A | K11: =(C11*D11) -> #N/A | L11: =(K11*12) -> #N/A | M11: =(F11*12) -> 0 | N11: =(L11-M11) -> #N/A
A12: 10 | B12: 12 | C12: =+J11 -> #N/A | D12: =(1+E12)^(1/12)-1 -> #N/A | E12: =+'Motor I'!$C$59 -> #N/A | F12: =+'Motor I'!$C$19*-1 -> 0 | G12: =+Portada!$EK$15*-1 -> -40000 | H12: =+Portada!$EK$17*-1 -> 0 | I12: =+F12+G12+H12 -> -40000 | J12: =FV(D12,B12,I12,-C12) -> #N/A | K12: =(C12*D12) -> #N/A | L12: =(K12*12) -> #N/A | M12: =(F12*12) -> 0 | N12: =(L12-M12) -> #N/A
A13: 11 | B13: 12 | C13: =+J12 -> #N/A | D13: =(1+E13)^(1/12)-1 -> #N/A | E13: =+'Motor I'!$C$59 -> #N/A | F13: =+'Motor I'!$C$19*-1 -> 0 | G13: =+Portada!$EK$15*-1 -> -40000 | H13: =+Portada!$EK$17*-1 -> 0 | I13: =+F13+G13+H13 -> -40000 | J13: =FV(D13,B13,I13,-C13) -> #N/A | K13: =(C13*D13) -> #N/A | L13: =(K13*12) -> #N/A | M13: =(F13*12) -> 0 | N13: =(L13-M13) -> #N/A
A14: 12 | B14: 12 | C14: =+J13 -> #N/A | D14: =(1+E14)^(1/12)-1 -> #N/A | E14: =+'Motor I'!$C$59 -> #N/A | F14: =+'Motor I'!$C$19*-1 -> 0 | G14: =+Portada!$EK$15*-1 -> -40000 | H14: =+Portada!$EK$17*-1 -> 0 | I14: =+F14+G14+H14 -> -40000 | J14: =FV(D14,B14,I14,-C14) -> #N/A | K14: =(C14*D14) -> #N/A | L14: =(K14*12) -> #N/A | M14: =(F14*12) -> 0 | N14: =(L14-M14) -> #N/A
A15: 13 | B15: 12 | C15: =+J14 -> #N/A | D15: =(1+E15)^(1/12)-1 -> #N/A | E15: =+'Motor I'!$C$59 -> #N/A | F15: =+'Motor I'!$C$19*-1 -> 0 | G15: =+Portada!$EK$15*-1 -> -40000 | H15: =+Portada!$EK$17*-1 -> 0 | I15: =+F15+G15+H15 -> -40000 | J15: =FV(D15,B15,I15,-C15) -> #N/A | K15: =(C15*D15) -> #N/A | L15: =(K15*12) -> #N/A | M15: =(F15*12) -> 0 | N15: =(L15-M15) -> #N/A
... A42: 40 | B42: 12 | C42: =+J41 -> #N/A | D42: =(1+E42)^(1/12)-1 -> #N/A | E42: =+'Motor I'!$C$59 -> #N/A | F42: =+'Motor I'!$C$19*-1 -> 0 | G42: =+Portada!$EK$15*-1 -> -40000 | H42: =+Portada!$EK$17*-1 -> 0 | I42: =+F42+G42+H42 -> -40000 | J42: =FV(D42,B42,I42,-C42) -> #N/A | K42: =(C42*D42) -> #N/A | L42: =(K42*12) -> #N/A | M42: =(F42*12) -> 0 | N42: =(L42-M42) -> #N/A

Sheet Motor III
B8: Género | C8: =+Portada!AX18 -> Mujer
B9: Edad actual | C9: =+Portada!BO18 -> 0
B10: Edad de pensión | C10: =+Portada!BO22 -> 0
B11: Años que faltan | C11: =+C10-C9 -> 0
B12: Monto de pensión objetivo | C12: =+Portada!BO24 -> 0
B13: CNU | C13: =+'Motor I'!C13 -> #N/A
B14: Saldo de pensión necesario | C14: =+C12*C13 -> #N/A
B15: Promedio de cotizaciones | C15: =+Portada!BO20 -> 0
B16: Tope | C16: 87.8
B17: UF | C17: 37754.47
B18: Cotización Maxima | C18: =+C16*C17 -> 3314842.5
B19: Cotización mensual | C19: =+MIN((C18*10%),(C15*10%)) -> 0
B22: Saldo total proyectado | C22: =+VLOOKUP(C11,'Pension proyectada III'!$A$2:$AM$42,39,FALSE) -> 0
B23: CNU | C23: =+C13 -> #N/A
B25: Pensión | C25: =+C22/C23 -> #N/A
B26: Tasa reemplazo | C26: =+C25/C15 -> #N/A
B28: Diferencia | C28: =+C22-C14 -> #N/A
C32: OBLIGATORIA | L32: Mujer | M32: 1
C33: Mujer | L33: Hombre | M33: 2
C34: Desde | D34: Hasta | E34: ACTIVO | G34: MODERADO | I34: CONSERVADOR | L34: Mujer | M34: Hombre | N34: =+Portada!AX18 -> Mujer | O34: =+VLOOKUP(N34,L32:M33,2,FALSE) -> 1
C35: 0 | D35: 50 | E35: A | F35: B | G35: C | H35: D | I35: E | L35: =+VLOOKUP(Portada!$BO$18,'Motor III'!$C$35:$I$36,3,TRUE) -> A | M35: =+VLOOKUP(Portada!$BO$18,'Motor III'!$C$38:$I$39,3,TRUE) -> A | N35: =+HLOOKUP($N$34,$L$34:$M$39,O35,FALSE) -> A | O35: 2
C36: 51 | D36: 100 | E36: NO | F36: B | G36: C | H36: D | I36: E | L36: =+VLOOKUP(Portada!$BO$18,'Motor III'!$C$35:$I$36,4,TRUE) -> B | M36: =+VLOOKUP(Portada!$BO$18,'Motor III'!$C$38:$I$39,4,TRUE) -> B | N36: =+HLOOKUP($N$34,$L$34:$M$39,O36,FALSE) -> B | O36: 3
C37: Hombre | L37: =+VLOOKUP(Portada!$BO$18,'Motor III'!$C$35:$I$36,5,TRUE) -> C | M37: =+VLOOKUP(Portada!$BO$18,'Motor III'!$C$38:$I$39,5,TRUE) -> C | N37: =+HLOOKUP($N$34,$L$34:$M$39,O37,FALSE) -> C | O37: 4
C38: 0 | D38: 55 | E38: A | F38: B | G38: C | H38: D | I38: E | L38: =+VLOOKUP(Portada!$BO$18,'Motor III'!$C$35:$I$36,6,TRUE) -> D | M38: =+VLOOKUP(Portada!$BO$18,'Motor III'!$C$38:$I$39,6,TRUE) -> D | N38: =+HLOOKUP($N$34,$L$34:$M$39,O38,FALSE) -> D | O38: 5
C39: 56 | D39: 100 | E39: NO | F39: B | G39: C | H39: D | I39: E | L39: =+VLOOKUP(Portada!$BO$18,'Motor III'!$C$35:$I$36,7,TRUE) -> E | M39: =+VLOOKUP(Portada!$BO$18,'Motor III'!$C$38:$I$39,7,TRUE) -> E | N39: =+HLOOKUP($N$34,$L$34:$M$39,O39,FALSE) -> E | O39: 6
C40: APV
C41: Mujer | E41: ACTIVO | G41: MODERADO | I41: CONSERVADOR | L41: A | M41: 0.0449 | N41: =+L41 -> A
C42: 0 | D42: 50 | E42: A | F42: B | G42: C | H42: D | I42: E | L42: B | M42: 0.0402 | N42: =+L42 -> B
C43: 51 | D43: 100 | E43: A | F43: B | G43: C | H43: D | I43: E | L43: C | M43: 0.0338 | N43: =+L43 -> C
C44: Hombre | L44: D | M44: 0.0281 | N44: =+L44 -> D
C45: 0 | E45: A | F45: B | G45: C | H45: D | I45: E | L45: E | M45: 0.0217 | N45: =+L45 -> E
C46: 56 | D46: 100 | E46: A | F46: B | G46: C | H46: D | I46: E
C47: DC
C48: Mujer | E48: ACTIVO | G48: MODERADO | I48: CONSERVADOR
C49: 0 | D49: 50 | E49: A | F49: B | G49: C | H49: D | I49: E
C50: 51 | D50: 100 | E50: A | F50: B | G50: C | H50: D | I50: E
C51: Hombre
C52: 0 | E52: A | F52: B | G52: C | H52: D | I52: E
C53: 56 | D53: 100 | E53: A | F53: B | G53: C | H53: D | I53: E

Sheet Pension proyectada III
A1: Plazo | B1: Meses | C1: Saldo actual | D1: Mensual | E1: Rentabilidad | F1: Cotizacion Obligatoria | G1: APV | H1: Deposito convenido | I1: Total Aporte mensual | J1: Saldo al Final del Periodo | K1: Rentabilidad Mensual | L1: Rentabilidad del año | M1: Aportes del año | N1: variación del saldo | O1: Saldo actual | P1: Mensual | Q1: Rentabilidad | R1: Cotizacion Obligatoria | S1: APV | T1: Deposito convenido | U1: Total Aporte mensual | V1: Saldo al Final del Periodo | W1: Rentabilidad Mensual | X1: Rentabilidad del año | Y1: Aportes del año | Z1: variación del saldo | AA1: Saldo actual | AB1: Mensual | AC1: Rentabilidad | AD1: Cotizacion Obligatoria | AE1: APV | AF1: Deposito convenido | AG1: Total Aporte mensual | AH1: Saldo al Final del Periodo | AI1: Rentabilidad Mensual | AJ1: Rentabilidad del año | AK1: Aportes del año | AL1: variación del saldo | AM1: TOTAL
A2: 0 | B2: 0 | C2: =+Portada!DS13 -> 0 | D2: 0 | E2: 0 | F2: 0 | G2: 0 | H2: 0 | I2: 0 | J2: =+C2 -> 0 | K2: 0 | L2: 0 | M2: 0 | N2: 0 | O2: =+Portada!DS15 -> 0 | P2: 0 | Q2: 0 | R2: 0 | S2: 0 | T2: 0 | U2: 0 | V2: =+O2 -> 0 | W2: 0 | X2: 0 | Y2: 0 | Z2: 0 | AA2: =+Portada!DS17 -> 0 | AB2: 0 | AC2: 0 | AD2: 0 | AE2: 0 | AF2: 0 | AG2: 0 | AH2: =+AA2 -> 0 | AI2: 0 | AJ2: 0 | AK2: 0 | AL2: 0 | AM2: =+AA2+O2+C2 -> 0
A3: 1 | B3: 12 | C3: =+Portada!DS13 -> 0 | D3: =(1+E3)^(1/12)-1 -> 0.0027739515 | E3: =+'Paso 2B solicitado por cliente'!$S$15 -> 0.0338 | F3: =+'Motor I'!$C$19*-1 -> 0 | G3: 0 | H3: 0 | I3: =+F3+G3+H3 -> 0 | J3: =FV(D3,B3,I3,-C3) -> 0 | K3: =(C3*D3) -> 0 | L3: =(K3*12) -> 0 | M3: =(F3*12) -> 0 | N3: =(L3-M3) -> 0 | O3: =+Portada!DS15 -> 0 | P3: =(1+Q3)^(1/12)-1 -> 0.0027739515 | Q3: =+'Paso 2B solicitado por cliente'!$S$16 -> 0.0338 | R3: 0 | S3: =+Portada!$EK$15*-1 -> -40000 | T3: 0 | U3: =+R3+S3+T3 -> -40000 | V3: =FV(P3,B3,S3,-O3) -> 487391.37 | W3: =(O3*P3) -> 0 | X3: =(W3*12) -> 0 | Y3: =(R3*12) -> 0 | Z3: =(X3-Y3) -> 0 | AA3: =+Portada!DS17 -> 0 | AB3: =(1+AC3)^(1/12)-1 -> 0.0027739515 | AC3: =+'Paso 2B solicitado por cliente'!$S$17 -> 0.0338 | AD3: 0 | AE3: 0 | AF3: =+Portada!$EK$17*-1 -> 0 | AG3: =+AD3+AE3+AF3 -> 0 | AH3: =FV(AB3,B3,AF3,-AA3) -> 0 | AI3: =(AA3*AB3) -> 0 | AJ3: =(AI3*12) -> 0 | AK3: =(AD3*12) -> 0 | AL3: =(AJ3-AK3) -> 0 | AM3: =+AH3+V3+J3 -> 487391.37
A4: 2 | B4: 12 | C4: =+J3 -> 0 | D4: =(1+E4)^(1/12)-1 -> 0.0027739515 | E4: =+'Paso 2B solicitado por cliente'!$S$15 -> 0.0338 | F4: =+'Motor I'!$C$19*-1 -> 0 | G4: 0 | H4: 0 | I4: =+F4+G4+H4 -> 0 | J4: =FV(D4,B4,I4,-C4) -> 0 | K4: =(C4*D4) -> 0 | L4: =(K4*12) -> 0 | M4: =(F4*12) -> 0 | N4: =(L4-M4) -> 0 | O4: =+V3 -> 487391.37 | P4: =(1+Q4)^(1/12)-1 -> 0.0027739515 | Q4: =+'Paso 2B solicitado por cliente'!$S$16 -> 0.0338 | R4: 0 | S4: =+Portada!$EK$15*-1 -> -40000 | T4: 0 | U4: =+R4+S4+T4 -> -40000 | V4: =FV(P4,B4,S4,-O4) -> 991256.57 | W4: =(O4*P4) -> 1352 | X4: =(W4*12) -> 16224 | Y4: =(R4*12) -> 0 | Z4: =(X4-Y4) -> 16224 | AA4: =+AH3 -> 0 | AB4: =(1+AC4)^(1/12)-1 -> 0.0027739515 | AC4: =+'Paso 2B solicitado por cliente'!$S$17 -> 0.0338 | AD4: 0 | AE4: 0 | AF4: =+Portada!$EK$17*-1 -> 0 | AG4: =+AD4+AE4+AF4 -> 0 | AH4: =FV(AB4,B4,AF4,-AA4) -> 0 | AI4: =(AA4*AB4) -> 0 | AJ4: =(AI4*12) -> 0 | AK4: =(AD4*12) -> 0 | AL4: =(AJ4-AK4) -> 0 | AM4: =+AH4+V4+J4 -> 991256.57
