Workbook

Sheet Hoja14
M2: AFP ahorro Obligatorio (APO) | P2: Capital | AA2: =+Y17-AB17-AC17-AD17-AE17 -> 3190663.5 | AD2: =+AD3-AD17 -> -57149.47
M3: Tipo de afiliado | P3: Pensionado no cotizante | AA3: =+AA2*Z17-AA17 -> -27076.229 | AD3: 183008
M4: Retiro APV B (2025) | P4: 10000000 | R4: Impuesto Único | T4: =Hoja9!I21 -> 0.34936739 | W4: YN | Y4: =IF(P3=Z34,1,0) -> 0 | AC4: =VLOOKUP(P2,$CF$14:$CG$19,2) -> 0.0144
F5: AFP cotiza ahorro APO | M5: Intereses crédito hipotecario (2025) | P5: 0 | R5: =Hoja9!Q15 -> 0 | T5: =Hoja9!R14 -> 0.50234715 | W5: =IF(R5=6164736,"(Tope UTA 8)"," ") | AF5: Si | AG5: No | AH5: =IF(Q270="Si",1,0) -> 1 | AX5: =IF(P3="No pensionado",0,IF(P3="Pensionado cotizante",3,2)) -> 2 | HM5: =MIN(P5,Hoja15!J19) -> 0
M6: Inversión 57 bis | N6: Saldo Ahorro Neto | R6: 0 | X6: , | AC6: 1510523 | AD6: =AC6/67.4 -> 22411.32 | HP6: Seguro cesantía | HS6: Si
N7: Años SAN positivo | P7: 0 | Q7: =IF(R6=0," ",IF(T45=1,"Credito","Débito")) | R7: =IF(R6=" "," ",IF(R6=0,0,IF(Q7="Débito",Q48,Q48*-1))) -> 0 | AA7: =IF(P3="No pensionado",0,1) -> 1 | BF7: =IF(P3="Pensionado no cotizante",0,1) -> 0
K11: APV opción A | AE11: APV B | AG11: APV A
E12: Mes | F12: UF | G12: Total renta afecta ($) | H12: Pensión Bruta ($) | I12: APV máximo vía empleador ($) | J12: Vía Empleador | K12: Directo | L12: Vía Empleador | M12: Directo | N12: Renta Tributable ($) | P12: Impuesto mensual ($) | R12: Pensión Tributable ($) | T12: Impuesto Pensión ($) | V12: Honorarios ($) | X12: Retención 14,5% ($) | Z12: Tramo impuesto | AA12: Rebaja | AB12: Obligatorio | AC12: Comisión AFP | AD12: Salud | AE12: Seguro Cesantía | AF12: Vía Empleador | AG12: Directo | AH12: Vía Empleador | AI12: Directo | AX12: Tramo impuesto | AY12: Rebaja | AZ12: Obligatorio | BA12: Comisión Pensión | BB12: Salud pensión | BC12: Seguro Cesantía | BD12: Comisión AFP | BJ12: Tramo impuesto | BK12: Rebaja
AJ13: =SUM(AJ14:AJ25) -> 0 | CK13: Factor actualización | CM13: Renta tributable | CN13: Pensión Tributable | CO13: Impuetso sueldo | CP13: Impuesto Pensión | CQ13: Honorarios | CR13: Retenciones | CS13: APV empleador | CT13: APV directo
A14: =P14/Hoja15!C6 -> 8.0044058 | B14: =J14/F14 -> 0.00078156731 | E14: Enero | F14: =H229 -> 38384.41 | G14: 7000000 | I14: =IF($Y$4=1,Y14*0.1,IF(G14-AB14-AC14-AD14-AE14<(50*F14),G14-AB14-AC14-AD14-AE14,50*F14)) -> 1919220.5 | J14: 30 | K14: 0 | L14: 0 | N14: =G14-AB14-AC14-AD14-AE14-AF14 -> 5612557.1 | P14: =N14*Z14-AA14 -> 539729.08 | R14: =AW14 -> 0 | T14: =AW14*AX14-AY14 -> 0 | X14: =+V14*0.145 -> 0 | Y14: =IF(G14>87.8*F14,87.8*F14,G14) -> 3370151.2 | Z14: =VLOOKUP(N14,Hoja15!$E$6:$H$13,3) -> 0.23 | AA14: =VLOOKUP(N14,Hoja15!$E$6:$H$14,4) -> 751159.06 | AB14: =IF($AX$5=2,0,Y14*0.1) -> 0 | AC14: =IF($BF$7=0,0,(IF(G14>87.8*F14,87.8*F14*$AC$4,$AC$4*G14))) -> 0 | AD14: =IF(G14>87.8*F14,87.8*7%*F14,7%*G14) -> 235910.58 | AE14: =(IF($BF$7=0,0,IF($HS$6="No",0,IF(G14>131.8*F14,0.6%*131.8*F14,0.6%*G14))))*AH5 -> 0 | AF14: =IF($AJ$42=2,J14*F14,J14) -> 1151532.3 | AG14: =IF($AK$42=2,M14*F14,M14) -> 0 | AH14: =IF($AL$42=2,L14*F14,L14) -> 0 | AI14: =IF($AM$42=2,M14*F14,M14) -> 0 | AJ14: =IF(AF14>I14,1,0) -> 0 | AK14: =I14/F14 -> 50 | AL14: =AF14/F14 -> 30 | AM14: =AG14/F14 -> 0 | AN14: =AH14/F14 -> 0 | AO14: =AI14/F14 -> 0 | AR14: =P14/F14 -> 14.061153 | AW14: =BF14-BB14-AZ14 -> 0 | AX14: =VLOOKUP(AW14,Hoja15!$E$6:$H$13,3) -> 0 | AY14: =VLOOKUP(AW14,Hoja15!$E$6:$H$13,4) -> 0 | AZ14: 0 | BA14: =1.25%*BF14 -> 0 | BB14: =IF(BF14>60*F14,60*7%*F14,7%*BF14) -> 0 | BC14: 0 | BD14: 0 | BF14: =IF($P$3="No pensionado",0,H14) -> 0 | BI14: =N14+R14 -> 5612557.1 | BJ14: =VLOOKUP(BI14,Hoja15!$E$6:$H$13,3) -> 0.23 | BK14: =VLOOKUP(BI14,Hoja15!$E$6:$H$13,4) -> 751159.06 | BL14: =BI14*BJ14-BK14 -> 539729.08 | BM14: =BL14/Hoja15!C6 -> 8.0044058 | BP14: =P14/Hoja15!C6 -> 8.0044058 | BQ14: =T14/Hoja15!C6 -> 0 | BT14: =I14/F14 -> 50 | BU14: =M14 -> 0 | BX14: =IF($AJ$42=1,M14/F14,J14) -> 30 | BY14: =IF($AJ$42=1,J14/F14,J14) -> 30 | BZ14: =I14/F14 -> 50 | CF14: Capital | CG14: 0.0144 | CJ14: enero | CK14: =J229 -> 0 | CM14: =N14*(1+CK14) -> 5612557.1 | CN14: =R14*(1+CK14) -> 0 | CO14: =P14*(1+CK14) -> 539729.08 | CP14: =T14*(1+CK14) -> 0 | CQ14: =V14*(1+CK14) -> 0 | CR14: =X14*(1+CK14) -> 0 | CS14: =IF($AJ$42=2,J14*H229,J14)*(1+CK14) -> 1151532.3 | CT14: =IF($AK$42=2,M14*H229,M14)*(1+CK14) -> 0 | DO14: =H14-10*H229 -> -383844.1
A15: =P15/Hoja15!C7 -> 8.010255 | B15: =J15/F15 -> 0.00077623801 | E15: Febrero | F15: =H230 -> 38647.94 | G15: 7000000 | I15: =IF($Y$4=1,Y15*0.1,IF(G15-AB15-AC15-AD15-AE15<(50*F15),G15-AB15-AC15-AD15-AE15,50*F15)) -> 1932397 | J15: 30 | K15: 0 | L15: 0 | N15: =G15-AB15-AC15-AD15-AE15-AF15 -> 5603031.6 | P15: =N15*Z15-AA15 -> 539042.1 | R15: =AW15 -> 0 | T15: =AW15*AX15-AY15 -> 0 | X15: =+V15*0.145 -> 0 | Y15: =IF(G15>87.8*F15,87.8*F15,G15) -> 3393289.1 | Z15: =VLOOKUP(N15,Hoja15!$E$15:$H$22,3) -> 0.23 | AA15: =VLOOKUP(N15,Hoja15!$E$15:$H$22,4) -> 749655.16 | AB15: =IF($AX$5=2,0,Y15*0.1) -> 0 | AC15: =IF($BF$7=0,0,(IF(G15>87.8*F15,87.8*F15*$AC$4,$AC$4*G15))) -> 0 | AD15: =IF(G15>87.8*F15,87.8*7%*F15,7%*G15) -> 237530.24 | AE15: =(IF($BF$7=0,0,IF($HS$6="No",0,IF(G15>131.8*F15,0.6%*131.8*F15,0.6%*G15))))*$AH$5 -> 0 | AF15: =IF($AJ$42=2,J15*F15,J15) -> 1159438.2 | AG15: =IF($AK$42=2,M15*F15,M15) -> 0 | AH15: =IF($AL$42=2,L15*F15,L15) -> 0 | AI15: =IF($AM$42=2,M15*F15,M15) -> 0 | AJ15: =IF(AF15>I15,1,0) -> 0 | AK15: =I15/F15 -> 50 | AL15: =AF15/F15 -> 30 | AM15: =AG15/F15 -> 0 | AN15: =AH15/F15 -> 0 | AO15: =AI15/F15 -> 0 | AR15: =P15/F15 -> 13.947499 | AW15: =BF15-BB15-AZ15 -> 0 | AX15: =VLOOKUP(AW15,Hoja15!$E$15:$H$22,3) -> 0 | AY15: =VLOOKUP(AW15,Hoja15!$E$15:$H$22,4) -> 0 | AZ15: 0 | BA15: =1.25%*BF15 -> 0 | BB15: =IF(BF15>60*F15,60*7%*F15,7%*BF15) -> 0 | BC15: 0 | BD15: 0 | BF15: =IF($P$3="No pensionado",0,H15) -> 0 | BI15: =N15+R15 -> 5603031.6 | BJ15: =VLOOKUP(BI15,Hoja15!$E$15:$H$22,3) -> 0.23 | BK15: =VLOOKUP(BI15,Hoja15!$E$15:$H$22,4) -> 749655.16 | BL15: =BI15*BJ15-BK15 -> 539042.1 | BM15: =BL15/Hoja15!C7 -> 8.010255 | BP15: =P15/Hoja15!C7 -> 8.010255 | BQ15: =T15/Hoja15!C7 -> 0 | BT15: =I15/F15 -> 50 | BX15: =IF($AJ$42=1,M15/F15,J15) -> 30 | BY15: =IF($AJ$42=1,J15/F15,J15) -> 30 | BZ15: =I15/F15 -> 50 | CF15: Cuprum | CG15: 0.0144 | CJ15: febrero | CK15: =J230 -> 0 | CM15: =N15*(1+CK15) -> 5603031.6 | CN15: =R15*(1+CK15) -> 0 | CO15: =P15*(1+CK15) -> 539042.1 | CP15: =T15*(1+CK15) -> 0 | CQ15: =V15*(1+CK15) -> 0 | CR15: =X15*(1+CK15) -> 0 | CS15: =IF($AJ$42=2,J15*H230,J15)*(1+CK15) -> 1159438.2 | CT15: =IF($AK$42=2,M15*H230,M15)*(1+CK15) -> 0 | DO15: =H15-10*H230 -> -386479.4
A16: =P16/Hoja15!C8 -> 117.5379 | B16: =J16/F16 -> 0.00077132502 | E16: Marzo | F16: =H231 -> 38894.11 | G16: 28000000 | I16: =IF($Y$4=1,Y16*0.1,IF(G16-AB16-AC16-AD16-AE16<(50*F16),G16-AB16-AC16-AD16-AE16,50*F16)) -> 1944705.5 | J16: 30 | K16: 0 | L16: 0 | N16: =G16-AB16-AC16-AD16-AE16-AF16 -> 26594133 | P16: =N16*Z16-AA16 -> 7996573.5 | R16: =AW16 -> 0 | T16: =AW16*AX16-AY16 -> 0 | X16: =+V16*0.145 -> 0 | Y16: =IF(G16>87.8*F16,87.8*F16,G16) -> 3414902.9 | Z16: =VLOOKUP(N16,Hoja15!$E$24:$H$31,3) -> 0.4 | AA16: =VLOOKUP(N16,Hoja15!$E$24:$H$31,4) -> 2641079.9 | AB16: =IF($AX$5=2,0,Y16*0.1) -> 0 | AC16: =IF($BF$7=0,0,(IF(G16>87.8*F16,87.8*F16*$AC$4,$AC$4*G16))) -> 0 | AD16: =IF(G16>87.8*F16,87.8*7%*F16,7%*G16) -> 239043.2 | AE16: =(IF($BF$7=0,0,IF($HS$6="No",0,IF(G16>131.8*F16,0.6%*131.8*F16,0.6%*G16))))*$AH$5 -> 0 | AF16: =IF($AJ$42=2,J16*F16,J16) -> 1166823.3 | AG16: =IF($AK$42=2,M16*F16,M16) -> 0 | AH16: =IF($AL$42=2,L16*F16,L16) -> 0 | AI16: =IF($AM$42=2,M16*F16,M16) -> 0 | AJ16: =IF(AF16>I16,1,0) -> 0 | AK16: =I16/F16 -> 50 | AL16: =AF16/F16 -> 30 | AM16: =AG16/F16 -> 0 | AN16: =AH16/F16 -> 0 | AO16: =AI16/F16 -> 0 | AR16: =P16/F16 -> 205.59857 | AW16: =BF16-BB16-AZ16 -> 0 | AX16: =VLOOKUP(AW16,Hoja15!$E$24:$H$31,3) -> 0 | AY16: =VLOOKUP(AW16,Hoja15!$E$24:$H$31,4) -> 0 | AZ16: 0 | BA16: =1.25%*BF16 -> 0 | BB16: =IF(BF16>60*F16,60*7%*F16,7%*BF16) -> 0 | BC16: 0 | BD16: 0 | BF16: =IF($P$3="No pensionado",0,H16) -> 0 | BI16: =N16+R16 -> 26594133 | BJ16: =VLOOKUP(BI16,Hoja15!$E$24:$H$31,3) -> 0.4 | BK16: =VLOOKUP(BI16,Hoja15!$E$24:$H$31,4) -> 2641079.9 | BL16: =BI16*BJ16-BK16 -> 7996573.5 | BM16: =BL16/Hoja15!C8 -> 117.5379 | BP16: =P16/Hoja15!C8 -> 117.5379 | BQ16: =T16/Hoja15!C8 -> 0 | BT16: =I16/F16 -> 50 | BX16: =IF($AJ$42=1,M16/F16,J16) -> 30 | BY16: =IF($AJ$42=1,J16/F16,J16) -> 30 | BZ16: =I16/F16 -> 50 | CF16: Habitat | CG16: 0.0127 | CJ16: marzo | CK16: =J231 -> 0 | CM16: =N16*(1+CK16) -> 26594133 | CN16: =R16*(1+CK16) -> 0 | CO16: =P16*(1+CK16) -> 7996573.5 | CP16: =T16*(1+CK16) -> 0 | CQ16: =V16*(1+CK16) -> 0 | CR16: =X16*(1+CK16) -> 0 | CS16: =IF($AJ$42=2,J16*H231,J16)*(1+CK16) -> 1166823.3 | CT16: =IF($AK$42=2,M16*H231,M16)*(1+CK16) -> 0 | DK16: APV independiente | DO16: =H16-10*H231 -> -388941.1 | EM16: =IF(AVERAGE(G14:G25)=G26/12,1,0) -> 1
A17: =P17/Hoja15!C9 -> 7.6745032 | B17: =J17/F17 -> 0.00076774626 | E17: Abril | F17: =H232 -> 39075.41 | G17: 7000000 | I17: =IF($Y$4=1,Y17*0.1,IF(G17-AB17-AC17-AD17-AE17<(50*F17),G17-AB17-AC17-AD17-AE17,50*F17)) -> 1953770.5 | J17: 30 | K17: 0 | L17: 0 | N17: =G17-AB17-AC17-AD17-AE17-AF17 -> 5587580.2 | P17: =N17*Z17-AA17 -> 524214.61 | R17: =AW17 -> 0 | T17: =AW17*AX17-AY17 -> 0 | X17: =+V17*0.145 -> 0 | Y17: =IF(G17>87.8*F17,87.8*F17,G17) -> 3430821 | Z17: =VLOOKUP(N17,Hoja15!$E$33:$H$40,3) -> 0.23 | AA17: =VLOOKUP(N17,Hoja15!$E$33:$H$40,4) -> 760928.84 | AB17: =IF($AX$5=2,0,Y17*0.1) -> 0 | AC17: =IF($BF$7=0,0,(IF(G17>87.8*F17,87.8*F17*$AC$4,$AC$4*G17))) -> 0 | AD17: =IF(G17>87.8*F17,87.8*7%*F17,7%*G17) -> 240157.47 | AE17: =(IF($BF$7=0,0,IF($HS$6="No",0,IF(G17>131.8*F17,0.6%*131.8*F17,0.6%*G17))))*$AH$5 -> 0 | AF17: =IF($AJ$42=2,J17*F17,J17) -> 1172262.3 | AG17: =IF($AK$42=2,M17*F17,M17) -> 0 | AH17: =IF($AL$42=2,L17*F17,L17) -> 0 | AI17: =IF($AM$42=2,M17*F17,M17) -> 0 | AJ17: =IF(AF17>I17,1,0) -> 0 | AK17: =I17/F17 -> 50 | AL17: =AF17/F17 -> 30 | AM17: =AG17/F17 -> 0 | AN17: =AH17/F17 -> 0 | AO17: =AI17/F17 -> 0 | AR17: =P17/F17 -> 13.41546 | AW17: =BF17-BB17-AZ17 -> 0 | AX17: =VLOOKUP(AW17,Hoja15!$E$33:$H$40,3) -> 0 | AY17: =VLOOKUP(AW17,Hoja15!$E$33:$H$40,4) -> 0 | AZ17: 0 | BA17: =1.25%*BF17 -> 0 | BB17: =IF(BF17>60*F17,60*7%*F17,7%*BF17) -> 0 | BC17: 0 | BD17: 0 | BF17: =IF($P$3="No pensionado",0,H17) -> 0 | BI17: =N17+R17 -> 5587580.2 | BJ17: =VLOOKUP(BI17,Hoja15!$E$33:$H$40,3) -> 0.23 | BK17: =VLOOKUP(BI17,Hoja15!$E$33:$H$40,4) -> 760928.84 | BL17: =BI17*BJ17-BK17 -> 524214.61 | BM17: =BL17/Hoja15!C9 -> 7.6745032 | BP17: =P17/Hoja15!C9 -> 7.6745032 | BQ17: =T17/Hoja15!C9 -> 0 | BT17: =I17/F17 -> 50 | BX17: =IF($AJ$42=1,M17/F17,J17) -> 30 | BY17: =IF($AJ$42=1,J17/F17,J17) -> 30 | BZ17: =I17/F17 -> 50 | CF17: Modelo | CG17: 0.0058 | CJ17: abril | CK17: =J232 -> 0 | CM17: =N17*(1+CK17) -> 5587580.2 | CN17: =R17*(1+CK17) -> 0 | CO17: =P17*(1+CK17) -> 524214.61 | CP17: =T17*(1+CK17) -> 0 | CQ17: =V17*(1+CK17) -> 0 | CR17: =X17*(1+CK17) -> 0 | CS17: =IF($AJ$42=2,J17*H232,J17)*(1+CK17) -> 1172262.3 | CT17: =IF($AK$42=2,M17*H232,M17)*(1+CK17) -> 0 | DK17: =15*I240*12 -> 12517560 | DO17: =H17-10*H232 -> -390754.1 | EM17: =IF(H26+J26+M26+V26+P4+P5+R6+J34=0,1,0) -> 0
A18: =P18/Hoja15!C10 -> 7.5669597 | B18: =J18/F18 -> 0.00076551215 | E18: Mayo | F18: =H233 -> 39189.45 | G18: 7000000 | I18: =IF($Y$4=1,Y18*0.1,IF(G18-AB18-AC18-AD18-AE18<(50*F18),G18-AB18-AC18-AD18-AE18,50*F18)) -> 1959472.5 | J18: 30 | K18: 0 | L18: 0 | N18: =G18-AB18-AC18-AD18-AE18-AF18 -> 5583458.1 | P18: =N18*Z18-AA18 -> 519456.65 | R18: =AW18 -> 0 | T18: =AW18*AX18-AY18 -> 0 | X18: =+V18*0.145 -> 0 | Y18: =IF(G18>87.8*F18,87.8*F18,G18) -> 3440833.7 | Z18: =VLOOKUP(N18,Hoja15!$E$42:$H$49,3) -> 0.23 | AA18: =VLOOKUP(N18,Hoja15!$E$42:$H$49,4) -> 764738.72 | AB18: =IF($AX$5=2,0,Y18*0.1) -> 0 | AC18: =IF($BF$7=0,0,(IF(G18>87.8*F18,87.8*F18*$AC$4,$AC$4*G18))) -> 0 | AD18: =IF(G18>87.8*F18,87.8*7%*F18,7%*G18) -> 240858.36 | AE18: =(IF($BF$7=0,0,IF($HS$6="No",0,IF(G18>131.8*F18,0.6%*131.8*F18,0.6%*G18))))*$AH$5 -> 0 | AF18: =IF($AJ$42=2,J18*F18,J18) -> 1175683.5 | AG18: =IF($AK$42=2,M18*F18,M18) -> 0 | AH18: =IF($AL$42=2,L18*F18,L18) -> 0 | AI18: =IF($AM$42=2,M18*F18,M18) -> 0 | AJ18: =IF(AF18>I18,1,0) -> 0 | AK18: =I18/F18 -> 50 | AL18: =AF18/F18 -> 30 | AM18: =AG18/F18 -> 0 | AN18: =AH18/F18 -> 0 | AO18: =AI18/F18 -> 0 | AR18: =P18/F18 -> 13.255013 | AW18: =BF18-BB18-AZ18 -> 0 | AX18: =VLOOKUP(AW18,Hoja15!$E$42:$H$49,3) -> 0 | AY18: =VLOOKUP(AW18,Hoja15!$E$42:$H$49,4) -> 0 | AZ18: 0 | BA18: =1.25%*BF18 -> 0 | BB18: =IF(BF18>60*F18,60*7%*F18,7%*BF18) -> 0 | BC18: 0 | BD18: 0 | BF18: =IF($P$3="No pensionado",0,H18) -> 0 | BI18: =N18+R18 -> 5583458.1 | BJ18: =VLOOKUP(BI18,Hoja15!$E$42:$H$49,3) -> 0.23 | BK18: =VLOOKUP(BI18,Hoja15!$E$42:$H$49,4) -> 764738.72 | BL18: =BI18*BJ18-BK18 -> 519456.65 | BM18: =BL18/Hoja15!C10 -> 7.5669597 | BP18: =P18/Hoja15!C10 -> 7.5669597 | BQ18: =T18/Hoja15!C10 -> 0 | BT18: =I18/F18 -> 50 | BX18: =IF($AJ$42=1,M18/F18,J18) -> 30 | BY18: =IF($AJ$42=1,J18/F18,J18) -> 30 | BZ18: =I18/F18 -> 50 | CF18: Planvital | CG18: 0.0116 | CJ18: mayo | CK18: =J233 -> 0 | CM18: =N18*(1+CK18) -> 5583458.1 | CN18: =R18*(1+CK18) -> 0 | CO18: =P18*(1+CK18) -> 519456.65 | CP18: =T18*(1+CK18) -> 0 | CQ18: =V18*(1+CK18) -> 0 | CR18: =X18*(1+CK18) -> 0 | CS18: =IF($AJ$42=2,J18*H233,J18)*(1+CK18) -> 1175683.5 | CT18: =IF($AK$42=2,M18*H233,M18)*(1+CK18) -> 0 | DK18: =V26-(MIN(30%*V26,DK17)) -> 0 | DO18: =H18-10*H233 -> -391894.5 | EM18: =EM16+EM17 -> 1
A19: =P19/Hoja15!C11 -> 7.5203194 | B19: =J19/F19 -> 0.00076399894 | E19: Junio | F19: =H234 -> 39267.07 | G19: 7000000 | I19: =IF($Y$4=1,Y19*0.1,IF(G19-AB19-AC19-AD19-AE19<(50*F19),G19-AB19-AC19-AD19-AE19,50*F19)) -> 1963353.5 | J19: 30 | K19: 0 | L19: 0 | N19: =G19-AB19-AC19-AD19-AE19-AF19 -> 5580652.5 | P19: =N19*Z19-AA19 -> 517285.17 | R19: =AW19 -> 0 | T19: =AW19*AX19-AY19 -> 0 | X19: =+V19*0.145 -> 0 | Y19: =IF(G19>87.8*F19,87.8*F19,G19) -> 3447648.7 | Z19: =VLOOKUP(N19,Hoja15!$E$51:$H$58,3) -> 0.23 | AA19: =VLOOKUP(N19,Hoja15!$E$51:$H$58,4) -> 766264.9 | AB19: =IF($AX$5=2,0,Y19*0.1) -> 0 | AC19: =IF($BF$7=0,0,(IF(G19>87.8*F19,87.8*F19*$AC$4,$AC$4*G19))) -> 0 | AD19: =IF(G19>87.8*F19,87.8*7%*F19,7%*G19) -> 241335.41 | AE19: =(IF($BF$7=0,0,IF($HS$6="No",0,IF(G19>131.8*F19,0.6%*131.8*F19,0.6%*G19))))*$AH$5 -> 0 | AF19: =IF($AJ$42=2,J19*F19,J19) -> 1178012.1 | AG19: =IF($AK$42=2,M19*F19,M19) -> 0 | AH19: =IF($AL$42=2,L19*F19,L19) -> 0 | AI19: =IF($AM$42=2,M19*F19,M19) -> 0 | AJ19: =IF(AF19>I19,1,0) -> 0 | AK19: =I19/F19 -> 50 | AL19: =AF19/F19 -> 30 | AM19: =AG19/F19 -> 0 | AN19: =AH19/F19 -> 0 | AO19: =AI19/F19 -> 0 | AR19: =P19/F19 -> 13.173511 | AW19: =BF19-BB19-AZ19 -> 0 | AX19: =VLOOKUP(AW19,Hoja15!$E$51:$H$58,3) -> 0 | AY19: =VLOOKUP(AW19,Hoja15!$E$51:$H$58,4) -> 0 | AZ19: 0 | BA19: =1.25%*BF19 -> 0 | BB19: =IF(BF19>60*F19,60*7%*F19,7%*BF19) -> 0 | BC19: 0 | BD19: 0 | BF19: =IF($P$3="No pensionado",0,H19) -> 0 | BI19: =N19+R19 -> 5580652.5 | BJ19: =VLOOKUP(BI19,Hoja15!$E$51:$H$58,3) -> 0.23 | BK19: =VLOOKUP(BI19,Hoja15!$E$51:$H$58,4) -> 766264.9 | BL19: =BI19*BJ19-BK19 -> 517285.17 | BM19: =BL19/Hoja15!C11 -> 7.5203194 | BP19: =P19/Hoja15!C11 -> 7.5203194 | BQ19: =T19/Hoja15!C11 -> 0 | BT19: =I19/F19 -> 50 | BX19: =IF($AJ$42=1,M19/F19,J19) -> 30 | BY19: =IF($AJ$42=1,J19/F19,J19) -> 30 | BZ19: =I19/F19 -> 50 | CF19: Provida | CG19: 0.0145 | CJ19: junio | CK19: =J234 -> 0 | CM19: =N19*(1+CK19) -> 5580652.5 | CN19: =R19*(1+CK19) -> 0 | CO19: =P19*(1+CK19) -> 517285.17 | CP19: =T19*(1+CK19) -> 0 | CQ19: =V19*(1+CK19) -> 0 | CR19: =X19*(1+CK19) -> 0 | CS19: =IF($AJ$42=2,J19*H234,J19)*(1+CK19) -> 1178012.1 | CT19: =IF($AK$42=2,M19*H234,M19)*(1+CK19) -> 0 | DK19: =MIN(600*H240,DK18) -> 0 | DO19: =H19-10*H234 -> -392670.7
A20: =P20/Hoja15!C12 -> 7.493579 | B20: =J20/F20 -> 0.00076571613 | E20: Julio | F20: =H235 -> 39179.01 | G20: 7000000 | I20: =IF($Y$4=1,Y20*0.1,IF(G20-AB20-AC20-AD20-AE20<(50*F20),G20-AB20-AC20-AD20-AE20,50*F20)) -> 1958950.5 | J20: 30 | K20: 0 | L20: 0 | N20: =G20-AB20-AC20-AD20-AE20-AF20 -> 5583835.5 | P20: =N20*Z20-AA20 -> 516479.95 | R20: =AW20 -> 0 | T20: =AW20*AX20-AY20 -> 0 | X20: =+V20*0.145 -> 0 | Y20: =IF(G20>87.8*F20,87.8*F20,G20) -> 3439917.1 | Z20: =VLOOKUP(N20,Hoja15!$E$60:$H$67,3) -> 0.23 | AA20: =VLOOKUP(N20,Hoja15!$E$60:$H$67,4) -> 767802.22 | AB20: =IF($AX$5=2,0,Y20*0.1) -> 0 | AC20: =IF($BF$7=0,0,(IF(G20>87.8*F20,87.8*F20*$AC$4,$AC$4*G20))) -> 0 | AD20: =IF(G20>87.8*F20,87.8*7%*F20,7%*G20) -> 240794.2 | AE20: =(IF($BF$7=0,0,IF($HS$6="No",0,IF(G20>131.8*F20,0.6%*131.8*F20,0.6%*G20))))*$AH$5 -> 0 | AF20: =IF($AJ$42=2,J20*F20,J20) -> 1175370.3 | AG20: =IF($AK$42=2,M20*F20,M20) -> 0 | AH20: =IF($AL$42=2,L20*F20,L20) -> 0 | AI20: =IF($AM$42=2,M20*F20,M20) -> 0 | AJ20: =IF(AF20>I20,1,0) -> 0 | AK20: =I20/F20 -> 50 | AL20: =AF20/F20 -> 30 | AM20: =AG20/F20 -> 0 | AN20: =AH20/F20 -> 0 | AO20: =AI20/F20 -> 0 | AR20: =P20/F20 -> 13.182568 | AW20: =BF20-BB20-AZ20 -> 0 | AX20: =VLOOKUP(AW20,Hoja15!$E$60:$H$67,3) -> 0 | AY20: =VLOOKUP(AW20,Hoja15!$E$60:$H$67,4) -> 0 | AZ20: 0 | BA20: =1.25%*BF20 -> 0 | BB20: =IF(BF20>60*F20,60*7%*F20,7%*BF20) -> 0 | BC20: 0 | BD20: 0 | BF20: =IF($P$3="No pensionado",0,H20) -> 0 | BI20: =N20+R20 -> 5583835.5 | BJ20: =VLOOKUP(BI20,Hoja15!$E$60:$H$67,3) -> 0.23 | BK20: =VLOOKUP(BI20,Hoja15!$E$60:$H$67,4) -> 767802.22 | BL20: =BI20*BJ20-BK20 -> 516479.95 | BM20: =BL20/Hoja15!C12 -> 7.493579 | BP20: =P20/Hoja15!C12 -> 7.493579 | BQ20: =T20/Hoja15!C12 -> 0 | BT20: =I20/F20 -> 50 | BX20: =IF($AJ$42=1,M20/F20,J20) -> 30 | BY20: =IF($AJ$42=1,J20/F20,J20) -> 30 | BZ20: =I20/F20 -> 50 | CJ20: julio | CK20: =J235 -> 0 | CM20: =N20*(1+CK20) -> 5583835.5 | CN20: =R20*(1+CK20) -> 0 | CO20: =P20*(1+CK20) -> 516479.95 | CP20: =T20*(1+CK20) -> 0 | CQ20: =V20*(1+CK20) -> 0 | CR20: =X20*(1+CK20) -> 0 | CS20: =IF($AJ$42=2,J20*H235,J20)*(1+CK20) -> 1175370.3 | CT20: =IF($AK$42=2,M20*H235,M20)*(1+CK20) -> 0 | DK20: =IF(((AK26-(AL26+AM26))*F25)<0,0,(AK26-(AL26+AM26))*F25) -> 9514461.6 | DO20: =H20-10*H235 -> -391790.1
A21: =P21/Hoja15!C13 -> 7.5437837 | B21: =J21/F21 -> 0.00076174864 | E21: Agosto | F21: =H236 -> 39383.07 | G21: 7000000 | I21: =IF($Y$4=1,Y21*0.1,IF(G21-AB21-AC21-AD21-AE21<(50*F21),G21-AB21-AC21-AD21-AE21,50*F21)) -> 1969153.5 | J21: 30 | K21: 0 | L21: 0 | N21: =G21-AB21-AC21-AD21-AE21-AF21 -> 5576459.6 | P21: =N21*Z21-AA21 -> 517858.12 | R21: =AW21 -> 0 | T21: =AW21*AX21-AY21 -> 0 | X21: =+V21*0.145 -> 0 | Y21: =IF(G21>87.8*F21,87.8*F21,G21) -> 3457833.5 | Z21: =VLOOKUP(N21,Hoja15!$E$69:$H$76,3) -> 0.23 | AA21: =VLOOKUP(N21,Hoja15!$E$69:$H$76,4) -> 764727.58 | AB21: =IF($AX$5=2,0,Y21*0.1) -> 0 | AC21: =IF($BF$7=0,0,(IF(G21>87.8*F21,87.8*F21*$AC$4,$AC$4*G21))) -> 0 | AD21: =IF(G21>87.8*F21,87.8*7%*F21,7%*G21) -> 242048.35 | AE21: =(IF($BF$7=0,0,IF($HS$6="No",0,IF(G21>131.8*F21,0.6%*131.8*F21,0.6%*G21))))*$AH$5 -> 0 | AF21: =IF($AJ$42=2,J21*F21,J21) -> 1181492.1 | AG21: =IF($AK$42=2,M21*F21,M21) -> 0 | AH21: =IF($AL$42=2,L21*F21,L21) -> 0 | AI21: =IF($AM$42=2,M21*F21,M21) -> 0 | AJ21: =IF(AF21>I21,1,0) -> 0 | AK21: =I21/F21 -> 50 | AL21: =AF21/F21 -> 30 | AM21: =AG21/F21 -> 0 | AN21: =AH21/F21 -> 0 | AO21: =AI21/F21 -> 0 | AR21: =P21/F21 -> 13.149257 | AW21: =BF21-BB21-AZ21 -> 0 | AX21: =VLOOKUP(AW21,Hoja15!$E$69:$H$76,3) -> 0 | AY21: =VLOOKUP(AW21,Hoja15!$E$69:$H$76,4) -> 0 | AZ21: 0 | BA21: =1.25%*BF21 -> 0 | BB21: =IF(BF21>60*F21,60*7%*F21,7%*BF21) -> 0 | BC21: 0 | BD21: 0 | BF21: =IF($P$3="No pensionado",0,H21) -> 0 | BI21: =N21+R21 -> 5576459.6 | BJ21: =VLOOKUP(BI21,Hoja15!$E$69:$H$76,3) -> 0.23 | BK21: =VLOOKUP(BI21,Hoja15!$E$69:$H$76,4) -> 764727.58 | BL21: =BI21*BJ21-BK21 -> 517858.12 | BM21: =BL21/Hoja15!C13 -> 7.5437837 | BP21: =P21/Hoja15!C13 -> 7.5437837 | BQ21: =T21/Hoja15!C13 -> 0 | BT21: =I21/F21 -> 50 | BX21: =IF($AJ$42=1,M21/F21,J21) -> 30 | BY21: =IF($AJ$42=1,J21/F21,J21) -> 30 | BZ21: =I21/F21 -> 50 | CJ21: agosto | CK21: =J236 -> 0 | CM21: =N21*(1+CK21) -> 5576459.6 | CN21: =R21*(1+CK21) -> 0 | CO21: =P21*(1+CK21) -> 517858.12 | CP21: =T21*(1+CK21) -> 0 | CQ21: =V21*(1+CK21) -> 0 | CR21: =X21*(1+CK21) -> 0 | CS21: =IF($AJ$42=2,J21*H236,J21)*(1+CK21) -> 1181492.1 | CT21: =IF($AK$42=2,M21*H236,M21)*(1+CK21) -> 0 | DO21: =H21-10*H236 -> -393830.7
A22: =P22/Hoja15!C14 -> 7.3647699 | B22: =J22/F22 -> 0.00075976969 | E22: Septiembre | F22: =H237 -> 39485.65 | G22: 7000000 | I22: =IF($Y$4=1,Y22*0.1,IF(G22-AB22-AC22-AD22-AE22<(50*F22),G22-AB22-AC22-AD22-AE22,50*F22)) -> 1974282.5 | J22: 30 | K22: 0 | L22: 0 | N22: =G22-AB22-AC22-AD22-AE22-AF22 -> 5572751.7 | P22: =N22*Z22-AA22 -> 510120.79 | R22: =AW22 -> 0 | T22: =AW22*AX22-AY22 -> 0 | X22: =+V22*0.145 -> 0 | Y22: =IF(G22>87.8*F22,87.8*F22,G22) -> 3466840.1 | Z22: =VLOOKUP(N22,Hoja15!$E$78:$H$85,3) -> 0.23 | AA22: =VLOOKUP(N22,Hoja15!$E$78:$H$85,4) -> 771612.1 | AB22: =IF($AX$5=2,0,Y22*0.1) -> 0 | AC22: =IF($BF$7=0,0,(IF(G22>87.8*F22,87.8*F22*$AC$4,$AC$4*G22))) -> 0 | AD22: =IF(G22>87.8*F22,87.8*7%*F22,7%*G22) -> 242678.8 | AE22: =(IF($BF$7=0,0,IF($HS$6="No",0,IF(G22>131.8*F22,0.6%*131.8*F22,0.6%*G22))))*$AH$5 -> 0 | AF22: =IF($AJ$42=2,J22*F22,J22) -> 1184569.5 | AG22: =IF($AK$42=2,M22*F22,M22) -> 0 | AH22: =IF($AL$42=2,L22*F22,L22) -> 0 | AI22: =IF($AM$42=2,M22*F22,M22) -> 0 | AJ22: =IF(AF22>I22,1,0) -> 0 | AK22: =I22/F22 -> 50 | AL22: =AF22/F22 -> 30 | AM22: =AG22/F22 -> 0 | AN22: =AH22/F22 -> 0 | AO22: =AI22/F22 -> 0 | AR22: =P22/F22 -> 12.919144 | AW22: =BF22-BB22-AZ22 -> 0 | AX22: =VLOOKUP(AW22,Hoja15!$E$78:$H$85,3) -> 0 | AY22: =VLOOKUP(AW22,Hoja15!$E$78:$H$85,4) -> 0 | AZ22: 0 | BA22: =1.25%*BF22 -> 0 | BB22: =IF(BF22>60*F22,60*7%*F22,7%*BF22) -> 0 | BC22: 0 | BD22: 0 | BF22: =IF($P$3="No pensionado",0,H22) -> 0 | BI22: =N22+R22 -> 5572751.7 | BJ22: =VLOOKUP(BI22,Hoja15!$E$78:$H$85,3) -> 0.23 | BK22: =VLOOKUP(BI22,Hoja15!$E$78:$H$85,4) -> 771612.1 | BL22: =BI22*BJ22-BK22 -> 510120.79 | BM22: =BL22/Hoja15!C14 -> 7.3647699 | BP22: =P22/Hoja15!C14 -> 7.3647699 | BQ22: =T22/Hoja15!C14 -> 0 | BT22: =I22/F22 -> 50 | BX22: =IF($AJ$42=1,M22/F22,J22) -> 30 | BY22: =IF($AJ$42=1,J22/F22,J22) -> 30 | BZ22: =I22/F22 -> 50 | CJ22: septiembre | CK22: =J237 -> 0 | CM22: =N22*(1+CK22) -> 5572751.7 | CN22: =R22*(1+CK22) -> 0 | CO22: =P22*(1+CK22) -> 510120.79 | CP22: =T22*(1+CK22) -> 0 | CQ22: =V22*(1+CK22) -> 0 | CR22: =X22*(1+CK22) -> 0 | CS22: =IF($AJ$42=2,J22*H237,J22)*(1+CK22) -> 1184569.5 | CT22: =IF($AK$42=2,M22*H237,M22)*(1+CK22) -> 0 | DO22: =H22-10*H237 -> -394856.5
A23: =P23/Hoja15!C15 -> 7.3647699 | B23: =J23/F23 -> 0.00075976969 | E23: Octubre | F23: =H238 -> 39485.65 | G23: 7000000 | I23: =IF($Y$4=1,Y23*0.1,IF(G23-AB23-AC23-AD23-AE23<(50*F23),G23-AB23-AC23-AD23-AE23,50*F23)) -> 1974282.5 | J23: 30 | K23: 0 | L23: 0 | N23: =G23-AB23-AC23-AD23-AE23-AF23 -> 5572751.7 | P23: =N23*Z23-AA23 -> 510120.79 | R23: =AW23 -> 0 | T23: =AW23*AX23-AY23 -> 0 | X23: =+V23*0.145 -> 0 | Y23: =IF(G23>87.8*F23,87.8*F23,G23) -> 3466840.1 | Z23: =VLOOKUP(N23,Hoja15!$E$87:$H$94,3) -> 0.23 | AA23: =VLOOKUP(N23,Hoja15!$E$87:$H$94,4) -> 771612.1 | AB23: =IF($AX$5=2,0,Y23*0.1) -> 0 | AC23: =IF($BF$7=0,0,(IF(G23>87.8*F23,87.8*F23*$AC$4,$AC$4*G23))) -> 0 | AD23: =IF(G23>87.8*F23,87.8*7%*F23,7%*G23) -> 242678.8 | AE23: =(IF($BF$7=0,0,IF($HS$6="No",0,IF(G23>131.8*F23,0.6%*131.8*F23,0.6%*G23))))*$AH$5 -> 0 | AF23: =IF($AJ$42=2,J23*F23,J23) -> 1184569.5 | AG23: =IF($AK$42=2,M23*F23,M23) -> 0 | AH23: =IF($AL$42=2,L23*F23,L23) -> 0 | AI23: =IF($AM$42=2,M23*F23,M23) -> 0 | AJ23: =IF(AF23>I23,1,0) -> 0 | AK23: =I23/F23 -> 50 | AL23: =AF23/F23 -> 30 | AM23: =AG23/F23 -> 0 | AN23: =AH23/F23 -> 0 | AO23: =AI23/F23 -> 0 | AR23: =P23/F23 -> 12.919144 | AW23: =BF23-BB23-AZ23 -> 0 | AX23: =VLOOKUP(AW23,Hoja15!$E$87:$H$94,3) -> 0 | AY23: =VLOOKUP(AW23,Hoja15!$E$87:$H$94,4) -> 0 | AZ23: 0 | BA23: =1.25%*BF23 -> 0 | BB23: =IF(BF23>60*F23,60*7%*F23,7%*BF23) -> 0 | BC23: 0 | BD23: 0 | BF23: =IF($P$3="No pensionado",0,H23) -> 0 | BI23: =N23+R23 -> 5572751.7 | BJ23: =VLOOKUP(BI23,Hoja15!$E$87:$H$94,3) -> 0.23 | BK23: =VLOOKUP(BI23,Hoja15!$E$87:$H$94,4) -> 771612.1 | BL23: =BI23*BJ23-BK23 -> 510120.79 | BM23: =BL23/Hoja15!C15 -> 7.3647699 | BP23: =P23/Hoja15!C15 -> 7.3647699 | BQ23: =T23/Hoja15!C15 -> 0 | BT23: =I23/F23 -> 50 | BX23: =IF($AJ$42=1,M23/F23,J23) -> 30 | BY23: =IF($AJ$42=1,J23/F23,J23) -> 30 | BZ23: =I23/F23 -> 50 | CJ23: octubre | CK23: =J238 -> 0 | CM23: =N23*(1+CK23) -> 5572751.7 | CN23: =R23*(1+CK23) -> 0 | CO23: =P23*(1+CK23) -> 510120.79 | CP23: =T23*(1+CK23) -> 0 | CQ23: =V23*(1+CK23) -> 0 | CR23: =X23*(1+CK23) -> 0 | CS23: =IF($AJ$42=2,J23*H238,J23)*(1+CK23) -> 1184569.5 | CT23: =IF($AK$42=2,M23*H238,M23)*(1+CK23) -> 0 | DO23: =H23-10*H238 -> -394856.5
A24: =P24/Hoja15!C16 -> 7.2776699 | B24: =J24/F24 -> 0.00075762033 | E24: Noviembre | F24: =H239 -> 39597.67 | G24: 7000000 | I24: =IF($Y$4=1,Y24*0.1,IF(G24-AB24-AC24-AD24-AE24<(50*F24),G24-AB24-AC24-AD24-AE24,50*F24)) -> 1979883.5 | J24: 30 | K24: 0 | L24: 0 | N24: =G24-AB24-AC24-AD24-AE24-AF24 -> 5568702.6 | P24: =N24*Z24-AA24 -> 506103.72 | R24: =AW24 -> 0 | T24: =AW24*AX24-AY24 -> 0 | X24: =+V24*0.145 -> 0 | Y24: =IF(G24>87.8*F24,87.8*F24,G24) -> 3476675.4 | Z24: =VLOOKUP(N24,Hoja15!$E$96:$H$103,3) -> 0.23 | AA24: =VLOOKUP(N24,Hoja15!$E$96:$H$103,4) -> 774697.88 | AB24: =IF($AX$5=2,0,Y24*0.1) -> 0 | AC24: =IF($BF$7=0,0,(IF(G24>87.8*F24,87.8*F24*$AC$4,$AC$4*G24))) -> 0 | AD24: =IF(G24>87.8*F24,87.8*7%*F24,7%*G24) -> 243367.28 | AE24: =(IF($BF$7=0,0,IF($HS$6="No",0,IF(G24>131.8*F24,0.6%*131.8*F24,0.6%*G24))))*$AH$5 -> 0 | AF24: =IF($AJ$42=2,J24*F24,J24) -> 1187930.1 | AG24: =IF($AK$42=2,M24*F24,M24) -> 0 | AH24: =IF($AL$42=2,L24*F24,L24) -> 0 | AI24: =IF($AM$42=2,M24*F24,M24) -> 0 | AJ24: =IF(AF24>I24,1,0) -> 0 | AK24: =I24/F24 -> 50 | AL24: =AF24/F24 -> 30 | AM24: =AG24/F24 -> 0 | AN24: =AH24/F24 -> 0 | AO24: =AI24/F24 -> 0 | AR24: =P24/F24 -> 12.781149 | AW24: =BF24-BB24-AZ24 -> 0 | AX24: =VLOOKUP(AW24,Hoja15!$E$96:$H$103,3) -> 0 | AY24: =VLOOKUP(AW24,Hoja15!$E$96:$H$103,4) -> 0 | AZ24: 0 | BA24: =1.25%*BF24 -> 0 | BB24: =IF(BF24>60*F24,60*7%*F24,7%*BF24) -> 0 | BC24: 0 | BD24: 0 | BF24: =IF($P$3="No pensionado",0,H24) -> 0 | BI24: =N24+R24 -> 5568702.6 | BJ24: =VLOOKUP(BI24,Hoja15!$E$96:$H$103,3) -> 0.23 | BK24: =VLOOKUP(BI24,Hoja15!$E$96:$H$103,4) -> 774697.88 | BL24: =BI24*BJ24-BK24 -> 506103.72 | BM24: =BL24/Hoja15!C16 -> 7.2776699 | BP24: =P24/Hoja15!C16 -> 7.2776699 | BQ24: =T24/Hoja15!C16 -> 0 | BT24: =I24/F24 -> 50 | BX24: =IF($AJ$42=1,M24/F24,J24) -> 30 | BY24: =IF($AJ$42=1,J24/F24,J24) -> 30 | BZ24: =I24/F24 -> 50 | CJ24: noviembre | CK24: =J239 -> 0 | CM24: =N24*(1+CK24) -> 5568702.6 | CN24: =R24*(1+CK24) -> 0 | CO24: =P24*(1+CK24) -> 506103.72 | CP24: =T24*(1+CK24) -> 0 | CQ24: =V24*(1+CK24) -> 0 | CR24: =X24*(1+CK24) -> 0 | CS24: =IF($AJ$42=2,J24*H239,J24)*(1+CK24) -> 1187930.1 | CT24: =IF($AK$42=2,M24*H239,M24)*(1+CK24) -> 0 | DK24: =G38/20000000 -> 0.19188476 | DO24: =H24-10*H239 -> -395976.7
A25: =P25/Hoja15!C17 -> 7.2721803 | B25: =J25/F25 -> 0.00075674277 | E25: Diciembre | F25: =H240 -> 39643.59 | G25: 7000000 | I25: =IF($Y$4=1,Y25*0.1,IF(G25-AB25-AC25-AD25-AE25<(50*F25),G25-AB25-AC25-AD25-AE25,50*F25)) -> 1982179.5 | J25: 30 | K25: 0 | L25: 0 | N25: =G25-AB25-AC25-AD25-AE25-AF25 -> 5567042.8 | P25: =N25*Z25-AA25 -> 505721.96 | R25: =AW25 -> 0 | T25: =AW25*AX25-AY25 -> 0 | X25: =+V25*0.145 -> 0 | Y25: =IF(G25>87.8*F25,87.8*F25,G25) -> 3480707.2 | Z25: =VLOOKUP(N25,Hoja15!$E$105:$H$112,3) -> 0.23 | AA25: =VLOOKUP(N25,Hoja15!$E$105:$H$112,4) -> 774697.88 | AB25: =IF($AX$5=2,0,Y25*0.1) -> 0 | AC25: =IF($BF$7=0,0,(IF(G25>87.8*F25,87.8*F25*$AC$4,$AC$4*G25))) -> 0 | AD25: =IF(G25>87.8*F25,87.8*7%*F25,7%*G25) -> 243649.5 | AE25: =(IF($BF$7=0,0,IF($HS$6="No",0,IF(G25>131.8*F25,0.6%*131.8*F25,0.6%*G25))))*$AH$5 -> 0 | AF25: =IF($AJ$42=2,J25*F25,J25) -> 1189307.7 | AG25: =IF($AK$42=2,M25*F25,M25) -> 0 | AH25: =IF($AL$42=2,L25*F25,L25) -> 0 | AI25: =IF($AM$42=2,M25*F25,M25) -> 0 | AJ25: =IF(AF25>I25,1,0) -> 0 | AK25: =I25/F25 -> 50 | AL25: =AF25/F25 -> 30 | AM25: =AG25/F25 -> 0 | AN25: =AH25/F25 -> 0 | AO25: =AI25/F25 -> 0 | AR25: =P25/F25 -> 12.756715 | AW25: =BF25-BB25-AZ25 -> 0 | AX25: =VLOOKUP(AW25,Hoja15!$E$105:$H$112,3) -> 0 | AY25: =VLOOKUP(AW25,Hoja15!$E$105:$H$112,4) -> 0 | AZ25: 0 | BA25: =1.25%*BF25 -> 0 | BB25: =IF(BF25>60*F25,60*7%*F25,7%*BF25) -> 0 | BC25: 0 | BD25: 0 | BF25: =IF($P$3="No pensionado",0,H25) -> 0 | BI25: =N25+R25 -> 5567042.8 | BJ25: =VLOOKUP(BI25,Hoja15!$E$105:$H$112,3) -> 0.23 | BK25: =VLOOKUP(BI25,Hoja15!$E$105:$H$112,4) -> 774697.88 | BL25: =BI25*BJ25-BK25 -> 505721.96 | BM25: =BL25/Hoja15!C17 -> 7.2721803 | BP25: =P25/Hoja15!C17 -> 7.2721803 | BQ25: =T25/Hoja15!C17 -> 0 | BT25: =I25/F25 -> 50 | BX25: =IF($AJ$42=1,M25/F25,J25) -> 30 | BY25: =IF($AJ$42=1,J25/F25,J25) -> 30 | BZ25: =I25/F25 -> 50 | CJ25: diciembre | CK25: =J240 -> 0 | CM25: =N25*(1+CK25) -> 5567042.8 | CN25: =R25*(1+CK25) -> 0 | CO25: =P25*(1+CK25) -> 505721.96 | CP25: =T25*(1+CK25) -> 0 | CQ25: =V25*(1+CK25) -> 0 | CR25: =X25*(1+CK25) -> 0 | CS25: =IF($AJ$42=2,J25*H240,J25)*(1+CK25) -> 1189307.7 | CT25: =IF($AK$42=2,M25*H240,M25)*(1+CK25) -> 0 | DO25: =H25-10*H240 -> -396435.9
E26: Total | G26: =SUM(G14:G25) -> 105000000 | H26: =SUM(H14:H25) -> 0 | I26: =SUM(I14:I25) -> 23511652 | J26: =AF26 -> 14106991 | K26: =AG26 -> 0 | L26: =AH26 -> 0 | M26: =(IF(AK42=1,SUM(M14:M25),AI26))+V62 -> 0 | N26: =SUM(N14:N25) -> 88002957 | P26: =SUM(P14:P25) -> 13702706 | R26: =SUM(R14:R25) -> 0 | T26: =SUM(T14:T25) -> 0 | V26: =SUM(V14:V25) -> 0 | X26: =SUM(X14:X25) -> 0 | AB26: =SUM(AB14:AB25) -> 0 | AC26: =SUM(AC14:AC25) -> 0 | AD26: =SUM(AD14:AD25) -> 2890052.2 | AE26: =SUM(AE14:AE25) -> 0 | AF26: =SUM(AF14:AF25) -> 14106991 | AG26: =SUM(AG14:AG25) -> 0 | AH26: =IF(AK42=2,SUMPRODUCT(F14:F25,AH14:AH25),SUM(AH14:AH25)) -> 0 | AI26: =SUMPRODUCT(AI14:AI25,F14:F25) -> 0 | AJ26: =IF(AF26>I26,1,0) -> 0 | AK26: =SUM(AK14:AK25) -> 600 | AL26: =SUM(AL14:AL25) -> 360 | AM26: =SUM(AM14:AM25) -> 0 | AN26: =SUM(AN14:AN25) -> 0 | AO26: =SUM(AO14:AO25) -> 0 | AR26: =SUM(AR14:AR25) -> 351.15919 | AS26: =AR26*Hoja14!F25 -> 13921211 | AW26: =SUM(AW14:AW25) -> 0 | AZ26: =SUM(AZ14:AZ25) -> 0 | BA26: =SUM(BA14:BA25) -> 0 | BB26: =SUM(BB14:BB25) -> 0 | BC26: =SUM(BC14:BC25) -> 0 | BD26: =SUM(BD14:BD25) -> 0 | BL26: =SUM(BL14:BL25) -> 13702706 | BM26: =SUM(BM14:BM25)*Hoja15!C17 -> 13952288 | BP26: =SUM(BP14:BP25)*Hoja15!C17 -> 13952288 | BQ26: =SUM(BQ14:BQ25)*Hoja15!C17 -> 0 | BR26: =BP26+BQ26 -> 13952288 | BX26: =SUM(BX14:BX25) -> 360 | BY26: =SUM(BY14:BY25) -> 360 | BZ26: =SUM(BZ14:BZ25) -> 600 | CA26: =BZ26-BY26-BX26 -> -120 | CB26: =CA26*F25 -> -4757230.8 | CM26: =SUM(CM14:CM25) -> 88002957 | CN26: =SUM(CN14:CN25) -> 0 | CO26: =SUM(CO14:CO25) -> 13702706 | CP26: =SUM(CP14:CP25) -> 0 | CQ26: =SUM(CQ14:CQ25) -> 0 | CR26: =SUM(CR14:CR25) -> 0 | CS26: =SUM(CS14:CS25) -> 14106991 | CT26: =SUM(CT14:CT25) -> 0 | DO26: =SUM(DO14:DO25) -> -4702330.3
CP27: =T27 -> 0 | CT27: =IF($AK$42=2,M27*H242,M27) -> 0
E30: Pagos Directos y Vía Empleador corregidos efectuados en el año | J30: =AL32+AM32 -> 14271692 | N30: Otras Rentas afectas a IGC | R30: 12000000 | DK30: APV máx. dependiente (Art. 42 N° 1) | DN30: =DK20 -> 9514461.6
E31: APV B máx. para utilizar 100% del beneficio tributario (*) | J31: =MIN(600*H240-J30,DK20+DK19) -> 9514461.6 | M31: =IF(((AK26-(AL26+AM26))*F25)<0,"Supera límite anual"," ") | Z31: 20939.49 | AA31: 20865.85 | AB31: 20924.09 | AC31: 21000.55 | AD31: 21032.2 | AE31: 21115.8 | AF31: 21204.99 | AG31: 21227.57 | AL31: =AL26+AM26 -> 360 | CM31: =CM26*Hoja15!L111-Hoja15!M111 -> 11340402 | DK31: APV max. Independiente (Art. 42 N° 2) | DN31: =DK19 -> 0
E32: =IF(Y4=1,"APV B máx. socio que se asigna Sueldo Empresarial","APV B máx. en calidad de trabajador dependiente (Art. 42 N° 1)") -> APV B máx. en calidad de trabajador dependiente (Art. 42 N° 1) | J32: =DN30 -> 9514461.6 | AL32: =AL26*H240 -> 14271692 | AM32: =AM26*H240 -> 0
E33: APV B máx. en calidad de trabajador independiente (Art. 42 N° 2) | J33: =MIN(J31,DN31) -> 0 | AL33: =AK26*H240 -> 23786154
E34: Pago Directo APV opción B final | Z34: Sueldo Empresarial | AA34: =R197+Hoja1!L17 -> -1305364.3 | AL34: =AL33-AL32 -> 9514461.6
Z35: No pensionado
G36: RESULTADO RELIQUIDACIÓN DE IMPUESTO : | Z36: Pensionado no cotizante | AB36: =IF(P5>8*Hoja15!B23,8*Hoja15!B23,Hoja14!P5) -> 0 | AZ36: =P26 -> 13702706
G37: =Z64 -> (En contra) | Z37: Pensionado cotizante | AZ37: =X26 -> 0
G38: =Hoja9!C23 -> 3837695.2 | AZ38: =N26 -> 88002957 | BA38: =AZ38+AZ39 -> 88002957
X39: =IF(G38=0,1,0) -> 0 | AB39: =Hoja15!C17*15*12 -> 12517560 | AZ39: =V26 -> 0
AB40: =IF(30%*V26>AB39,AB39,30%*V26) -> 0 | AD40: Directos anuales | AE40: =IF(M26>0,1,0) -> 0 | AJ40: pesos ($) | AK40: Si | AZ40: =IF((L110+L111)=0,0,IF(L111=0,0,M84-M94)) -> 0
Q41: =IF(P7=4,1,0) -> 0 | AB41: =V26-AB40 -> 0 | AD41: Directo final | AE41: =IF(J34>0,1,0) -> 0 | AJ41: UF | AK41: No
AD42: 55 bis | AE42: =IF(R5>0,1,0) -> 0 | AJ42: 2 | AK42: 1 | AL42: 1 | AM42: 1 | AZ42: =IF((M86+M88)>0,AZ40,IF(V26>0,Hoja15!R109,Hoja14!AZ40)) -> 0
Q43: =IF(T45=1,R6*1,R6*-1) -> 0 | T43: =IF(T45=1,1,-1) -> -1 | AA43: =N26+R26 -> 88002957 | AE43: =SUM(AE40:AE42) -> 0
E44: =SUM(B14:B25)*F25 -> 364.23559 | X44: =R197+R198-Y132-R199-#REF! -> #REF! | AA44: =Hoja14!AA43*Hoja15!L110-Hoja15!M110 -> 11898728
E45: =SUM(BT14:BT25)*F25 -> 23786154 | Q45: =15%*MIN(65*Hoja15!C17*12,30%*Hoja5!F8,Hoja14!R6) -> 0 | T45: 2
E46: =E45-E44 -> 23785790 | R46: 0 | T46: positivo
...

Sheet Hoja8

Sheet Hoja7

Sheet Hoja15
B6: Enero | C6: =Hoja14!I229 -> 67429 | E6: =$C$6*J6 -> 0 | F6: =$C$6*$K$6 -> 910291.5 | G6: =L6 -> 0 | H6: =$C$6*$M$6 -> 0 | J6: 0 | K6: 13.5 | L6: 0 | M6: 0 | U6: =C6 -> 67429 | AJ6: =B6 -> Enero | AK6: =Hoja14!P14/C6 -> 8.0044058
B7: Febrero | C7: =Hoja14!I230 -> 67294 | E7: =$C$6*$J$7 -> 910291.5 | F7: =$C$6*$K$7 -> 2022870 | G7: =L7 -> 0.04 | H7: =$C$6*$M$7 -> 36411.66 | J7: 13.5 | K7: 30 | L7: 0.04 | M7: 0.54 | O7: 36679 | U7: =C7 -> 67294 | AJ7: =B7 -> Febrero | AK7: =Hoja14!P15/C7 -> 8.010255
B8: Marzo | C8: =Hoja14!I231 -> 68034 | E8: =$C$6*$J$8 -> 2022870 | F8: =$C$6*$K$8 -> 3371450 | G8: =L8 -> 0.08 | H8: =$C$6*$M$8 -> 117326.46 | J8: 30 | K8: 50 | L8: 0.08 | M8: 1.74 | O8: 36569 | U8: =C8 -> 68034 | AJ8: =B8 -> Marzo | AK8: =Hoja14!P16/C8 -> 117.5379
B9: Abril | C9: =Hoja14!I232 -> 68306 | E9: =$C$6*$J$9 -> 3371450 | F9: =$C$6*$K$9 -> 4720030 | G9: =L9 -> 0.135 | H9: =$C$6*$M$9 -> 302756.21 | J9: 50 | K9: 70 | L9: 0.135 | M9: 4.49 | O9: 36752 | U9: =C9 -> 68306 | AJ9: =B9 -> Abril | AK9: =Hoja14!P17/C9 -> 7.6745032
B10: Mayo | C10: =Hoja14!I233 -> 68648 | E10: =$C$6*$J$10 -> 4720030 | F10: =$C$6*$K$10 -> 6068610 | G10: =L10 -> 0.23 | H10: =$C$6*$M$10 -> 751159.06 | J10: 70 | K10: 90 | L10: 0.23 | M10: 11.14 | O10: 36862 | U10: =C10 -> 68648 | AJ10: =B10 -> Mayo | AK10: =Hoja14!P18/C10 -> 7.5669597
B11: Junio | C11: =Hoja14!I234 -> 68785 | E11: =$C$6*$J$11 -> 6068610 | F11: =$C$6*$K$11 -> 8091480 | G11: =L11 -> 0.304 | H11: =$C$6*$M$11 -> 1200236.2 | J11: 90 | K11: 120 | L11: 0.304 | M11: 17.8 | O11: 36899 | U11: =C11 -> 68785 | AA11: 2014 | AB11: UTM (1) | AC11: UTA (2) | AD11: Indice de Precios al Consumidor (IPC) | AE11: Variación Porcentual | AJ11: =B11 -> Junio | AK11: =Hoja14!P19/C11 -> 7.5203194
B12: Julio | C12: =Hoja14!I235 -> 68923 | E12: =$C$6*$J$12 -> 8091480 | F12: =$C$6*$K$12 -> 20902990 | G12: =L12 -> 0.35 | H12: =$C$6*$M$12 -> 1572444.3 | J12: 120 | K12: 310 | L12: 0.35 | M12: 23.32 | O12: 37083 | U12: =C12 -> 68923 | AD12: Valor en puntos (6) | AE12: Mensual (3) | AF12: Acumulado 2014 (4) | AG12: Ultimos 12 meses (5) | AJ12: =B12 -> Julio | AK12: =Hoja14!P20/C12 -> 7.493579
B13: Agosto | C13: =Hoja14!I236 -> 68647 | E13: =$C$6*$J$13 -> 20902990 | F13: =$C$6*$K$13 -> 674290000 | G13: =L13 -> 0.4 | H13: =$C$6*$M$13 -> 2617593.8 | J13: 310 | K13: 10000 | L13: 0.4 | M13: 38.82 | O13: 37231 | U13: =C13 -> 68647 | AA13: Enero | AB13: 40935 | AC13: 491220 | AD13: 101.69 | AE13: 0.2 | AF13: 0.2 | AG13: 3 | AJ13: =B13 -> Agosto | AK13: =Hoja14!P21/C13 -> 7.5437837
B14: Septiembre | C14: =Hoja14!I237 -> 69265 | O14: 37231 | U14: =C14 -> 69265 | AA14: Febrero | AB14: 41181 | AC14: 494172 | AD14: 102.18 | AE14: 0.5 | AF14: 0.7 | AG14: 3.4 | AJ14: =B14 -> Septiembre | AK14: =Hoja14!P22/C14 -> 7.3647699 | AM14: |
B15: Octubre | C15: =Hoja14!I238 -> 69265 | E15: =$C$7*J6 -> 0 | F15: =$C$7*K6 -> 908469 | G15: 0 | H15: =$C$7*M6 -> 0 | O15: 37231 | U15: =C15 -> 69265 | AA15: Marzo | AB15: 41263 | AC15: 495156 | AD15: 103.04 | AE15: 0.8 | AF15: 1.5 | AG15: 3.9 | AJ15: =B15 -> Octubre | AK15: =Hoja14!P23/C15 -> 7.3647699
B16: Noviembre | C16: =Hoja14!I239 -> 69542 | E16: =$C$7*J7 -> 908469 | F16: =$C$7*K7 -> 2018820 | G16: 0.04 | H16: =$C$7*M7 -> 36338.76 | O16: 37231 | U16: =C16 -> 69542 | AA16: Abril | AB16: 41469 | AC16: 497628 | AD16: 103.68 | AE16: 0.6 | AF16: 2.1 | AG16: 5 | AJ16: =B16 -> Noviembre | AK16: =Hoja14!P24/C16 -> 7.2776699
B17: Diciembre | C17: =Hoja14!I240 -> 69542 | E17: =$C$7*J8 -> 2018820 | F17: =$C$7*K8 -> 3364700 | G17: 0.08 | H17: =$C$7*M8 -> 117091.56 | J17: =Hoja14!N15*Hoja15!G17-Hoja15!H17 -> 331150.96 | O17: 37231 | U17: =C17 -> 69542 | AA17: Mayo | AB17: 41801 | AC17: 501612 | AD17: 104.03 | AE17: 0.3 | AF17: 2.5 | AG17: 5.4 | AJ17: =B17 -> Diciembre | AK17: =Hoja14!P25/C17 -> 7.2721803
E18: =$C$7*J9 -> 3364700 | F18: =$C$7*K9 -> 4710580 | G18: 0.135 | H18: =$C$7*M9 -> 302150.06 | O18: 37231 | AA18: Junio | AB18: 42052 | AC18: 504624 | AD18: 104.08 | AE18: 0.1 | AF18: 2.5 | AG18: 4.8 | AK18: =SUM(AK6:AK17) -> 200.6311 | AL18: =AK18*C17 -> 13952288
E19: =$C$7*J10 -> 4710580 | F19: =$C$7*K10 -> 6056460 | G19: 0.23 | H19: =$C$7*M10 -> 749655.16 | J19: =8*C17*12 -> 6676032 | AA19: Julio | AB19: 42178 | AC19: 506136 | AD19: 104.32 | AE19: 0.2 | AF19: 2.8 | AG19: 4.7
C20: =(C17-C6)/C6 -> 0.031336665 | E20: =$C$7*J11 -> 6056460 | F20: =$C$7*K11 -> 8075280 | G20: 0.304 | H20: =$C$7*M11 -> 1197833.2 | Q20: =Hoja14!J138+Hoja14!J140-Hoja14!J272-Hoja14!J34 -> 89358141 | X20: =455*34000 -> 15470000 | AA20: Agosto | AB20: 42220 | AC20: 506640 | AD20: 104.66 | AE20: 0.3 | AF20: 3.1 | AG20: 4.8
E21: =$C$7*J12 -> 8075280 | F21: =$C$7*K12 -> 20861140 | G21: 0.35 | H21: =$C$7*M12 -> 1569296.1 | AA21: Septiembre | AB21: 42304 | AC21: 507648 | AD21: 105.54 | AE21: 0.8 | AF21: 4 | AG21: 5.1
E22: =$C$7*J13 -> 20861140 | F22: =$C$7*K13 -> 672940000 | G22: 0.4 | H22: =$C$7*M13 -> 2612353.1 | M22: 0 | N22: =90*B23 -> 75105360 | O22: 1 | Q22: =Q20/B23 -> 107.07934 | AA22: Octubre | AB22: 42431 | AC22: 509172 | AD22: 106.64 | AE22: 1 | AF22: 5.1 | AG22: 6.1 | AK22: =Hoja14!N26*Hoja15!L111-Hoja15!M111 -> 11340402
B23: =C17*12 -> 834504 | M23: =N22+0.1 -> 75105360 | N23: =150*B23 -> 125175600 | O23: =Q23 -> 0.71498734 | Q23: =(250-Q22*1.667)/100 -> 0.71498734 | AA23: Noviembre | AB23: 42770 | AC23: 513240
E24: =$C$8*J6 -> 0 | F24: =$C$8*K6 -> 918459 | G24: 0 | H24: =$C$8*M6 -> 0 | M24: =N23+0.1 -> 1.251756e+08 | N24: y más | O24: 0 | AA24: Diciembre | AB24: 43198 | AC24: 518376
E25: =$C$8*J7 -> 918459 | F25: =$C$8*K7 -> 2041020 | G25: 0.04 | H25: =$C$8*M7 -> 36738.36 | J25: 47646524
E26: =$C$8*J8 -> 2041020 | F26: =$C$8*K8 -> 3401700 | G26: 0.08 | H26: =$C$8*M8 -> 118379.16
B27: =Hoja14!P14/Hoja15!C6 -> 8.0044058 | C27: =Hoja14!P14/Hoja14!F14 -> 14.061153 | E27: =$C$8*J9 -> 3401700 | F27: =$C$8*K9 -> 4762380 | G27: 0.135 | H27: =$C$8*M9 -> 305472.66 | N27: =VLOOKUP($Q$20,$M$22:$O$24,3) -> 0.71498734
B28: =Hoja14!P15/Hoja15!C7 -> 8.010255 | C28: =Hoja14!P15/Hoja14!F15 -> 13.947499 | E28: =$C$8*J10 -> 4762380 | F28: =$C$8*K10 -> 6123060 | G28: 0.23 | H28: =$C$8*M10 -> 757898.76
B29: =Hoja14!P16/Hoja15!C8 -> 117.5379 | C29: =Hoja14!P16/Hoja14!F16 -> 205.59857 | E29: =$C$8*J11 -> 6123060 | F29: =$C$8*K11 -> 8164080 | G29: 0.304 | H29: =$C$8*M11 -> 1211005.2
B30: =Hoja14!P17/Hoja15!C9 -> 7.6745032 | C30: =Hoja14!P17/Hoja14!F17 -> 13.41546 | E30: =$C$8*J12 -> 8164080 | F30: =$C$8*K12 -> 21090540 | G30: 0.35 | H30: =$C$8*M12 -> 1586552.9 | J30: =J25*G31-H31 -> 16417530
B31: =Hoja14!P18/Hoja15!C10 -> 7.5669597 | C31: =Hoja14!P18/Hoja14!F18 -> 13.255013 | E31: =$C$8*J13 -> 21090540 | F31: =$C$8*K13 -> 680340000 | G31: 0.4 | H31: =$C$8*M13 -> 2641079.9
B32: =Hoja14!P19/Hoja15!C11 -> 7.5203194 | C32: =Hoja14!P19/Hoja14!F19 -> 13.173511
B33: =Hoja14!P20/Hoja15!C12 -> 7.493579 | C33: =Hoja14!P20/Hoja14!F20 -> 13.182568 | E33: =$C$9*$J$6 -> 0 | F33: =$C$9*$K$6 -> 922131 | G33: 0 | H33: =$C$9*$M$6 -> 0
B34: =Hoja14!P21/Hoja15!C13 -> 7.5437837 | C34: =Hoja14!P21/Hoja14!F21 -> 13.149257 | E34: =$C$9*$J$7 -> 922131 | F34: =$C$9*$K$7 -> 2049180 | G34: 0.04 | H34: =$C$9*$M$7 -> 36885.24
B35: =Hoja14!P22/Hoja15!C14 -> 7.3647699 | C35: =Hoja14!P22/Hoja14!F22 -> 12.919144 | E35: =$C$9*$J$8 -> 2049180 | F35: =$C$9*$K$8 -> 3415300 | G35: 0.08 | H35: =$C$9*$M$8 -> 118852.44 | J35: =Hoja14!N17*Hoja15!G35-Hoja15!H35 -> 328153.98
B36: =Hoja14!P23/Hoja15!C15 -> 7.3647699 | C36: =Hoja14!P23/Hoja14!F23 -> 12.919144 | E36: =$C$9*$J$9 -> 3415300 | F36: =$C$9*$K$9 -> 4781420 | G36: 0.135 | H36: =$C$9*$M$9 -> 306693.94
B37: =Hoja14!P24/Hoja15!C16 -> 7.2776699 | C37: =Hoja14!P24/Hoja14!F24 -> 12.781149 | E37: =$C$9*$J$10 -> 4781420 | F37: =$C$9*$K$10 -> 6147540 | G37: 0.23 | H37: =$C$9*$M$10 -> 760928.84
B38: =Hoja14!P25/Hoja15!C17 -> 7.2721803 | C38: =Hoja14!P25/Hoja14!F25 -> 12.756715 | E38: =$C$9*$J$11 -> 6147540 | F38: =$C$9*$K$11 -> 8196720 | G38: 0.304 | H38: =$C$9*$M$11 -> 1215846.8
B39: =SUM(B27:B38) -> 200.6311 | C39: =SUM(C27:C38) -> 351.15919 | E39: =$C$9*$J$12 -> 8196720 | F39: =$C$9*$K$12 -> 21174860 | G39: 0.35 | H39: =$C$9*$M$12 -> 1592895.9
C40: =C39*Hoja14!F25 -> 13921211 | E40: =$C$9*$J$13 -> 21174860 | F40: =$C$9*$K$13 -> 683060000 | G40: 0.4 | H40: =$C$9*$M$13 -> 2651638.9
E42: =$C$10*$J$6 -> 0 | F42: =$C$10*$K$6 -> 926748 | G42: 0 | H42: =$C$10*$M$6 -> 0
E43: =$C$10*$J$7 -> 926748 | F43: =$C$10*$K$7 -> 2059440 | G43: 0.04 | H43: =$C$10*$M$7 -> 37069.92 | K43: =25629*8*50 -> 10251600
E44: =$C$10*$J$8 -> 2059440 | F44: =$C$10*$K$8 -> 3432400 | G44: 0.08 | H44: =$C$10*$M$8 -> 119447.52
E45: =$C$10*$J$9 -> 3432400 | F45: =$C$10*$K$9 -> 4805360 | G45: 0.135 | H45: =$C$10*$M$9 -> 308229.52
E46: =$C$10*$J$10 -> 4805360 | F46: =$C$10*$K$10 -> 6178320 | G46: 0.23 | H46: =$C$10*$M$10 -> 764738.72
...

Sheet Hoja9
L2: UTA | M2: =Hoja14!I240*12 -> 834504
B3: Renta tributable | C3: Pensión Tributable | D3: Impuetso sueldo | E3: Impuesto Pensión | F3: Honorarios | G3: Retenciones | H3: APV empleador | I3: APV directo | L3: UTA 15 | M3: =Hoja14!I240*12*15 -> 12517560
B4: =Hoja14!CM26 -> 88002957 | C4: =Hoja14!CN26 -> 0 | D4: =Hoja14!CO26 -> 13702706 | E4: =Hoja14!CP26 -> 0 | F4: =Hoja14!CQ26 -> 0 | G4: =Hoja14!CR26 -> 0 | H4: =Hoja14!CS26 -> 14106991 | I4: =Hoja14!AM32 -> 0 | L4: UTA 8 | M4: =Hoja14!I240*12*8 -> 6676032
L6: Base UTA | M6: =C13/M2 -> 119.8352 | O6: Intereses | P6: =Hoja14!P5 -> 0
P7: =P6/M2 -> 0 | R7: 0 | S7: 90 | T7: 1
B8: Sueldo | C8: =B4+Hoja14!R30 -> 1.0000296e+08 | O8: Maximo | P8: =MIN(P7*T12,8)*M2 -> 0 | R8: 90.0001 | S8: 150 | T8: =(250-1.667*M6)/100 -> 0.50234715
B9: Pensión | C9: =C4 -> 0 | L9: Gastos | M9: =MIN(30%*Hoja14!CQ26,Hoja9!M3) -> 0 | R9: 150.0001 | S9: y más | T9: 0
B10: Honorarios | C10: =F4 -> 0 | G10: Retención | H10: =H15*15% -> 1500000
B11: Gastos presuntos | C11: =MIN(C10*30%,M3) -> 0
B12: APV directo | C12: =I4+Hoja14!J34 -> 0 | T12: =VLOOKUP(M6,R7:T9,3) -> 0.50234715
B13: Subtotal | C13: =C8+C9+C10-C11-C12 -> 1.0000296e+08 | G13: 57 bis | H13: =Hoja14!R7 -> 0
B14: Intereses | C14: =Q15 -> 0 | Q14: =MIN(M4,Hoja14!P5) -> 0 | R14: =IF(M6<=90,100%,IF(M6>150,0%,T8)) -> 0.50234715
B15: Base Global | C15: =C13-C14 -> 1.0000296e+08 | G15: Retiro | H15: =Hoja14!P4 -> 10000000 | Q15: =Q14*R14 -> 0
B16: Impuesto Global | C16: =C15*VLOOKUP(C15,Hoja15!$J$105:$M$112,3)-VLOOKUP(C15,Hoja15!$J$105:$M$112,4) -> 15546728 | G16: B+R | H16: =C15+H15 -> 1.1000296e+08
B17: Crédito IUSC | C17: =D4+E4 -> 13702706 | D17: =C16-C17 -> 1844021.2 | G17: IGC B+R | H17: =H16*VLOOKUP(H16,Hoja15!$J$105:$M$112,3)-VLOOKUP(H16,Hoja15!$J$105:$M$112,4) -> 19040402
B18: Retenciones | C18: =G4 -> 0 | G18: Pensionado | H18: =IFERROR((H17-C16)/H15,0) -> 0.34936739 | I18: =H18*H15 -> 3493673.9
B19: Resultado | C19: =C16-C17-C18 -> 1844021.2 | G19: No pensionado | H19: =(H18*1.1)+3% -> 0.41430413 | I19: =H19*H15 -> 4143041.3
B20: 55 bis | C20: =H13 -> 0 | I20: =IF(Hoja14!P3="no pensionado",Hoja9!I19,Hoja9!I18) -> 3493673.9
B21: Retiro APV | C21: =I20 -> 3493673.9 | I21: =IFERROR(I20/H15," ") -> 0.34936739
B22: Retención | C22: =-H10 -> -1500000
B23: Final | C23: =C19+C20+C21+C22 -> 3837695.2
E26: =Hoja14!P26+Hoja14!T26 -> 13702706
E27: =C16-E26 -> 1844021.2

Sheet Hoja1
C5: Enero | D5: =Hoja15!C6 -> 67429 | F5: =Hoja14!N14/D5*$D$16 -> 5788435.9 | G5: =Hoja14!P14/Hoja1!D5*Hoja1!$D$16 -> 556642.39 | I5: =Hoja2!K13/D5*$D$16 -> 8412468.3 | J5: =Hoja2!M13/Hoja1!D5*Hoja1!$D$16 -> 1322644.5 | N5: =Hoja14!R14/D5*$D$16 -> 0 | O5: =Hoja14!T14/Hoja1!D5*Hoja1!$D$16 -> 0
C6: Febrero | D6: =Hoja15!C7 -> 67294 | F6: =Hoja14!N15/D6*$D$16 -> 5790204.5 | G6: =Hoja14!P15/Hoja1!D6*Hoja1!$D$16 -> 557049.15 | I6: =Hoja2!K14/D6*$D$16 -> 8425136.5 | J6: =Hoja2!M14/Hoja1!D6*Hoja1!$D$16 -> 1327078.3 | N6: =Hoja14!R15/D6*$D$16 -> 0 | O6: =Hoja14!T15/Hoja1!D6*Hoja1!$D$16 -> 0
C7: Marzo | D7: =Hoja15!C8 -> 68034 | F7: =Hoja14!N16/D7*$D$16 -> 27183603 | G7: =Hoja14!P16/Hoja1!D7*Hoja1!$D$16 -> 8173820.7 | I7: =Hoja2!K15/D7*$D$16 -> 8329608.7 | J7: =Hoja2!M15/Hoja1!D7*Hoja1!$D$16 -> 1294353.4 | N7: =Hoja14!R16/D7*$D$16 -> 0 | O7: =Hoja14!T16/Hoja1!D7*Hoja1!$D$16 -> 0
C8: Abril | D8: =Hoja15!C9 -> 68306 | F8: =Hoja14!N17/D8*$D$16 -> 5688687.7 | G8: =Hoja14!P17/Hoja1!D8*Hoja1!$D$16 -> 533700.3 | I8: =Hoja2!K16/D8*$D$16 -> 8293587.3 | J8: =Hoja2!M16/Hoja1!D8*Hoja1!$D$16 -> 1283402.9 | N8: =Hoja14!R17/D8*$D$16 -> 0 | O8: =Hoja14!T17/Hoja1!D8*Hoja1!$D$16 -> 0
C9: Mayo | D9: =Hoja15!C10 -> 68648 | F9: =Hoja14!N18/D9*$D$16 -> 5656171.3 | G9: =Hoja14!P18/Hoja1!D9*Hoja1!$D$16 -> 526221.51 | I9: =Hoja2!K17/D9*$D$16 -> 8250484 | J9: =Hoja2!M17/Hoja1!D9*Hoja1!$D$16 -> 1270299.5 | N9: =Hoja14!R18/D9*$D$16 -> 0 | O9: =Hoja14!T18/Hoja1!D9*Hoja1!$D$16 -> 0
C10: Junio | D10: =Hoja15!C11 -> 68785 | F10: =Hoja14!N19/D10*$D$16 -> 5642069.3 | G10: =Hoja14!P19/Hoja1!D10*Hoja1!$D$16 -> 522978.05 | I10: =Hoja2!K18/D10*$D$16 -> 8232838.7 | J10: =Hoja2!M18/Hoja1!D10*Hoja1!$D$16 -> 1264935.4 | N10: =Hoja14!R19/D10*$D$16 -> 0 | O10: =Hoja14!T19/Hoja1!D10*Hoja1!$D$16 -> 0
C11: Julio | D11: =Hoja15!C12 -> 68923 | F11: =Hoja14!N20/D11*$D$16 -> 5633984.1 | G11: =Hoja14!P20/Hoja1!D11*Hoja1!$D$16 -> 521118.47 | I11: =Hoja2!K19/D11*$D$16 -> 8217727.6 | J11: =Hoja2!M19/Hoja1!D11*Hoja1!$D$16 -> 1260341.6 | N11: =Hoja14!R20/D11*$D$16 -> 0 | O11: =Hoja14!T20/Hoja1!D11*Hoja1!$D$16 -> 0
C12: Agosto | D12: =Hoja15!C13 -> 68647 | F12: =Hoja14!N21/D12*$D$16 -> 5649163.8 | G12: =Hoja14!P21/Hoja1!D12*Hoja1!$D$16 -> 524609.8 | I12: =Hoja2!K20/D12*$D$16 -> 8247573.2 | J12: =Hoja2!M20/Hoja1!D12*Hoja1!$D$16 -> 1269414.7 | N12: =Hoja14!R21/D12*$D$16 -> 0 | O12: =Hoja14!T21/Hoja1!D12*Hoja1!$D$16 -> 0
C13: Septiembre | D13: =Hoja15!C14 -> 69265 | F13: =Hoja14!N22/D13*$D$16 -> 5595037.9 | G13: =Hoja14!P22/Hoja1!D13*Hoja1!$D$16 -> 512160.83 | I13: =Hoja2!K21/D13*$D$16 -> 8172394.8 | J13: =Hoja2!M21/Hoja1!D13*Hoja1!$D$16 -> 1246560.4 | N13: =Hoja14!R22/D13*$D$16 -> 0 | O13: =Hoja14!T22/Hoja1!D13*Hoja1!$D$16 -> 0
C14: Octubre | D14: =Hoja15!C15 -> 69265 | F14: =Hoja14!N23/D14*$D$16 -> 5595037.9 | G14: =Hoja14!P23/Hoja1!D14*Hoja1!$D$16 -> 512160.83 | I14: =Hoja2!K22/D14*$D$16 -> 8172394.8 | J14: =Hoja2!M22/Hoja1!D14*Hoja1!$D$16 -> 1246560.4 | N14: =Hoja14!R23/D14*$D$16 -> 0 | O14: =Hoja14!T23/Hoja1!D14*Hoja1!$D$16 -> 0
C15: Noviembre | D15: =Hoja15!C16 -> 69542 | F15: =Hoja14!N24/D15*$D$16 -> 5568702.6 | G15: =Hoja14!P24/Hoja1!D15*Hoja1!$D$16 -> 506103.72 | I15: =Hoja2!K23/D15*$D$16 -> 8138111.5 | J15: =Hoja2!M23/Hoja1!D15*Hoja1!$D$16 -> 1236138.3 | N15: =Hoja14!R24/D15*$D$16 -> 0 | O15: =Hoja14!T24/Hoja1!D15*Hoja1!$D$16 -> 0
C16: Diciembre | D16: =Hoja15!C17 -> 69542 | F16: =Hoja14!N25/D16*$D$16 -> 5567042.8 | G16: =Hoja14!P25/Hoja1!D16*Hoja1!$D$16 -> 505721.96 | I16: =Hoja2!K24/D16*$D$16 -> 8137401.9 | J16: =Hoja2!M24/Hoja1!D16*Hoja1!$D$16 -> 1235922.6 | N16: =Hoja14!R25/D16*$D$16 -> 0 | O16: =Hoja14!T25/Hoja1!D16*Hoja1!$D$16 -> 0
F17: =SUM(F5:F16) -> 89358141 | G17: =SUM(G5:G16) -> 13952288 | I17: =SUM(I5:I16) -> 99029727 | J17: =SUM(J5:J16) -> 15257652 | L17: =G17-J17 -> -1305364.3 | N17: =SUM(N5:N16) -> 0 | O17: =SUM(O5:O16) -> 0
F18: =F23 -> 12310704 | I18: =I23 -> 15250866 | N18: =N23 -> 0
F20: =VLOOKUP(F17,Hoja15!$J$105:$M$112,3) -> 0.304 | I20: =VLOOKUP(I17,Hoja15!$J$105:$M$112,3) -> 0.304 | N20: =VLOOKUP(N17,Hoja15!$J$105:$M$112,3) -> 0
F21: =VLOOKUP(F17,Hoja15!$J$105:$M$112,4) -> 14854171 | I21: =VLOOKUP(I17,Hoja15!$J$105:$M$112,4) -> 14854171 | N21: =VLOOKUP(N17,Hoja15!$J$105:$M$112,4) -> 0
F23: =F17*F20-F21 -> 12310704 | I23: =I17*I20-I21 -> 15250866 | N23: =N17*N20-N21 -> 0
G26: =G17-F18 -> 1641584.1

Sheet imp cte
B6: Enero | C6: =Hoja15!C6 -> 67429 | E6: =$C$6*J6 -> 0 | F6: =$C$6*$K$6 -> 910291.5 | G6: =Hoja15!G6 -> 0 | H6: =$C$6*$M$6 -> 0 | J6: 0 | K6: 13.5 | L6: =Hoja15!L6 -> 0 | M6: =Hoja15!M6 -> 0
B7: Febrero | C7: =Hoja15!C7 -> 67294 | E7: =$C$6*$J$7 -> 910291.5 | F7: =$C$6*$K$7 -> 2022870 | G7: =Hoja15!G7 -> 0.04 | H7: =$C$6*$M$7 -> 36411.66 | J7: 13.5 | K7: 30 | L7: =Hoja15!L7 -> 0.04 | M7: =Hoja15!M7 -> 0.54 | O7: 36679
B8: Marzo | C8: =Hoja15!C8 -> 68034 | E8: =$C$6*$J$8 -> 2022870 | F8: =$C$6*$K$8 -> 3371450 | G8: =Hoja15!G8 -> 0.08 | H8: =$C$6*$M$8 -> 117326.46 | J8: 30 | K8: 50 | L8: =Hoja15!L8 -> 0.08 | M8: =Hoja15!M8 -> 1.74 | O8: 36569
B9: Abril | C9: =Hoja15!C9 -> 68306 | E9: =$C$6*$J$9 -> 3371450 | F9: =$C$6*$K$9 -> 4720030 | G9: =Hoja15!G9 -> 0.135 | H9: =$C$6*$M$9 -> 302756.21 | J9: 50 | K9: 70 | L9: =Hoja15!L9 -> 0.135 | M9: =Hoja15!M9 -> 4.49 | O9: 36752
B10: Mayo | C10: =Hoja15!C10 -> 68648 | E10: =$C$6*$J$10 -> 4720030 | F10: =$C$6*$K$10 -> 6068610 | G10: =Hoja15!G10 -> 0.23 | H10: =$C$6*$M$10 -> 751159.06 | J10: 70 | K10: 90 | L10: =Hoja15!L10 -> 0.23 | M10: =Hoja15!M10 -> 11.14 | O10: 36862
B11: Junio | C11: =Hoja15!C11 -> 68785 | E11: =$C$6*$J$11 -> 6068610 | F11: =$C$6*$K$11 -> 8091480 | G11: =Hoja15!G11 -> 0.304 | H11: =$C$6*$M$11 -> 1200236.2 | J11: 90 | K11: 120 | L11: =Hoja15!L11 -> 0.304 | M11: =Hoja15!M11 -> 17.8 | O11: 36899
B12: Julio | C12: =Hoja15!C12 -> 68923 | E12: =$C$6*$J$12 -> 8091480 | F12: =$C$6*$K$12 -> 10114350 | G12: =Hoja15!G12 -> 0.35 | H12: =$C$6*$M$12 -> 1572444.3 | J12: 120 | K12: 150 | L12: =Hoja15!L12 -> 0.35 | M12: =Hoja15!M12 -> 23.32 | O12: 37083
B13: Agosto | C13: =Hoja15!C13 -> 68647 | E13: =$C$6*$J$13 -> 10114350 | F13: y más | G13: =Hoja15!G13 -> 0.4 | H13: =$C$6*$M$13 -> 2617593.8 | J13: 150 | K13: y más | L13: =Hoja15!L13 -> 0.4 | M13: =Hoja15!M13 -> 38.82 | O13: 37231
B14: Septiembre | C14: =Hoja15!C14 -> 69265 | G14: =Hoja15!G14 -> 0 | O14: 37231
B15: Octubre | C15: =Hoja15!C15 -> 69265 | E15: =$C$7*J6 -> 0 | F15: =$C$7*K6 -> 908469 | G15: =Hoja15!G15 -> 0 | H15: =$C$7*M6 -> 0 | O15: 37231
B16: Noviembre | C16: =Hoja15!C16 -> 69542 | E16: =$C$7*J7 -> 908469 | F16: =$C$7*K7 -> 2018820 | G16: =Hoja15!G16 -> 0.04 | H16: =$C$7*M7 -> 36338.76 | O16: 37231
B17: Diciembre | C17: =Hoja15!C17 -> 69542 | E17: =$C$7*J8 -> 2018820 | F17: =$C$7*K8 -> 3364700 | G17: =Hoja15!G17 -> 0.08 | H17: =$C$7*M8 -> 117091.56 | J17: =Hoja14!N15*Hoja15!G17-Hoja15!H17 -> 331150.96 | O17: 37231
E18: =$C$7*J9 -> 3364700 | F18: =$C$7*K9 -> 4710580 | G18: =Hoja15!G18 -> 0.135 | H18: =$C$7*M9 -> 302150.06 | O18: 37231
E19: =$C$7*J10 -> 4710580 | F19: =$C$7*K10 -> 6056460 | G19: =Hoja15!G19 -> 0.23 | H19: =$C$7*M10 -> 749655.16
C20: =(C17-C6)/C6 -> 0.031336665 | E20: =$C$7*J11 -> 6056460 | F20: =$C$7*K11 -> 8075280 | G20: =Hoja15!G20 -> 0.304 | H20: =$C$7*M11 -> 1197833.2 | Q20: =Hoja14!J138+Hoja14!J140-Hoja14!J272-Hoja14!J34 -> 89358141
E21: =$C$7*J12 -> 8075280 | F21: =$C$7*K12 -> 10094100 | G21: =Hoja15!G21 -> 0.35 | H21: =$C$7*M12 -> 1569296.1
E22: =$C$7*J13 -> 10094100 | F22: y más | G22: =Hoja15!G22 -> 0.4 | H22: =$C$7*M13 -> 2612353.1 | M22: 0 | N22: =90*B23 -> 75105360 | O22: 1 | Q22: =Q20/B23 -> 107.07934
B23: =C17*12 -> 834504 | G23: =Hoja15!G23 -> 0 | M23: =N22+0.1 -> 75105360 | N23: =150*B23 -> 125175600 | O23: =Q23 -> 0.71498734 | Q23: =(250-Q22*1.667)/100 -> 0.71498734
E24: =$C$8*J6 -> 0 | F24: =$C$8*K6 -> 918459 | G24: =Hoja15!G24 -> 0 | H24: =$C$8*M6 -> 0 | M24: =N23+0.1 -> 1.251756e+08 | N24: y más | O24: 0
E25: =$C$8*J7 -> 918459 | F25: =$C$8*K7 -> 2041020 | G25: =Hoja15!G25 -> 0.04 | H25: =$C$8*M7 -> 36738.36
E26: =$C$8*J8 -> 2041020 | F26: =$C$8*K8 -> 3401700 | G26: =Hoja15!G26 -> 0.08 | H26: =$C$8*M8 -> 118379.16
B27: =Hoja14!P14/Hoja15!C6 -> 8.0044058 | C27: =Hoja14!P14/Hoja14!F14 -> 14.061153 | E27: =$C$8*J9 -> 3401700 | F27: =$C$8*K9 -> 4762380 | G27: =Hoja15!G27 -> 0.135 | H27: =$C$8*M9 -> 305472.66 | N27: =VLOOKUP($Q$20,$M$22:$O$24,3) -> 0.71498734
B28: =Hoja14!P15/Hoja15!C7 -> 8.010255 | C28: =Hoja14!P15/Hoja14!F15 -> 13.947499 | E28: =$C$8*J10 -> 4762380 | F28: =$C$8*K10 -> 6123060 | G28: =Hoja15!G28 -> 0.23 | H28: =$C$8*M10 -> 757898.76
B29: =Hoja14!P16/Hoja15!C8 -> 117.5379 | C29: =Hoja14!P16/Hoja14!F16 -> 205.59857 | E29: =$C$8*J11 -> 6123060 | F29: =$C$8*K11 -> 8164080 | G29: =Hoja15!G29 -> 0.304 | H29: =$C$8*M11 -> 1211005.2
B30: =Hoja14!P17/Hoja15!C9 -> 7.6745032 | C30: =Hoja14!P17/Hoja14!F17 -> 13.41546 | E30: =$C$8*J12 -> 8164080 | F30: =$C$8*K12 -> 10205100 | G30: =Hoja15!G30 -> 0.35 | H30: =$C$8*M12 -> 1586552.9
B31: =Hoja14!P18/Hoja15!C10 -> 7.5669597 | C31: =Hoja14!P18/Hoja14!F18 -> 13.255013 | E31: =$C$8*J13 -> 10205100 | F31: y más | G31: =Hoja15!G31 -> 0.4 | H31: =$C$8*M13 -> 2641079.9
B32: =Hoja14!P19/Hoja15!C11 -> 7.5203194 | C32: =Hoja14!P19/Hoja14!F19 -> 13.173511 | G32: =Hoja15!G32 -> 0
B33: =Hoja14!P20/Hoja15!C12 -> 7.493579 | C33: =Hoja14!P20/Hoja14!F20 -> 13.182568 | E33: =$C$9*$J$6 -> 0 | F33: =$C$9*$K$6 -> 922131 | G33: =Hoja15!G33 -> 0 | H33: =$C$9*$M$6 -> 0
B34: =Hoja14!P21/Hoja15!C13 -> 7.5437837 | C34: =Hoja14!P21/Hoja14!F21 -> 13.149257 | E34: =$C$9*$J$7 -> 922131 | F34: =$C$9*$K$7 -> 2049180 | G34: =Hoja15!G34 -> 0.04 | H34: =$C$9*$M$7 -> 36885.24
B35: =Hoja14!P22/Hoja15!C14 -> 7.3647699 | C35: =Hoja14!P22/Hoja14!F22 -> 12.919144 | E35: =$C$9*$J$8 -> 2049180 | F35: =$C$9*$K$8 -> 3415300 | G35: =Hoja15!G35 -> 0.08 | H35: =$C$9*$M$8 -> 118852.44 | J35: =Hoja14!N17*Hoja15!G35-Hoja15!H35 -> 328153.98
B36: =Hoja14!P23/Hoja15!C15 -> 7.3647699 | C36: =Hoja14!P23/Hoja14!F23 -> 12.919144 | E36: =$C$9*$J$9 -> 3415300 | F36: =$C$9*$K$9 -> 4781420 | G36: =Hoja15!G36 -> 0.135 | H36: =$C$9*$M$9 -> 306693.94 | L36: =B6 -> Enero | M36: =Hoja14!N14 -> 5612557.1 | N36: =(M36*VLOOKUP(M36,$E$6:$H$13,3))-(VLOOKUP(M36,$E$6:$H$13,4)) -> 539729.08
B37: =Hoja14!P24/Hoja15!C16 -> 7.2776699 | C37: =Hoja14!P24/Hoja14!F24 -> 12.781149 | E37: =$C$9*$J$10 -> 4781420 | F37: =$C$9*$K$10 -> 6147540 | G37: =Hoja15!G37 -> 0.23 | H37: =$C$9*$M$10 -> 760928.84 | L37: =B7 -> Febrero | M37: =Hoja14!N15 -> 5603031.6 | N37: =(M37*VLOOKUP(M37,$E$6:$H$13,3))-(VLOOKUP(M37,$E$6:$H$13,4)) -> 537538.2
B38: =Hoja14!P25/Hoja15!C17 -> 7.2721803 | C38: =Hoja14!P25/Hoja14!F25 -> 12.756715 | E38: =$C$9*$J$11 -> 6147540 | F38: =$C$9*$K$11 -> 8196720 | G38: =Hoja15!G38 -> 0.304 | H38: =$C$9*$M$11 -> 1215846.8 | L38: =B8 -> Marzo | M38: =Hoja14!N16 -> 26594133 | N38: =(M38*VLOOKUP(M38,$E$6:$H$13,3))-(VLOOKUP(M38,$E$6:$H$13,4)) -> 8020059.6
B39: =SUM(B27:B38) -> 200.6311 | C39: =SUM(C27:C38) -> 351.15919 | E39: =$C$9*$J$12 -> 8196720 | F39: =$C$9*$K$12 -> 10245900 | G39: =Hoja15!G39 -> 0.35 | H39: =$C$9*$M$12 -> 1592895.9 | L39: =B9 -> Abril | M39: =Hoja14!N17 -> 5587580.2 | N39: =(M39*VLOOKUP(M39,$E$6:$H$13,3))-(VLOOKUP(M39,$E$6:$H$13,4)) -> 533984.39
C40: =C39*Hoja14!F25 -> 13921211 | E40: =$C$9*$J$13 -> 10245900 | F40: y más | G40: =Hoja15!G40 -> 0.4 | H40: =$C$9*$M$13 -> 2651638.9 | L40: =B10 -> Mayo | M40: =Hoja14!N18 -> 5583458.1 | N40: =(M40*VLOOKUP(M40,$E$6:$H$13,3))-(VLOOKUP(M40,$E$6:$H$13,4)) -> 533036.31
G41: =Hoja15!G41 -> 0 | L41: =B11 -> Junio | M41: =Hoja14!N19 -> 5580652.5 | N41: =(M41*VLOOKUP(M41,$E$6:$H$13,3))-(VLOOKUP(M41,$E$6:$H$13,4)) -> 532391.01
E42: =$C$10*$J$6 -> 0 | F42: =$C$10*$K$6 -> 926748 | G42: =Hoja15!G42 -> 0 | H42: =$C$10*$M$6 -> 0 | L42: =B12 -> Julio | M42: =Hoja14!N20 -> 5583835.5 | N42: =(M42*VLOOKUP(M42,$E$6:$H$13,3))-(VLOOKUP(M42,$E$6:$H$13,4)) -> 533123.11
E43: =$C$10*$J$7 -> 926748 | F43: =$C$10*$K$7 -> 2059440 | G43: =Hoja15!G43 -> 0.04 | H43: =$C$10*$M$7 -> 37069.92 | L43: =B13 -> Agosto | M43: =Hoja14!N21 -> 5576459.6 | N43: =(M43*VLOOKUP(M43,$E$6:$H$13,3))-(VLOOKUP(M43,$E$6:$H$13,4)) -> 531426.64
E44: =$C$10*$J$8 -> 2059440 | F44: =$C$10*$K$8 -> 3432400 | G44: =Hoja15!G44 -> 0.08 | H44: =$C$10*$M$8 -> 119447.52 | L44: =B14 -> Septiembre | M44: =Hoja14!N22 -> 5572751.7 | N44: =(M44*VLOOKUP(M44,$E$6:$H$13,3))-(VLOOKUP(M44,$E$6:$H$13,4)) -> 530573.83
E45: =$C$10*$J$9 -> 3432400 | F45: =$C$10*$K$9 -> 4805360 | G45: =Hoja15!G45 -> 0.135 | H45: =$C$10*$M$9 -> 308229.52 | L45: =B15 -> Octubre | M45: =Hoja14!N23 -> 5572751.7 | N45: =(M45*VLOOKUP(M45,$E$6:$H$13,3))-(VLOOKUP(M45,$E$6:$H$13,4)) -> 530573.83
...

Sheet Hoja3
B2: Día | C2: Ene | D2: Feb | E2: Mar | F2: Abr | G2: May | H2: Jun | I2: Jul | J2: Ago | K2: Sep | L2: Oct | M2: Nov | N2: Dic
B3: 1 | C3: 22296.19 | D3: 22412.68 | E3: 22463.56 | F3: 22536.41 | G3: 22592.72 | H3: 22621.53 | I3: 22627.36 | J3: 22576.98 | K3: 22559.48 | L3: 22592.56 | M3: 22738.63
B4: 2 | C4: 22298.34 | D4: 22417.01 | E4: 22464.34 | F4: 22539.31 | G4: 22594.22 | H4: 22622.26 | I4: 22627.36 | J4: 22574.79 | K4: 22559.48 | L4: 22594.06 | M4: 22744.48
B5: 3 | C5: 22300.5 | D5: 22421.34 | E5: 22465.11 | F5: 22542.22 | G5: 22595.73 | H5: 22622.99 | I5: 22627.36 | J5: 22572.6 | K5: 22559.48 | L5: 22595.57 | M5: 22750.32
B6: 4 | C6: 22302.65 | D6: 22425.66 | E6: 22465.89 | F6: 22545.12 | G6: 22597.23 | H6: 22623.72 | I6: 22627.36 | J6: 22570.41 | K6: 22559.48 | L6: 22597.07 | M6: 22756.17
B7: 5 | C7: 22304.81 | D7: 22429.99 | E7: 22466.66 | F7: 22548.02 | G7: 22598.74 | H7: 22624.45 | I7: 22627.36 | J7: 22568.23 | K7: 22559.48 | L7: 22598.58 | M7: 22762.02
B8: 6 | C8: 22306.96 | D8: 22434.32 | E8: 22467.43 | F8: 22550.93 | G8: 22600.24 | H8: 22625.18 | I8: 22627.36 | J8: 22566.04 | K8: 22559.48 | L8: 22600.08 | M8: 22767.87
B9: 7 | C9: 22309.12 | D9: 22438.65 | E9: 22468.21 | F9: 22553.83 | G9: 22601.75 | H9: 22625.91 | I9: 22627.36 | J9: 22563.85 | K9: 22559.48 | L9: 22601.59 | M9: 22773.73
B10: 8 | C10: 22311.27 | D10: 22442.98 | E10: 22468.98 | F10: 22556.73 | G10: 22603.25 | H10: 22626.64 | I10: 22627.36 | J10: 22561.66 | K10: 22559.48 | L10: 22603.09 | M10: 22779.58 | P10: 22408.36
B11: 9 | C11: 22313.43 | D11: 22447.31 | E11: 22469.76 | F11: 22559.64 | G11: 22604.76 | H11: 22627.36 | I11: 22627.36 | J11: 22559.48 | K11: 22559.48 | L11: 22604.6 | M11: 22785.44 | P11: 22462.79
B12: 10 | C12: 22317.74 | D12: 22448.08 | E12: 22472.65 | F12: 22561.14 | G12: 22605.49 | H12: 22627.36 | I12: 22625.17 | J12: 22559.48 | K12: 22560.98 | L12: 22610.41 | M12: 22785.44 | P12: 22533.51
B13: 11 | C13: 22322.04 | D13: 22448.86 | E13: 22475.55 | F13: 22562.65 | G13: 22606.22 | H13: 22627.36 | I13: 22622.97 | J13: 22559.48 | K13: 22562.49 | L13: 22616.22 | M13: 22785.44 | P13: 22591.21
B14: 12 | C14: 22326.35 | D14: 22449.63 | E14: 22478.44 | F14: 22564.15 | G14: 22606.95 | H14: 22627.36 | I14: 22620.78 | J14: 22559.48 | K14: 22563.99 | L14: 22622.04 | M14: 22785.44 | P14: 22620.8
B15: 13 | C15: 22330.66 | D15: 22450.4 | E15: 22481.34 | F15: 22565.65 | G15: 22607.68 | H15: 22627.36 | I15: 22618.59 | J15: 22559.48 | K15: 22565.49 | L15: 22627.85 | M15: 22785.44 | P15: 22627.36
B16: 14 | C16: 22334.97 | D16: 22451.18 | E16: 22484.23 | F16: 22567.15 | G16: 22608.4 | H16: 22627.36 | I16: 22616.4 | J16: 22559.48 | K16: 22566.99 | L16: 22633.67 | M16: 22785.44 | P16: 22579.16
