Workbook

Sheet RESUMEN
B2: 2026 | C2: ENERO | D2: FEBRERO | E2: MARZO | F2: ABRIL | G2: MAYO | H2: JUNIO | I2: JULIO | J2: AGOSTO | K2: SEPTIEMBRE | L2: OCTUBRE | M2: NOVIEMBRE | N2: DICIEMBRE | O2: TOTAL
B3: RG | C3: 0 | D3: ='FEBRERO 26'!$E$23 -> 3965423270 | E3: ='MARZO 26'!$E$29 -> 1220948602 | F3: ='ABRIL 26'!$E$32 -> 1227000000 | O3: =SUM(C3:N3) -> 6413371872
B4: PREVISIONAL | C4: 0 | D4: ='FEBRERO 26'!$E$24 -> 0 | E4: ='MARZO 26'!$E$30 -> 986498517 | F4: ='ABRIL 26'!$E$33 -> 790000000 | O4: =SUM(C4:N4) -> 1776498517
B5: TOTAL | C5: =SUM(C3:C4) -> 0 | D5: =SUM(D3:D4) -> 3965423270 | E5: =SUM(E3:E4) -> 2207447119 | F5: =SUM(F3:F4) -> 2017000000 | G5: =SUM(G3:G4) -> 0 | H5: =SUM(H3:H4) -> 0 | I5: =SUM(I3:I4) -> 0 | J5: =SUM(J3:J4) -> 0 | ... O5: =SUM(O3:O4) -> 8189870389
A8: FACTURACIÓN | C8: ENERO | D8: FEBRERO | E8: MARZO | F8: ABRIL | G8: MAYO | H8: JUNIO | I8: JULIO | J8: AGOSTO | K8: SEPTIEMBRE | L8: OCTUBRE | M8: NOVIEMBRE | N8: DICIEMBRE | O8: TOTAL
A9: UP FRONT | B9: NETO | C9: 0 | D9: 26028588
B10: IVA | C10: =C9*0.19 -> 0 | D10: =D9*0.19 -> 4945431.7 | E10: =E9*0.19 -> 0 | F10: =F9*0.19 -> 0 | G10: =G9*0.19 -> 0 | H10: =H9*0.19 -> 0 | I10: =I9*0.19 -> 0 | J10: =J9*0.19 -> 0 | ... N10: =N9*0.19 -> 0
B11: BRUTO | C11: =SUM(C9:C10) -> 0 | D11: =SUM(D9:D10) -> 30974020 | E11: =SUM(E9:E10) -> 0 | F11: =SUM(F9:F10) -> 0 | G11: =SUM(G9:G10) -> 0 | H11: =SUM(H9:H10) -> 0 | I11: =SUM(I9:I10) -> 0 | J11: =SUM(J9:J10) -> 0 | ... O11: =SUM(O9:O10) -> 0
A12: TRAILER FEE | B12: NETO | C12: 0 | D12: 322687
B13: IVA | C13: =C12*0.19 -> 0 | D13: =D12*0.19 -> 61310.53 | E13: =E12*0.19 -> 0 | F13: =F12*0.19 -> 0 | G13: =G12*0.19 -> 0 | H13: =H12*0.19 -> 0 | I13: =I12*0.19 -> 0 | J13: =J12*0.19 -> 0 | ... N13: =N12*0.19 -> 0
B14: BRUTO | C14: =SUM(C12:C13) -> 0 | D14: =SUM(D12:D13) -> 383997.53 | E14: =SUM(E12:E13) -> 0 | F14: =SUM(F12:F13) -> 0 | G14: =SUM(G12:G13) -> 0 | H14: =SUM(H12:H13) -> 0 | I14: =SUM(I12:I13) -> 0 | J14: =SUM(J12:J13) -> 0 | ... O14: =SUM(O12:O13) -> 0
A17: TOTAL | B17: NETO | C17: =+C9+C12 -> 0 | D17: =+D9+D12 -> 26351275 | E17: =+E9+E12 -> 0 | F17: =+F9+F12 -> 0 | G17: =+G9+G12 -> 0 | H17: =+H9+H12 -> 0 | I17: =+I9+I12 -> 0 | J17: =+J9+J12 -> 0 | ... O17: =+O9+O12 -> 0
B18: IVA | C18: =+C10+C13 -> 0 | D18: =+D10+D13 -> 5006742.2 | E18: =+E10+E13 -> 0 | F18: =+F10+F13 -> 0 | G18: =+G10+G13 -> 0 | H18: =+H10+H13 -> 0 | I18: =+I10+I13 -> 0 | J18: =+J10+J13 -> 0 | ... O18: =+O10+O13 -> 0
B19: BRUTO | C19: =+C17+C18 -> 0 | D19: =+D17+D18 -> 31358017 | E19: =+E17+E18 -> 0 | F19: =+F17+F18 -> 0 | G19: =+G17+G18 -> 0 | H19: =+H17+H18 -> 0 | I19: =+I17+I18 -> 0 | J19: =+J17+J18 -> 0 | ... O19: =+O17+O18 -> 0

Sheet FEBRERO 26
A1: FEBRERO 2026 | L1: Mes | M1: Hasta | N1: % Trailer Retail | O1: % Trailer APV
A2: RUT | B2: NOMBRE | C2: RG | F2: PREVISIONAL | L2: 1 al 24 | M2: 2099 | N2: 0.25 | O2: 0.25
C3: FECHA | D3: FFMM | E3: UP FRONT | F3: FECHA | G3: FFMM | J3: UP FRONT | M3: 4999 | N3: 0.38 | O3: 0.38
E4: 0.0075 | G4: APV-B | H4: APV-A | I4: DC | J4: 0.0038 | M4: 19999 | N4: 40%* | O4: 40%*
A5: 9448035-3 | B5: Maria Soledad Palleres Ulloa | C5: 46071 | D5: 30000000 | E5: =D5*$E$4 -> 225000 | J5: =(G5+H5+I5)*$J$4 -> 0 | L5: 25 > | M5: 29999 | N5: 0.45 | O5: 0.45
A6: 8789145-3 | B6: Erick Alejandro Madrid Izquierdo | C6: 46071 | D6: 70000000 | E6: =D6*$E$4 -> 525000 | J6: =(G6+H6+I6)*$J$4 -> 0 | M6: 39999 | N6: 0.5 | O6: 0.45
A7: 9697981-9 | B7: Loreto Grossi Galeb | C7: 46070 | D7: 458689258 | E7: =D7*$E$4 -> 3440169.4 | J7: =(G7+H7+I7)*$J$4 -> 0 | M7: 40.000 > | N7: 0.55 | O7: 0.45
A8: 9697981-9 | B8: Loreto Grossi Galeb | C8: 46078 | D8: 70000000 | E8: =D8*$E$4 -> 525000 | J8: =(G8+H8+I8)*$J$4 -> 0
A9: 11400557-6 | B9: Claudia Patricia Enriquez Garcia | C9: 46058 | D9: 20000000 | E9: =D9*$E$4 -> 150000 | J9: =(G9+H9+I9)*$J$4 -> 0
A10: 19837527-6 | B10: Luis David Troncoso Enriquez | C10: 46058 | D10: 5000000 | E10: =D10*$E$4 -> 37500 | J10: =(G10+H10+I10)*$J$4 -> 0
A11: 76107236-6 | B11: Inversiones Canto Del Agua Ltda. | C11: 46070 | D11: 2301734012 | E11: =D11*$E$4 -> 17263005 | J11: =(G11+H11+I11)*$J$4 -> 0
A12: 14283516-9 | B12: Luis Javier Escobar Andrade | C12: 46070 | D12: 350000000 | E12: =D12*$E$4 -> 2625000 | J12: =(G12+H12+I12)*$J$4 -> 0
A13: 10123952-7 | B13: Eric Hugo Mancilla Reygadas | C13: 46076 | D13: 165000000 | E13: =D13*$E$4 -> 1237500 | J13: =(G13+H13+I13)*$J$4 -> 0
A14: 8904562-2 | B14: Maria Del Pilar Iduya Ortiz De Luzuriaga | C14: 46078 | D14: 192000000 | E14: =D14*$E$4 -> 1440000 | J14: =(G14+H14+I14)*$J$4 -> 0
A15: 8904562-2 | B15: Maria Del Pilar Iduya Ortiz De Luzuriaga | C15: 46079 | D15: 58000000 | E15: =D15*$E$4 -> 435000 | J15: =(G15+H15+I15)*$J$4 -> 0
A16: 8904562-2 | B16: Maria Del Pilar Iduya Ortiz De Luzuriaga | C16: 46080 | D16: 240000000 | E16: =D16*$E$4 -> 1800000 | J16: =(G16+H16+I16)*$J$4 -> 0
A17: 21515724-5 | B17: Nicolás Alejandro Troncoso Enriquez | C17: 46080 | D17: 5000000 | E17: =D17*$E$4 -> 37500 | J17: =(G17+H17+I17)*$J$4 -> 0
A18: TOTAL | D18: =SUM(D5:D17) -> 3965423270 | E18: =SUM(E5:E17) -> 29740675 | G18: =SUM(G5:I17) -> 0 | J18: =SUM(J5:J17) -> 0
D21: REGIMEN | E21: TOTAL AUM | F21: UP FRONT | G21: TRAILER FEE
G22: 0.012
D23: RG | E23: =$D$18 -> 3965423270 | F23: =$E$18 -> 29740675 | G23: =((E23*(($G$22/12)*0.38))) -> 1506860.8
D24: PREVISIONAL | E24: =$G$18 -> 0 | F24: =$J$18 -> 0 | G24: =((E24*(($G$22/12)*0.38))) -> 0
D25: TOTAL | E25: =+E23+E24 -> 3965423270 | F25: =+F23+F24 -> 29740675 | G25: =+G23+G24 -> 1506860.8
A28: CIERRE MES: | C28: $ | D28: CANT. CLIENTES
A29: REGIMEN GENERAL: | C29: =$E$23 -> 3965423270 | D29: 10
A30: REGIMEN PREVISIONAL: | C30: 0 | D30: 0
A31: SEGUROS (RG): | C31: 0 | D31: 0
A32: SEGUROS (PREVISIONAL): | C32: 0 | D32: 0
A33: NUEVOS CLIENTES: | C33: 0 | D33: 5
A34: ALLFUNDS: | C34: 0 | D34: 0
A35: STONEX | C35: 0 | D35: 0
A36: F.I. | C36: 0 | D36: 0
A37: TOTAL | C37: =SUM(C29:C36) -> 3965423270
A40: ACUMULADO TRIMESTRE: | C40: ENERO | D40: FEBRERO | E40: MARZO
A41: REGIMEN GENERAL: | C41: 0 | D41: =C29 -> 3965423270
A42: REGIMEN PREVISIONAL: | C42: 0 | D42: =C30 -> 0
A43: SEGUROS (RG): | C43: 0 | D43: =C31 -> 0
A44: SEGUROS (PREVISIONAL): | C44: 0 | D44: =C32 -> 0
A45: NUEVOS CLIENTES: | C45: 0 | D45: 10
A46: ALLFUNDS: | C46: 0 | D46: =C34 -> 0
...

Sheet MARZO 26
A1: MARZO 2026 | L1: Mes | M1: Hasta | N1: % Trailer Retail | O1: % Trailer APV
A2: RUT | B2: NOMBRE | C2: RG | F2: PREVISIONAL | L2: 1 al 24 | M2: 2099 | N2: 0.25 | O2: 0.25
C3: FECHA | D3: FFMM | E3: UP FRONT | F3: FECHA | G3: FFMM | J3: UP FRONT | M3: 4999 | N3: 0.38 | O3: 0.38
E4: 0.0075 | G4: APV-B | H4: APV-A | I4: DC | J4: 0.0038 | M4: 19999 | N4: 40%* | O4: 40%*
A5: 8904562-2 | B5: Maria Del Pilar Iduya Ortiz De Luzuriaga | C5: 46083 | D5: 70000000 | E5: =D5*$E$4 -> 525000 | J5: =(G5+H5+I5)*$J$4 -> 0 | L5: 25 > | M5: 29999 | N5: 0.45 | O5: 0.45
A6: 10675057-2 | B6: Mauricio Alejandro Aguilera Pasten | C6: 46086 | D6: 200000000 | E6: =D6*$E$4 -> 1500000 | M6: 39999 | N6: 0.5 | O6: 0.45
A7: 9632135-K | B7: Oscar Marcelo Begliomini Saintloup | C7: 46086 | D7: 1524946 | E7: =D7*$E$4 -> 11437.095 | M7: 40.000 > | N7: 0.55 | O7: 0.45
A8: 9632135-K | B8: Oscar Marcelo Begliomini Saintloup | C8: 46086 | D8: 1763117 | E8: =D8*$E$4 -> 13223.377
A9: 9632135-K | B9: Oscar Marcelo Begliomini Saintloup | C9: 46086 | D9: 1659079 | E9: =D9*$E$4 -> 12443.092
A10: 9632135-K | B10: Oscar Marcelo Begliomini Saintloup | C10: 46086 | D10: 20900000 | E10: =D10*$E$4 -> 156750
A11: 6298500-3 | B11: Nelson Orlando Moraga Benavides | C11: 46087 | D11: 115000000 | E11: =D11*$E$4 -> 862500 | F11: 46108 | G11: 318618396 | J11: =(G11+H11+I11)*$J$4 -> 1210749.9
A12: 76352809-K | B12: Asesorías Intraholding Anduril SPA | C12: 46091 | D12: 150000000 | E12: =D12*$E$4 -> 1125000
A13: 6560742-5 | B13: Carlos Alberto Bostelmann Muñoz | C13: 46091 | D13: 139000000 | E13: =D13*$E$4 -> 1042500
A14: 20107864-4 | B14: Bastián Andrés Troncoso Enriquez | C14: 46092 | D14: 5000000 | E14: =D14*$E$4 -> 37500
A15: 76451622-2 | B15: Xpertime Ingenieria Spa | C15: 46098 | D15: 45000000 | E15: =D15*$E$4 -> 337500
A16: 9632135-K | B16: Oscar Marcelo Begliomini Saintloup | C16: 46101 | D16: 1000000 | E16: =D16*$E$4 -> 7500
A17: 9632135-K | B17: Oscar Marcelo Begliomini Saintloup | C17: 46101 | D17: 101460 | E17: =D17*$E$4 -> 760.95
A18: 9697981-9 | B18: Loreto Grossi Galeb | F18: 46105 | G18: 76188746 | H18: 6467959 | J18: =(G18+H18+I18)*$J$4 -> 314095.48
A19: 8789145-3 | B19: Erick Alejandro Madrid Izquierdo | F19: 46108 | G19: 24286543 | I19: 51312536 | J19: =(G19+H19+I19)*$J$4 -> 287276.5
A20: 10123952-7 | B20: Eric Hugo Mancilla Reygadas | F20: 46108 | G20: 59136790 | I20: 23079926 | J20: =(G20+H20+I20)*$J$4 -> 312423.52
A21: 8350143-K | B21: Mauricio Enrique Méndez Mardones | C21: 46108 | D21: 400000000 | E21: =D21*$E$4 -> 3000000 | F21: 46099 | G21: 427407621 | J21: =(G21+H21+I21)*$J$4 -> 1624149
A22: 10675057-2 | B22: Mauricio Alejandro Aguilera Pasten | C22: 46108 | D22: 70000000 | E22: =D22*$E$4 -> 525000
A25: TOTAL | D25: =SUM(D5:D24) -> 1220948602 | E25: =SUM(E5:E24) -> 9157114.5 | G25: =SUM(G5:I24) -> 986498517 | J25: =SUM(J5:J24) -> 3748694.4
D27: REGIMEN | E27: TOTAL AUM | F27: UP FRONT | G27: TRAILER FEE | I27: SIN FORMULA | J27: TOTAL NETO
G28: 0.012
D29: RG | E29: =$D$25 -> 1220948602 | F29: =$E$25 -> 9157114.5 | G29: =((RESUMEN!$O$3*($G$28/12))*(N3)) -> 2437081.3 | I29: 1944221.3 | J29: =+F29+I29 -> 11101336
D30: PREVISIONAL | E30: =$G$25 -> 986498517 | F30: =$J$25 -> 3748694.4 | G30: =(RESUMEN!$O$4*('MARZO 26'!$G$28/12)*'MARZO 26'!$N$3) -> 675069.44 | I30: 394432.92 | J30: =+F30+I30 -> 4143127.3
D31: TOTAL | E31: =+E29+E30 -> 2207447119 | F31: =+F29+F30 -> 12905809 | G31: =+G29+G30 -> 3112150.7 | I31: 2338654.2 | J31: =SUM(J29:J30) -> 15244463
A34: CIERRE MES: | C34: $ | D34: CANT. CLIENTES
A35: REGIMEN GENERAL: | C35: =$D$25-D24 -> 1220948602 | D35: 8
A36: REGIMEN PREVISIONAL: | C36: =+G18+H18+G24 -> 82656705 | D36: 3
A37: SEGUROS (RG): | C37: =D24 -> 0 | D37: 1
A38: SEGUROS (PREVISIONAL): | C38: 0 | D38: 0
A39: NUEVOS CLIENTES: | D39: 5
A40: ALLFUNDS: | C40: 0 | D40: 0
A41: STONEX | C41: 0 | D41: 0
A42: F.I. | C42: 0 | D42: 0
A43: TOTAL | C43: =SUM(C35:C42) -> 1303605307
A46: ACUMULADO TRIMESTRE: | C46: ENERO | D46: FEBRERO | E46: MARZO | F46: T1 2026
A47: REGIMEN GENERAL: | C47: 0 | D47: ='FEBRERO 26'!$D41 -> 3965423270 | E47: =$C$35 -> 1220948602 | F47: =SUM(C47:E47) -> 5186371872
...

Sheet ABRIL 26
A1: ABRIL 2026 | L1: Mes | M1: Hasta | N1: % Trailer Retail | O1: % Trailer APV
A2: RUT | B2: NOMBRE | C2: RG | F2: PREVISIONAL | L2: 1 al 24 | M2: 2099 | N2: 0.25 | O2: 0.25
C3: FECHA | D3: FFMM | E3: UP FRONT | F3: FECHA | G3: FFMM | J3: UP FRONT | M3: 4999 | N3: 0.38 | O3: 0.38
E4: 0.0075 | G4: APV-B | H4: APV-A | I4: DC | J4: 0.0038 | M4: 19999 | N4: 40%* | O4: 40%*
A5: 8757376-1 | B5: Juan Carlos Lucero Larenas | E5: =D5*$E$4 -> 0 | G5: 295000000 | J5: =(G5+H5+I5)*$J$4 -> 1121000 | L5: 25 > | M5: 29999 | N5: 0.45 | O5: 0.45
A6: 10675057-2 | B6: Mauricio Alejandro Aguilera Pasten | E6: =D6*$E$4 -> 0 | G6: 40000000 | J6: =(G6+H6+I6)*$J$4 -> 152000 | M6: 39999 | N6: 0.5 | O6: 0.45
A7: 7330058-4 | B7: Marcelo Alejandro Martinez Proboste | E7: =D7*$E$4 -> 0 | G7: 295000000 | J7: =(G7+H7+I7)*$J$4 -> 1121000 | M7: 40.000 > | N7: 0.55 | O7: 0.45
A8: 7012917-5 | B8: Gonzalo Alberto Bremer Gomez | D8: =108000000+180000000 -> 288000000 | E8: =D8*$E$4 -> 2160000 | J8: =(G8+H8+I8)*$J$4 -> 0
A9: 7798092-K | B9: Luciana Patricia Martínez Fernández | D9: 140000000 | E9: =D9*$E$4 -> 1050000 | J9: =(G9+H9+I9)*$J$4 -> 0
A10: 77818160-6 | B10: Afg Servicios Spa | D10: 90000000 | E10: =D10*$E$4 -> 675000 | J10: =(G10+H10+I10)*$J$4 -> 0
A11: 76107236-6 | B11: Inversiones Canto Del Agua Ltda. | E11: =D11*$E$4 -> 0 | J11: =(G11+H11+I11)*$J$4 -> 0
A12: 8398104-0 | B12: Rosendo Antenor Tirado Arcos | D12: 125000000 | E12: =D12*$E$4 -> 937500 | G12: 160000000 | J12: =(G12+H12+I12)*$J$4 -> 608000
A13: 6111512-9 | B13: Lilian Del Carmen Urrutia Romero | D13: 175000000 | E13: =D13*$E$4 -> 1312500
A14: 76698211-5 | B14: Ceg Spa | D14: 200000000 | E14: =D14*$E$4 -> 1500000
A15: 11400557-6 | B15: Claudia Patricia Enriquez Garcia | D15: 95000000 | E15: =D15*$E$4 -> 712500
A16: 21515724-5 | B16: Nicolás Alejandro Troncoso Enriquez | D16: 38000000 | E16: =D16*$E$4 -> 285000
A17: 19837527-6 | B17: Luis David Troncoso Enriquez | D17: 38000000 | E17: =D17*$E$4 -> 285000
A18: 20107864-4 | B18: Bastián Andrés Troncoso Enriquez | D18: 38000000 | E18: =D18*$E$4 -> 285000
A19: 76717295-8 | B19: INVERSIONES PILIDUX SPA | E19: =D19*$E$4 -> 0 | J19: =(G19+H19+I19)*$J$4 -> 0
A20: 7299521-K | B20: Alfredo Antonio Fuentes Hernández
A21: 6430735-5 | B21: Marco Antonio Campomanes Monserrat
A22: 10034620-6 | B22: Paola Riveri López
A28: TOTAL | D28: =SUM(D5:D27) -> 1227000000 | E28: =SUM(E5:E27) -> 9202500 | G28: =SUM(G5:I27) -> 790000000 | J28: =SUM(J5:J27) -> 3002000
D30: REGIMEN | E30: TOTAL AUM | F30: UP FRONT | G30: TRAILER FEE | I30: SIN FORMULA | J30: TOTAL NETO
G31: 0.012
D32: RG | E32: =$D$28 -> 1227000000 | F32: =$E$28 -> 9202500 | G32: =((RESUMEN!$O$3*($G$31/12))*($N$3)) -> 2437081.3 | I32: 1944221.3 | J32: =+F32+I32 -> 11146721
D33: PREVISIONAL | E33: =$G$28 -> 790000000 | F33: =$J$28 -> 3002000 | G33: =(RESUMEN!$O$4*($G$31/12)*$N$3) -> 675069.44 | I33: 394432.92 | J33: =+F33+I33 -> 3396432.9
D34: TOTAL | E34: =+E32+E33 -> 2017000000 | F34: =+F32+F33 -> 12204500 | G34: =+G32+G33 -> 3112150.7 | I34: 2338654.2 | J34: =SUM(J32:J33) -> 14543154
A37: CIERRE MES: | C37: $ | D37: CANT. CLIENTES
A38: REGIMEN GENERAL: | C38: =+#REF! -> #REF! | D38: 1 | J38: =J34*0.19 -> 2763199.3
A39: REGIMEN PREVISIONAL: | C39: =+G5+I5+#REF!+#REF!+#REF! -> #REF! | D39: 3
A40: SEGUROS (RG): | C40: =#REF! -> #REF! | D40: 0
A41: SEGUROS (PREVISIONAL): | C41: 0 | D41: 0
A42: NUEVOS CLIENTES: | D42: 4
A43: ALLFUNDS: | C43: 0 | D43: 0
A44: STONEX | C44: 0 | D44: 0
A45: F.I. | C45: 0 | D45: 0
A46: TOTAL | C46: =SUM(C38:C45) -> #REF!
A49: ACUMULADO TRIMESTRE: | C49: ENERO | D49: FEBRERO | E49: MARZO | F49: T1 2026
A50: REGIMEN GENERAL: | C50: 0 | D50: ='FEBRERO 26'!$D41 -> 3965423270 | E50: =$C$38 -> #REF! | F50: =SUM(C50:E50) -> #REF!
...

Sheet Hoja2
B1: 76107236-6 | C1: INVERSIONES CANTO DEL AGUA LTDA | E1: adcmineria@gmail.com | F1: 2295795869 | G1: FM | H1: Perfil Muy Arriesgado | I1: #VALUE! | K1: 27/03/2026, 05:18
B2: 9697981-9 | C2: LORETO VIVIANA GROSSI | E2: loretogrossi@gmail.com | F2: 599501603 | G2: APV, FM, ULAPV, ULIP | H2: Perfil Balanceado | I2: #VALUE! | J2: High Affluent | K2: 27/03/2026, 05:17
B3: 8904562-2 | C3: MARIA DEL PILAR IDUYA | E3: pilar.iduya@gmail.com | F3: 552771251 | G3: FM | H3: Perfil Arriesgado | I3: #VALUE! | J3: Vacío | K3: 27/03/2026, 05:23
B4: 6298500-3 | C4: NELSON ORLANDO MORAGA | E4: nmoraga@userena.cl | F4: 432506499 | G4: APV, FM | H4: Perfil Arriesgado | I4: #VALUE! | J4: Sin Segmento | K4: 27/03/2026, 09:13
B5: 8350143-k | C5: MAURICIO ENRIQUE MENDEZ | E5: mauricio.mendez.m@gmail.com | F5: 424773180 | G5: APV, FM, ULIP | H5: Perfil Arriesgado | I5: #VALUE! | J5: Mass Affluent | K5: 27/03/2026, 05:22
F6: 400000000
B7: 14283516-9 | C7: LUIS JAVIER ESCOBAR | E7: javiere712@gmail.com | F7: 349631333 | G7: FM | H7: Perfil Arriesgado | I7: #VALUE! | J7: Affluent | K7: 27/03/2026, 05:21
B8: 10123952-7 | C8: ERIC MANCILLA | E8: emancilla.r@gmail.com | F8: 246296571 | G8: CCV, CAV, FM, APV | H8: Perfil Muy Arriesgado | I8: #VALUE! | J8: Affluent | K8: 27/03/2026, 09:22
B9: 10675057-2 | C9: MAURICIO ALEJANDRO AGUILERA | E9: mauricio0069@gmail.com | F9: 195665713 | G9: FM | H9: Perfil Arriesgado | I9: #VALUE! | J9: Sin Segmento | K9: 27/03/2026, 05:25
B10: 76352809-K | C10: ASESORÍAS INTRAHOLDING ANDURIL SPA | E10: alejandro.molina@luval.cl | F10: 149439086 | G10: FM | H10: Perfil Muy Arriesgado | I10: #VALUE! | K10: 27/03/2026, 05:19
B11: 8789145-3 | C11: ERICK ALEJANDRO MADRID | E11: erickalejandromi@gmail.com | F11: 144525013 | G11: CCV, CAV, FM, APV | H11: Perfil Arriesgado | I11: #VALUE! | J11: Emerging Affluent | K11: 27/03/2026, 09:23
B12: 6560742-5 | C12: CARLOS ALBERTO BOSTELMANN | E12: carlosbostelm@gmail.com | F12: 138081675 | G12: APV, FM, UL | H12: Perfil Arriesgado | I12: #VALUE! | J12: Mass Affluent | K12: 27/03/2026, 05:19
B13: 9448035-3 | C13: MARIA SOLEDAD PALLERES | E13: erickalejandromi@gmail.com | F13: 29757666 | G13: FM | H13: Perfil Balanceado | I13: #VALUE! | J13: Mass Affluent | K13: 27/03/2026, 05:21
B14: 9632135-K | C14: OSCAR MARCELO BEGLIOMINI | E14: mbegly@outlook.cl | F14: 26516761 | G14: APV, FM | H14: Perfil Arriesgado | I14: #VALUE! | K14: 27/03/2026, 05:19
B15: 11400557-6 | C15: CLAUDIA PATRICIA ENRIQUEZ | E15: cenriquezg@gmail.com | F15: 19892456 | G15: FM | H15: Perfil Arriesgado | I15: #VALUE! | J15: Mass Affluent | K15: 27/03/2026, 05:17
B16: 8757376-1 | C16: JUAN CARLOS LUCERO | E16: juanclucero@dyg.cl | F16: 7358840 | G16: APV | H16: Perfil Muy Arriesgado | I16: #VALUE! | J16: Mass Affluent | K16: 27/03/2026, 05:21
B17: 20107864-4 | C17: BASTIAN ANDRES TRONCOSO | E17: 03lubani@gmail.com | F17: 4980145 | G17: FM | H17: Perfil Conservador | I17: #VALUE! | J17: Sin Segmento | K17: 27/03/2026, 05:19
B18: 21515724-5 | C18: NICOLAS ALEJANDRO TRONCOSO | E18: 03lubani@gmail.com | F18: 4974733 | G18: FM | H18: Perfil Conservador | I18: #VALUE! | J18: Nuevo-Cliente | K18: 27/03/2026, 05:23
B19: 19837527-6 | C19: LUIS DAVID TRONCOSO | E19: 03lubani@gmail.com | F19: 4969811 | G19: FM | H19: Perfil Balanceado | I19: #VALUE! | J19: Emerging Affluent | K19: 27/03/2026, 05:22
B20: 15884242-4 | C20: FRANCISCO JAVIER VALENCIA | E20: francisco.valencia24@gmail.com | F20: 49408 | G20: FM | H20: Perfil Muy Arriesgado | I20: #VALUE! | J20: Mass Affluent | K20: 27/03/2026, 05:19
B21: 7012917-5 | C21: GONZALO BREMER | E21: gbremer@aybconsultores.net | F21: 9846
F27: =SUM(F1:F21) -> 6027497459 | G27: 0.012 | H27: 12 | I27: 0.38 | J27: =(F27*((G27/H27)*I27)) -> 2290449
